Workbook

Sheet 00_Mat
A1: MATERIALES
A3: CODIGO | B3: MATERIALES CORRALON | C3: UNIDAD | D3: PRECIO CON IVA | E3: PRECIO SIN IVA | F3: DESCUENTO | G3: PRECIO CON DESCUENTO | I3: REFERENCIA | J3: FECHA
A4: ARG | B4: Arena a granel (1m3) | C4: m3 | D4: 29403 | E4: =D4/1.21 -> 24300 | I4: Su Corralon | J4: 45406
A5: AR | B5: Bolson de Arena (1m3) | C5: m3 | E5: 31040 | I5: Su Corralon | J5: 45824
A6: PIEG | B6: Piedra a granel (1m3) | C6: m3 | D6: 58995 | E6: =D6/1.21 -> 48756.198 | I6: Su Corralon | J6: 45406
A7: PIEP | B7: Bolson de Piedra partida (1m3) | C7: m3 | E7: 74566 | I7: Su Corralon | J7: 45824
A8: PIE | B8: Bolson de Piedra (1m3) | C8: m3 | D8: 60000 | E8: =D8/1.21 -> 49586.777 | I8: Su Corralon | J8: 45777
A9: CEM | B9: Bolsa Cemento "Loma Negra" 25 k (u) | C9: u | E9: 5050 | I9: Su Corralon | J9: 45890
A10: CEM-GROUT | B10: Sika Grout 25k (u) | C10: u | E10: 31900 | I10: Su Corralon | J10: 45890
A11: CAL | B11: Bolsa Cal "Cacique" 25 k (u) | C11: u | D11: 6500 | E11: =D11/1.21 -> 5371.9008 | I11: ML | J11: 45785
A12: PLASTICOR | B12: Bolsa Plasticor 40k (u) | C12: u | D12: 8500 | E12: =D12/1.21 -> 7024.7934 | I12: ML | J12: 45785
A13: CER | B13: Ceresita 20 k (u) | C13: u | D13: 45000 | E13: =D13/1.21 -> 37190.083 | I13: Su Corralon | J13: 45771
A14: LP18 | B14: Ladrillo Portante 18 (u) | C14: u | E14: 1377 | I14: Su Corralon | J14: 45824
A15: LP12 | B15: Ladrillo Portante 12 (u) | C15: u | E15: 1110.2 | I15: Su Corralon | J15: 45824
A16: LH18 | B16: Ladrillo Hueco 18 (u) | C16: u | E16: 598 | I16: Su Corralon | J16: 45478
A17: LH12 | B17: Ladrillo Hueco 12 (u) | C17: u | E17: 726 | I17: Su Corralon | J17: 45824
A18: LH8 | B18: Ladrillo Hueco 8 (u) | C18: u | E18: 568.7 | I18: Su Corralon | J18: 45824
A19: LCOM | B19: Ladrillo Comun | C19: u | E19: 190.61 | I19: Su Corralon | J19: 45824
A20: LCOMVIST | B20: Ladrillo Comun Vista | C20: u | D20: 240 | E20: =D20/1.21 -> 198.34711 | I20: Su Corralon | J20: 45771
A21: LPINT | B21: Pavimento Intertrabado | C21: m2 | E21: 37600 | I21: Su Corralon | J21: 45824
A22: LGB | B22: Garden Block 38x38x8cm (1m2) | C22: m2 | E22: 22500 | I22: ml | J22: 45877
A23: LDC | B23: Deck Liston Hormigon Cemento Piso Durmiente 100 X 12 Cms (1m2) | E23: 41000 | I23: ml | J23: 45877
A24: YES | B24: Bolsa Yeso Tuyango 30 k (u) | C24: u | D24: 13879 | E24: =D24/1.21 -> 11470.248 | I24: Su Corralon | J24: 45400
A25: ES | B25: Cascote / Escombro (m3) | C25: m3 | D25: 19360 | E25: =D25/1.21 -> 16000 | I25: Su Corralon | J25: 45412
A26: TOS8 | B26: Tosca | C26: m3 | E26: 30000 | I26: NICO | J26: 45498
A27: TOS30 | B27: Tosca | C27: m3 | E27: 9500 | I27: NICO | J27: 45498
A28: TN | B28: BOLSON Tierra negra | C28: m3 | E28: 33275 | I28: Su Corralon | J28: 45824
A29: TNF | B29: BOLSON Tierra negra fertil 10% compost | C29: m3 | E29: 86600 | I29: Su Corralon | J29: 45890
A30: TRA | B30: BOLSON Tierra negra abonada 40% compost | C30: m3 | E30: 94400 | I30: Su Corralon | J30: 45890
A31: CL2 | B31: Clavos 2" punta paris (k) | C31: k | E31: 3739.67 | I31: Naclelio | J31: 45496
A32: CL2.5 | B32: Clavos 2,5" punta paris (k) | C32: k | E32: 3739.67 | I32: Naclelio | J32: 45496
A33: AL | B33: Alambre Fardo (k) | C33: k | E33: 4326.45 | I33: Naclelio | J33: 45496
A34: ES24 | B34: Cascote / Escombro cada 24 m3 (m3) | C34: m3 | D34: 16500 | E34: =D34/1.21 -> 13636.364 | I34: Su Corralon | J34: 45412
A35: DISCO PORC | B35: Disco Amoladora para porcelanato. marca aliafor | E35: 20000 | I35: ML | J35: 45783
A36: DISCO | B36: Disco Ascerradora | C36: u | E36: 120000
A37: DIS | B37: Disco corte | C37: u | E37: 40000
A38: VI7 | B38: Vigueta pretensada de hormigon 7m | C38: u | E38: 34000 | I38: ML | J38: 45817
A39: VI6 | B39: Vigueta pretensada de hormigon 6m | C39: u | E39: 30111 | I39: Su Corralon | J39: 45824
A40: VI4 | B40: Vigueta pretensada de hormigon 4m | C40: u | E40: 26000 | I40: ML | J40: 11//9/25
A41: VI-EPS | B41: Ladrillos Telgopor 10cm | C41: u | E41: 3600 | I41: Su Corralon | J41: 45824
...

Sheet 00_MO
A1: MANO DE OBRA
A3: CODIGO | B3: MATERIALES CORRALON | C3: UNIDAD | D3: PRECIO SIN IVA | E3: FECHA
A4: MO-CA | B4: Capataz | C4: u | D4: =60000*1.5 -> 90000 | E4: 45926
A5: MO-PU | B5: Puntero | C5: u | D5: =55000*1.5 -> 82500 | E5: 45926
A6: MO-OF | B6: Oficial | C6: u | D6: =50000*1.5 -> 75000 | E6: 45926
A7: MO-AY | B7: Ayudante | C7: u | D7: =40000*1.5 -> 60000 | E7: 45926
A8: MO-GER | B8: GERVACIO | C8: u | D8: 80000 | E8: 45926

Sheet 00_Eq
A1: EQUIPOS
A3: CODIGO | B3: MATERIALES CORRALON | C3: UNIDAD | D3: PRECIO SIN IVA | E3: FECHA
A4: E-MC | B4: Mini Cargadora | C4: u | D4: 420000 | E4: 45804
A5: E-MCM | B5: Mini Cargadora con martillo | C5: u | D5: 550000 | E5: 45804
A6: E-ME | B6: Mini Excavadora | C6: u | D6: 550000 | E6: 45804
A7: E-MP | B7: Motopison | C7: u | D7: 40000
A8: E-RP | B8: Retropala | C8: u | D8: 450000
A9: E-VC | B9: Vibrocompactador | C9: u | D9: 400000
A10: E-MN | B10: Motoniveladora | C10: u | D10: 600000
A11: E-CAMCH | B11: Camion Chasis | C11: u | D11: 150000
A12: E-REG | B12: Regador | C12: u | D12: 200000
A13: E-MAR | B13: Martillete | C13: u | D13: 60000
A14: E-ASC | B14: Ascerradora | C14: u | D14: 60000 | E14: 45890
A15: E-RET | B15: Retiro x camion | C15: u | D15: 250000 | E15: 45890
A16: E-MR | B16: Mini Retro | C16: u | D16: 480000 | E16: 45804
A17: MS-TM3 | B17: TOSCA x M3 | C17: m3 | D17: 30000 | E17: 45804
A18: MS-TCA | B18: TOSCA X CAMION | C18: m3 | D18: =D17*8 -> 240000 | E18: 45804
A19: MS-ER | B19: EXCAVACION Y RETIRO | C19: m3 | D19: 21000 | E19: 45804
A20: MS-TC | B20: TOSCA COMPACTADA | C20: m3 | D20: 25000 | E20: 45804
A21: MS-ARBOL | B21: RETIRO DE ARBOL | C21: u | D21: 570000 | E21: 45804
A22: E-CAM | B22: Camioneta | C22: u | D22: 100000
A23: E-TRAS | B23: TRASLADO DE MAQUINARIA | C23: u | D23: 300000
A24: E-VOL | B24: Volquete | C24: u | D24: 200000

Sheet 00_Sub
A1: SUBCONTRATOS
A3: CODIGO | B3: SUBCONTRATOS | C3: UNIDAD | D3: PRECIO SIN IVA
A4: SUB-PI | B4: Pintura Interior: 1Mano Enduido + Yeso, 1 Mano Enduido, 2 a 3 Manos de Pintura | C4: m2 | D4: 16000 | F4: 45789
A5: SUB-PIC | B5: Pintura Interior Cielorraso | C5: m2 | D5: 10000 | F5: 45789
A6: SUB-PET | B6: Pintura Exterior Tarquini | C6: m2 | D6: 12000 | F6: 45789
A7: SUB-PE | B7: Pintura Exterior | C7: m2 | D7: 10000
A8: SUB-PI | B8: Pintura Interior | C8: m2 | D8: 8000
A9: SUB-END | B9: Enduido | C9: m2 | D9: 8000
A10: SUB-PPS | B10: Pintura Puerta Simple Hoja | C10: u | D10: 25000
A11: SUB-PPD | B11: Pintura Puerta Doble Hoja | C11: u | D11: 50000
A12: SUB-CIE | B12: Instalacion de Cielorraso Durlock. Incluye Materiales. | C12: m2 | D12: 37000 | F12: 45791
A13: SUB-CIEDES | B13: Instalacion de Cielorraso Desmontable. Incluye Materiales. | C13: m2 | D13: 37000 | F13: 45791
A14: SUB-CIECO | B14: Instalacion de Cielorraso Durlock Cortineros. Incluye Materiales. | C14: m | D14: 45000 | F14: 45791
A15: SUB-CIECA | B15: Instalacion de Cajon Durlock. Incluye Materiales. | C15: m | D15: 20000 | F15: 45791
A16: SUB-CIEGL | B16: Instalacion de Cielorraso Durlock Garganta Led. Incluye Materiales. | C16: m | D16: 45000 | F16: 45791
A17: SUB-TAB | B17: Instalacion de Tabique Durlock. Incluye Materiales. | C17: m2 | D17: 48000 | F17: 45791
A18: SUB-BZ | B18: Instlacion Buña Z. Incluye Materiales. | C18: m | D18: 16000 | F18: 45791
A19: SUB-CAN | B19: Instalacion Cantonera. Incluye Materiales. | C19: m | D19: 16000 | F19: 45791
A20: SUB-E-BOC | B20: Boca. Incluye Materiales. | C20: boca | D20: 100000 | E20: MDO Y MAT | F20: 45800 | G20: CABEZA
A21: SUB-E-COL | B21: Colocacion de artefatcos | C21: u | D21: 7000 | E21: MDO | F21: 45800 | G21: CABEZA
A22: SUB-E-AAC | B22: Alimentacion aire acondicionado con split. | C22: u | D22: 100000 | E22: MDO Y MAT | F22: 45800 | G22: CABEZA
A23: SUB-E-TAB | B23: Instalacion de Tablero para 100 bocas (casa chica). Incluye alimentacion desde el pilar. | C23: u | D23: 100000 | E23: MDO | F23: 45800 | G23: CABEZA
A24: SUB-ZING | B24: Zinguero | C24: u | D24: 700000
A25: SUB-PIS | B25: Pisero | C25: m² | D25: 7000 | F25: 45800 | G25: CEFERINO
A26: SUB-COR | B26: CORDON | C26: m | D26: 10000 | F26: 45800 | G26: CEFERINO
A27: SUB-ELE-T | C27: TABLERO | D27: 1000000
A28: SUB-ELE-B | B28: Electricista | C28: boca | D28: 60000
A29: SUB-SIDING | B29: COLOCAcion de siding en pared | C29: m2 | D29: 18000
A30: SUB-REV-CH | B30: Revestimiento de chapa | C30: m2 | D30: 18000 | F30: 45902 | G30: HUGO
A32: CODIGO | B32: MOVIMIENTO DE SUELOS | C32: UNIDAD | D32: PRECIO SIN IVA
A33: MS-MC | B33: MINICARGADORA | C33: u | D33: 420000
A34: MS-MCM | B34: MINICARGADORA CON MARTILLO | C34: u | D34: 550000
A35: MS-MR | B35: MINIRETRO EXCAVADORA | C35: u | D35: 550000
A36: MS-T | B36: TRASLADO DE MAQUINARIA | C36: u | D36: 300000
A37: MS-RV | B37: RETIRO X VIAJE | C37: u | D37: 60000
A38: MS-TM3 | B38: TOSCA x M3 | C38: m3 | D38: 30000
A39: MS-TCA | B39: TOSCA X CAMION | C39: m3 | D39: =D38*8 -> 240000
A40: MS-ER | B40: EXCAVACION Y RETIRO | C40: m3 | D40: 21000
A41: MS-TC | B41: TOSCA COMPACTADA | C41: m3 | D41: 25000
A42: MS-ARBOL | B42: RETIRO DE ARBOL | C42: u | D42: 200000
...

Sheet 00_JEF + ESTR
A1: JEFATURA DE OBRA (mes)
A3: Jefatura de Obra | B3: 2000000
A4: Jefe de Obra | B4: 1500000
A5: Gastos Estructura | B5: =SUM(B6:B9) -> 1620000
A6: Nafta Jefe de Obra | B6: 280000
A7: Nafta Nico | B7: 140000
A8: Guille | B8: 200000
A9: Herramientas | B9: 1000000
B11: =SUM(B5+B3) -> 3620000
A13: JEFATURA X 12 MESES | B13: =B3*12 -> 24000000
A14: G.E. X 12 MESES | B14: =B5*12 -> 19440000

Sheet 01_C&P
A1: CASA LUGONES
A3: PLANILLA COMPUTO Y PRESPUPUESTO
A5: ITEM | B5: DESCRIPCIÓN | C5: UNIDAD | D5: CANTIDAD | E5: SUBTOTAL 01: GASTOS DIRECTOS | O5: SUBTOTAL 02: GASTOS INDIRECTOS | R5: SUBTOTAL 03: BENEFICIOS | U5: TOTAL (NETO)
E6: V.UNITARIO | L6: V.GENERAL | O6: V. GENERAL | R6: V. GENERAL | U6: V. UNITARIO | X6: V.GENERAL
E7: MAT. | F7: M.O.: JORNALES | G7: M.O.: EQUIPOS | H7: M.O.: MATERIALES | I7: M.O.: SUBCONTRATOS | J7: M.O. | K7: GENERAL | L7: MAT. | M7: M.O | N7: GENERAL | O7: MAT. | P7: M.O. | Q7: GENERAL | R7: MAT. | S7: M.O. | T7: GENERAL | U7: MAT. | V7: M.O | W7: GENERAL | X7: MAT. | Y7: M.O | Z7: GENERAL
A8: 1- TAREAS PRELIMINARES
A9: 45658 | B9: OBRADOR | C9: mes | D9: 1 | E9: 800000 | F9: 400000 | H9: 200000 | I9: 0 | J9: =SUM(F9:I9) -> 600000 | K9: =SUM(E9,J9) -> 1400000 | L9: =$D9*E9 -> 800000 | M9: =$D9*(SUM(F9:I9)) -> 600000 | N9: =L9+M9 -> 1400000 | O9: =L9 -> 800000 | P9: =(P$110*M9)/M$110 -> 1014000 | Q9: =O9+P9 -> 1814000 | R9: =L9 -> 800000 | S9: =(S$110*P9)/P$110 -> 1368900 | T9: =R9+S9 -> 2168900 | U9: =E9 -> 800000 | V9: =Y9/D9 -> 1481149.8 | W9: =U9+V9 -> 2281149.8 | X9: =L9 -> 800000 | Y9: =(Y$110*S9)/S$110 -> 1481149.8 | Z9: =X9+Y9 -> 2281149.8
A10: 45689 | B10: CARTEL DE OBRA | C10: unid | D10: 1 | J10: =SUM(F10:I10) -> 0 | K10: =SUM(E10,J10) -> 0 | L10: =$D10*E10 -> 0 | M10: =$D10*(SUM(F10:I10)) -> 0 | N10: =L10+M10 -> 0 | O10: =L10 -> 0 | P10: =(P$110*M10)/M$110 -> 0 | Q10: =O10+P10 -> 0 | R10: =L10 -> 0 | S10: =(S$110*P10)/P$110 -> 0 | T10: =R10+S10 -> 0 | U10: =E10 | V10: =Y10/D10 -> 0 | W10: =U10+V10 -> 0 | X10: =L10 -> 0 | Y10: =(Y$110*S10)/S$110 -> 0 | Z10: =X10+Y10 -> 0
A11: 45717 | B11: BAÑO QUIMICO | C11: mes | D11: 12 | I11: 100000 | J11: =SUM(F11:I11) -> 100000 | K11: =SUM(E11,J11) -> 100000 | L11: =$D11*E11 -> 0 | M11: =$D11*(SUM(F11:I11)) -> 1200000 | N11: =L11+M11 -> 1200000 | O11: =L11 -> 0 | P11: =(P$110*M11)/M$110 -> 2028000 | Q11: =O11+P11 -> 2028000 | R11: =L11 -> 0 | S11: =(S$110*P11)/P$110 -> 2737800 | T11: =R11+S11 -> 2737800 | U11: =E11 | V11: =Y11/D11 -> 246858.3 | W11: =U11+V11 -> 246858.3 | X11: =L11 -> 0 | Y11: =(Y$110*S11)/S$110 -> 2962299.6 | Z11: =X11+Y11 -> 2962299.6
A12: 45748 | B12: INSTALACIONES PROVISORIAS | C12: unid | D12: 1 | J12: =SUM(F12:I12) -> 0 | K12: =SUM(E12,J12) -> 0 | L12: =$D12*E12 -> 0 | M12: =$D12*(SUM(F12:I12)) -> 0 | N12: =L12+M12 -> 0 | O12: =L12 -> 0 | P12: =(P$110*M12)/M$110 -> 0 | Q12: =O12+P12 -> 0 | R12: =L12 -> 0 | S12: =(S$110*P12)/P$110 -> 0 | T12: =R12+S12 -> 0 | U12: =E12 | V12: =Y12/D12 -> 0 | W12: =U12+V12 -> 0 | X12: =L12 -> 0 | Y12: =(Y$110*S12)/S$110 -> 0 | Z12: =X12+Y12 -> 0
A13: 45778 | B13: CERCO PERIMETRAL | C13: unid | D13: 1 | J13: =SUM(F13:I13) -> 0 | K13: =SUM(E13,J13) -> 0 | L13: =$D13*E13 -> 0 | M13: =$D13*(SUM(F13:I13)) -> 0 | N13: =L13+M13 -> 0 | O13: =L13 -> 0 | P13: =(P$110*M13)/M$110 -> 0 | Q13: =O13+P13 -> 0 | R13: =L13 -> 0 | S13: =(S$110*P13)/P$110 -> 0 | T13: =R13+S13 -> 0 | U13: =E13 | V13: =Y13/D13 -> 0 | W13: =U13+V13 -> 0 | X13: =L13 -> 0 | Y13: =(Y$110*S13)/S$110 -> 0 | Z13: =X13+Y13 -> 0
A14: 45809 | B14: REPLANTEO Y NIVELACION INICIAL DEL TERRENO | C14: unid | D14: 1 | I14: 700000 | J14: =SUM(F14:I14) -> 700000 | K14: =SUM(E14,J14) -> 700000 | L14: =$D14*E14 -> 0 | M14: =$D14*(SUM(F14:I14)) -> 700000 | N14: =L14+M14 -> 700000 | O14: =L14 -> 0 | P14: =(P$110*M14)/M$110 -> 1183000 | Q14: =O14+P14 -> 1183000 | R14: =L14 -> 0 | S14: =(S$110*P14)/P$110 -> 1597050 | T14: =R14+S14 -> 1597050 | U14: =E14 | V14: =Y14/D14 -> 1728008.1 | W14: =U14+V14 -> 1728008.1 | X14: =L14 -> 0 | Y14: =(Y$110*S14)/S$110 -> 1728008.1 | Z14: =X14+Y14 -> 1728008.1
A15: 45839 | B15: LIMPIEZA PERIODICA DE OBRA | C15: mes | D15: 12 | F15: 100000 | I15: 0 | J15: =SUM(F15:I15) -> 100000 | K15: =SUM(E15,J15) -> 100000 | L15: =$D15*E15 -> 0 | M15: =$D15*(SUM(F15:I15)) -> 1200000 | N15: =L15+M15 -> 1200000 | O15: =L15 -> 0 | P15: =(P$110*M15)/M$110 -> 2028000 | Q15: =O15+P15 -> 2028000 | R15: =L15 -> 0 | S15: =(S$110*P15)/P$110 -> 2737800 | T15: =R15+S15 -> 2737800 | U15: =E15 | V15: =Y15/D15 -> 246858.3 | W15: =U15+V15 -> 246858.3 | X15: =L15 -> 0 | Y15: =(Y$110*S15)/S$110 -> 2962299.6 | Z15: =X15+Y15 -> 2962299.6
A16: 45870 | B16: LIMPIEZA FINAL DE OBRA | C16: unid | D16: 1 | F16: 250000 | I16: 150000 | J16: =SUM(F16:I16) -> 400000 | K16: =SUM(E16,J16) -> 400000 | L16: =$D16*E16 -> 0 | M16: =$D16*(SUM(F16:I16)) -> 400000 | N16: =L16+M16 -> 400000 | O16: =L16 -> 0 | P16: =(P$110*M16)/M$110 -> 676000 | Q16: =O16+P16 -> 676000 | R16: =L16 -> 0 | S16: =(S$110*P16)/P$110 -> 912600 | T16: =R16+S16 -> 912600 | U16: =E16 | V16: =Y16/D16 -> 987433.2 | W16: =U16+V16 -> 987433.2 | X16: =L16 -> 0 | Y16: =(Y$110*S16)/S$110 -> 987433.2 | Z16: =X16+Y16 -> 987433.2
A17: 45901 | B17: AYUDA DE GREMIO | C17: mes | D17: 12 | F17: 150000 | J17: =SUM(F17:I17) -> 150000 | K17: =SUM(E17,J17) -> 150000 | L17: =$D17*E17 -> 0 | M17: =$D17*(SUM(F17:I17)) -> 1800000 | N17: =L17+M17 -> 1800000 | O17: =L17 -> 0 | P17: =(P$110*M17)/M$110 -> 3042000 | Q17: =O17+P17 -> 3042000 | R17: =L17 -> 0 | S17: =(S$110*P17)/P$110 -> 4106700 | T17: =R17+S17 -> 4106700 | U17: =E17 | V17: =Y17/D17 -> 370287.45 | W17: =U17+V17 -> 370287.45 | X17: =L17 -> 0 | Y17: =(Y$110*S17)/S$110 -> 4443449.4 | Z17: =X17+Y17 -> 4443449.4
A18: 45931 | B18: PROGRAMA DE SEGURIDAD E HIGENE DE ACUERDO A LA NORMATIVA VIGENTE (TODO EL PERSONAL ALCANZADO POR EL MISMO Y CON ART) | C18: mes | D18: 12 | I18: 200000 | J18: =SUM(F18:I18) -> 200000 | K18: =SUM(E18,J18) -> 200000 | L18: =$D18*E18 -> 0 | M18: =$D18*(SUM(F18:I18)) -> 2400000 | N18: =L18+M18 -> 2400000 | O18: =L18 -> 0 | P18: =(P$110*M18)/M$110 -> 4056000 | Q18: =O18+P18 -> 4056000 | R18: =L18 -> 0 | S18: =(S$110*P18)/P$110 -> 5475600 | T18: =R18+S18 -> 5475600 | U18: =E18 | V18: =Y18/D18 -> 493716.6 | W18: =U18+V18 -> 493716.6 | X18: =L18 -> 0 | Y18: =(Y$110*S18)/S$110 -> 5924599.2 | Z18: =X18+Y18 -> 5924599.2
A19: 2- DEMOLICION
A20: 45659 | B20: DEMOLICION LOSAS | C20: m² | D20: 30
A21: 45690 | B21: DEMOLICION COLUMNAS | C21: unid. | D21: 3
A22: 45718 | B22: DEMOLICION MUROS | C22: m² | D22: =48*3.4 -> 163.2
A23: 45749 | B23: DEMOLICION DE ESCALERA (1 x 0,84m) h- 4 escalones | C23: gl | D23: 1
A24: 45779 | B24: DEMOLICION EN SECTOR CANTERO | C24: m² | D24: 9
A25: 45810 | B25: DEMOLICION DE VOLUMEN PA | C25: gl | D25: 1
A26: 45840 | B26: DEMOLICION DE LOSA PARA INSTALACIONES | C26: gl | D26: 1
A27: 45871 | B27: DEMOLICION DE FUNDACIONES PARA REFORZAR ESTRUCTURA | C27: gl | D27: 1
A28: 45902 | B28: RETIRO DE PORTON | C28: unid. | D28: 1
A29: 45932 | B29: RETIRO DE CARPINTERIAS | C29: gl | D29: 1
A30: 45963 | B30: RETIRO DE PUERTA PRINCIPAL | C30: unid. | D30: 1
A31: 45993 | B31: RETIRO DE SOLADO EN PLANTA BAJA | C31: m² | D31: 118
A32: 2.13 | B32: RETIRO DE ALERO METALICO | C32: gl | D32: 1
A33: 2.14 | B33: DEMOLICION TOTAL DE ITEMS ANTERIORES | C33: gl | D33: 1 | E33: ='2.14'!I22 -> 0 | F33: ='2.14'!I36 -> 6180000 | G33: ='2.14'!I50 -> 7500000 | H33: ='2.14'!I64 -> 503700 | I33: ='2.14'!I78 -> 0 | J33: =SUM(F33:I33) -> 14183700 | K33: =SUM(E33,J33) -> 14183700 | L33: =$D33*E33 -> 0 | M33: =$D33*(SUM(F33:I33)) -> 14183700 | N33: =L33+M33 -> 14183700 | O33: =L33 -> 0 | P33: =(P$110*M33)/M$110 -> 23970453 | Q33: =O33+P33 -> 23970453 | R33: =L33 -> 0 | S33: =(S$110*P33)/P$110 -> 32360112 | T33: =R33+S33 -> 32360112 | U33: =E33 -> 0 | V33: =Y33/D33 -> 35013641 | W33: =U33+V33 -> 35013641 | X33: =L33 -> 0 | Y33: =(Y$110*S33)/S$110 -> 35013641 | Z33: =X33+Y33 -> 35013641
A34: 3-ESTRUCTURA
A35: FUNDACIONES
A36: 3.0-1 | B36: EXCAVACION DE BASES PARA REFORZAR ESTRUCTURA | C36: unid. | D36: 14 | E36: ='3.0-1'!I25 -> 0 | F36: ='3.0-1'!I39 -> 321428.57 | G36: ='3.0-1'!I53 -> 71428.571 | H36: ='3.0-1'!I67 -> 0 | I36: ='3.0-1'!I81 -> 0 | J36: =SUM(F36:I36) -> 392857.14 | K36: =SUM(E36,J36) -> 392857.14 | L36: =$D36*E36 -> 0 | M36: =$D36*(SUM(F36:I36)) -> 5500000 | N36: =L36+M36 -> 5500000 | O36: =L36 -> 0 | P36: =(P$110*M36)/M$110 -> 9295000 | Q36: =O36+P36 -> 9295000 | R36: =L36 -> 0 | S36: =(S$110*P36)/P$110 -> 12548250 | T36: =R36+S36 -> 12548250 | U36: =E36 -> 0 | V36: =Y36/D36 -> 969800.46 | W36: =U36+V36 -> 969800.46 | X36: =L36 -> 0 | Y36: =(Y$110*S36)/S$110 -> 13577206 | Z36: =X36+Y36 -> 13577206
A37: 3.0-2 | B37: EJECUCION DE BASES DE H 30 100x100 + TRONCO 25X25x100 + TENSORES 30x40cm | C37: unid. | D37: 14 | E37: ='3.0-2'!I26 -> 206681.2 | F37: ='3.0-2'!I40 -> 273214.29 | G37: ='3.0-2'!I54 -> 0 | H37: ='3.0-2'!I68 -> 24452.191 | I37: ='3.0-2'!I82 -> 0 | J37: =SUM(F37:I37) -> 297666.48 | K37: =SUM(E37,J37) -> 504347.68 | L37: =$D37*E37 -> 2893536.9 | M37: =$D37*(SUM(F37:I37)) -> 4167330.7 | N37: =L37+M37 -> 7060867.5 | O37: =L37 -> 2893536.9 | P37: =(P$110*M37)/M$110 -> 7042788.8 | Q37: =O37+P37 -> 9936325.7 | R37: =L37 -> 2893536.9 | S37: =(S$110*P37)/P$110 -> 9507764.9 | T37: =R37+S37 -> 12401302 | U37: =E37 -> 206681.2 | V37: =Y37/D37 -> 734814.41 | W37: =U37+V37 -> 941495.61 | X37: =L37 -> 2893536.9 | Y37: =(Y$110*S37)/S$110 -> 10287402 | Z37: =X37+Y37 -> 13180939
A38: 3.0-3 | B38: RELLENO DE FUNDACIONES (TOSCA + HORMIGON EN PLATEA DE FUNDACION) | C38: unid. | D38: 14 | E38: =' 3.0-3'!I25 -> 125774.59 | F38: =' 3.0-3'!I39 -> 107142.86 | G38: =' 3.0-3'!I53 -> 0 | H38: =' 3.0-3'!I67 -> 0 | I38: =' 3.0-3'!I81 -> 0 | J38: =SUM(F38:I38) -> 107142.86 | K38: =SUM(E38,J38) -> 232917.45 | L38: =$D38*E38 -> 1760844.3 | M38: =$D38*(SUM(F38:I38)) -> 1500000 | N38: =L38+M38 -> 3260844.3 | O38: =L38 -> 1760844.3 | P38: =(P$110*M38)/M$110 -> 2535000 | Q38: =O38+P38 -> 4295844.3 | R38: =L38 -> 1760844.3 | S38: =(S$110*P38)/P$110 -> 3422250 | T38: =R38+S38 -> 5183094.3 | U38: =E38 -> 125774.59 | V38: =Y38/D38 -> 264491.04 | W38: =U38+V38 -> 390265.63 | X38: =L38 -> 1760844.3 | Y38: =(Y$110*S38)/S$110 -> 3702874.5 | Z38: =X38+Y38 -> 5463718.8
A39: SOBRE PLANTA BAJA
A40: 3.1-1 | B40: VIGAS H30 SOBRE PLANTA BAJA 0,15x0,35 (Hierros 6 ∅8 con estribos ∅ 6 c/14) | C40: m | D40: 29 | E40: ='3.1-1'!I22 -> 17958.966 | F40: ='3.1-1'!I36 -> 49655.172 | G40: ='3.1-1'!I50 -> 0 | H40: ='3.1-1'!I64 -> 28161.198 | I40: ='3.1-1'!I78 -> 0 | J40: =SUM(F40:I40) -> 77816.37 | K40: =SUM(E40,J40) -> 95775.336 | L40: =$D40*E40 -> 520810 | M40: =$D40*(SUM(F40:I40)) -> 2256674.7 | N40: =L40+M40 -> 2777484.7 | O40: =L40 -> 520810 | P40: =(P$110*M40)/M$110 -> 3813780.3 | Q40: =O40+P40 -> 4334590.3 | R40: =L40 -> 520810 | S40: =(S$110*P40)/P$110 -> 5148603.4 | T40: =R40+S40 -> 5669413.4 | U40: =E40 -> 17958.966 | V40: =Y40/D40 -> 192096.17 | W40: =U40+V40 -> 210055.13 | X40: =L40 -> 520810 | Y40: =(Y$110*S40)/S$110 -> 5570788.9 | Z40: =X40+Y40 -> 6091598.9
A41: 3.1-2 | B41: VIGAS METALICAS + COLUMNA METALICA | C41: m | D41: =4+4.3 -> 8.3 | E41: ='3.1-2'!I22 -> 139757.45 | F41: ='3.1-2'!I36 -> 0 | G41: ='3.1-2'!I50 -> 0 | H41: ='3.1-2'!I64 -> 0 | I41: ='3.1-2'!I78 -> 120481.93 | J41: =SUM(F41:I41) -> 120481.93 | K41: =SUM(E41,J41) -> 260239.37 | L41: =$D41*E41 -> 1159986.8 | M41: =$D41*(SUM(F41:I41)) -> 1000000 | N41: =L41+M41 -> 2159986.8 | O41: =L41 -> 1159986.8 | P41: =(P$110*M41)/M$110 -> 1690000 | Q41: =O41+P41 -> 2849986.8 | R41: =L41 -> 1159986.8 | S41: =(S$110*P41)/P$110 -> 2281500 | T41: =R41+S41 -> 3441486.8 | U41: =E41 -> 139757.45 | V41: =Y41/D41 -> 297419.64 | W41: =U41+V41 -> 437177.09 | X41: =L41 -> 1159986.8 | Y41: =(Y$110*S41)/S$110 -> 2468583 | Z41: =X41+Y41 -> 3628569.8
A42: 3.1-3 | B42: LOSA DE VIGUETAS SECTOR COCINA e=0,08m | C42: m² | D42: 18 | E42: ='3.1-3'!I22 -> 49897.778 | F42: ='3.1-3'!I36 -> 29166.667 | G42: ='3.1-3'!I50 -> 0 | H42: ='3.1-3'!I64 -> 12111.111 | I42: ='3.1-3'!I78 -> 0 | J42: =SUM(F42:I42) -> 41277.778 | K42: =SUM(E42,J42) -> 91175.556 | L42: =$D42*E42 -> 898160 | M42: =$D42*(SUM(F42:I42)) -> 743000 | N42: =L42+M42 -> 1641160 | O42: =L42 -> 898160 | P42: =(P$110*M42)/M$110 -> 1255670 | Q42: =O42+P42 -> 2153830 | R42: =L42 -> 898160 | S42: =(S$110*P42)/P$110 -> 1695154.5 | T42: =R42+S42 -> 2593314.5 | U42: =E42 -> 49897.778 | V42: =Y42/D42 -> 101897.62 | W42: =U42+V42 -> 151795.4 | X42: =L42 -> 898160 | Y42: =(Y$110*S42)/S$110 -> 1834157.2 | Z42: =X42+Y42 -> 2732317.2
...

Sheet 01_VENTA
A1: CASA LUGONES
A2: Arq. Andres Barone
A3: Pilar, 11 de Septiembre de 2025.
A5: PLANILLA COMPUTO Y PRESPUPUESTO
A7: ITEM | B7: DESCRIPCIÓN | C7: UNIDAD | D7: CANTIDAD | E7: TOTAL (NETO)
E8: V. UNITARIO | H8: V.GENERAL
E9: MAT. | F9: M.O | G9: GENERAL | H9: MAT. | I9: M.O | J9: GENERAL
A10: ='01_C&P'!A8 -> 1- TAREAS PRELIMINARES | C10: ='01_C&P'!C8 | D10: ='01_C&P'!D8
A11: ='01_C&P'!A9 -> 45658 | B11: ='01_C&P'!B9 -> OBRADOR | C11: ='01_C&P'!C9 -> mes | D11: ='01_C&P'!D9 -> 1 | E11: ='01_C&P'!U9 -> 800000 | F11: ='01_C&P'!V9 -> 1481149.8 | G11: ='01_C&P'!W9 -> 2281149.8 | H11: ='01_C&P'!X9 -> 800000 | I11: ='01_C&P'!Y9 -> 1481149.8 | J11: ='01_C&P'!Z9 -> 2281149.8
A12: ='01_C&P'!A10 -> 45689 | B12: ='01_C&P'!B10 -> CARTEL DE OBRA | C12: ='01_C&P'!C10 -> unid | D12: ='01_C&P'!D10 -> 1 | E12: ='01_C&P'!U10 | F12: ='01_C&P'!V10 -> 0 | G12: ='01_C&P'!W10 -> 0 | H12: ='01_C&P'!X10 -> 0 | I12: ='01_C&P'!Y10 -> 0 | J12: ='01_C&P'!Z10 -> 0
A13: ='01_C&P'!A11 -> 45717 | B13: ='01_C&P'!B11 -> BAÑO QUIMICO | C13: ='01_C&P'!C11 -> mes | D13: ='01_C&P'!D11 -> 12 | E13: ='01_C&P'!U11 | F13: ='01_C&P'!V11 -> 246858.3 | G13: ='01_C&P'!W11 -> 246858.3 | H13: ='01_C&P'!X11 -> 0 | I13: ='01_C&P'!Y11 -> 2962299.6 | J13: ='01_C&P'!Z11 -> 2962299.6
A14: ='01_C&P'!A12 -> 45748 | B14: ='01_C&P'!B12 -> INSTALACIONES PROVISORIAS | C14: ='01_C&P'!C12 -> unid | D14: ='01_C&P'!D12 -> 1 | E14: ='01_C&P'!U12 | F14: ='01_C&P'!V12 -> 0 | G14: ='01_C&P'!W12 -> 0 | H14: ='01_C&P'!X12 -> 0 | I14: ='01_C&P'!Y12 -> 0 | J14: ='01_C&P'!Z12 -> 0
A15: ='01_C&P'!A13 -> 45778 | B15: ='01_C&P'!B13 -> CERCO PERIMETRAL | C15: ='01_C&P'!C13 -> unid | D15: ='01_C&P'!D13 -> 1 | E15: ='01_C&P'!U13 | F15: ='01_C&P'!V13 -> 0 | G15: ='01_C&P'!W13 -> 0 | H15: ='01_C&P'!X13 -> 0 | I15: ='01_C&P'!Y13 -> 0 | J15: ='01_C&P'!Z13 -> 0
A16: ='01_C&P'!A14 -> 45809 | B16: ='01_C&P'!B14 -> REPLANTEO Y NIVELACION INICIAL DEL TERRENO | C16: ='01_C&P'!C14 -> unid | D16: ='01_C&P'!D14 -> 1 | E16: ='01_C&P'!U14 | F16: ='01_C&P'!V14 -> 1728008.1 | G16: ='01_C&P'!W14 -> 1728008.1 | H16: ='01_C&P'!X14 -> 0 | I16: ='01_C&P'!Y14 -> 1728008.1 | J16: ='01_C&P'!Z14 -> 1728008.1
A17: ='01_C&P'!A15 -> 45839 | B17: ='01_C&P'!B15 -> LIMPIEZA PERIODICA DE OBRA | C17: ='01_C&P'!C15 -> mes | D17: ='01_C&P'!D15 -> 12 | E17: ='01_C&P'!U15 | F17: ='01_C&P'!V15 -> 246858.3 | G17: ='01_C&P'!W15 -> 246858.3 | H17: ='01_C&P'!X15 -> 0 | I17: ='01_C&P'!Y15 -> 2962299.6 | J17: ='01_C&P'!Z15 -> 2962299.6
A18: ='01_C&P'!A16 -> 45870 | B18: ='01_C&P'!B16 -> LIMPIEZA FINAL DE OBRA | C18: ='01_C&P'!C16 -> unid | D18: ='01_C&P'!D16 -> 1 | E18: ='01_C&P'!U16 | F18: ='01_C&P'!V16 -> 987433.2 | G18: ='01_C&P'!W16 -> 987433.2 | H18: ='01_C&P'!X16 -> 0 | I18: ='01_C&P'!Y16 -> 987433.2 | J18: ='01_C&P'!Z16 -> 987433.2
A19: ='01_C&P'!A17 -> 45901 | B19: ='01_C&P'!B17 -> AYUDA DE GREMIO | C19: ='01_C&P'!C17 -> mes | D19: ='01_C&P'!D17 -> 12 | E19: ='01_C&P'!U17 | F19: ='01_C&P'!V17 -> 370287.45 | G19: ='01_C&P'!W17 -> 370287.45 | H19: ='01_C&P'!X17 -> 0 | I19: ='01_C&P'!Y17 -> 4443449.4 | J19: ='01_C&P'!Z17 -> 4443449.4
A20: ='01_C&P'!A18 -> 45931 | B20: ='01_C&P'!B18 -> PROGRAMA DE SEGURIDAD E HIGENE DE ACUERDO A LA NORMATIVA VIGENTE (TODO EL PERSONAL ALCANZADO POR EL MISMO Y CON ART) | C20: ='01_C&P'!C18 -> mes | D20: ='01_C&P'!D18 -> 12 | E20: ='01_C&P'!U18 | F20: ='01_C&P'!V18 -> 493716.6 | G20: ='01_C&P'!W18 -> 493716.6 | H20: ='01_C&P'!X18 -> 0 | I20: ='01_C&P'!Y18 -> 5924599.2 | J20: ='01_C&P'!Z18 -> 5924599.2
A21: ='01_C&P'!A19 -> 2- DEMOLICION | C21: ='01_C&P'!C19 | E21: ='01_C&P'!E19 | G21: ='01_C&P'!G19 | I21: ='01_C&P'!I19
A22: ='01_C&P'!A20 -> 45659 | B22: ='01_C&P'!B20 -> DEMOLICION LOSAS | C22: ='01_C&P'!C20 -> m² | D22: ='01_C&P'!D20 -> 30 | E22: ='01_C&P'!U20 | F22: ='01_C&P'!V20 | G22: ='01_C&P'!W20 | H22: ='01_C&P'!X20 | I22: ='01_C&P'!Y20 | J22: ='01_C&P'!Z20
A23: ='01_C&P'!A21 -> 45690 | B23: ='01_C&P'!B21 -> DEMOLICION COLUMNAS | C23: ='01_C&P'!C21 -> unid. | D23: ='01_C&P'!D21 -> 3 | E23: ='01_C&P'!U21 | F23: ='01_C&P'!V21 | G23: ='01_C&P'!W21 | H23: ='01_C&P'!X21 | I23: ='01_C&P'!Y21 | J23: ='01_C&P'!Z21
A24: ='01_C&P'!A22 -> 45718 | B24: ='01_C&P'!B22 -> DEMOLICION MUROS | C24: ='01_C&P'!C22 -> m² | D24: ='01_C&P'!D22 -> 163.2 | E24: ='01_C&P'!U22 | F24: ='01_C&P'!V22 | G24: ='01_C&P'!W22 | H24: ='01_C&P'!X22 | I24: ='01_C&P'!Y22 | J24: ='01_C&P'!Z22
A25: ='01_C&P'!A23 -> 45749 | B25: ='01_C&P'!B23 -> DEMOLICION DE ESCALERA (1 x 0,84m) h- 4 escalones | C25: ='01_C&P'!C23 -> gl | D25: ='01_C&P'!D23 -> 1 | E25: ='01_C&P'!U23 | F25: ='01_C&P'!V23 | G25: ='01_C&P'!W23 | H25: ='01_C&P'!X23 | I25: ='01_C&P'!Y23 | J25: ='01_C&P'!Z23
A26: ='01_C&P'!A24 -> 45779 | B26: ='01_C&P'!B24 -> DEMOLICION EN SECTOR CANTERO | C26: ='01_C&P'!C24 -> m² | D26: ='01_C&P'!D24 -> 9 | E26: ='01_C&P'!U24 | F26: ='01_C&P'!V24 | G26: ='01_C&P'!W24 | H26: ='01_C&P'!X24 | I26: ='01_C&P'!Y24 | J26: ='01_C&P'!Z24
A27: ='01_C&P'!A25 -> 45810 | B27: ='01_C&P'!B25 -> DEMOLICION DE VOLUMEN PA | C27: ='01_C&P'!C25 -> gl | D27: ='01_C&P'!D25 -> 1 | E27: ='01_C&P'!U25 | F27: ='01_C&P'!V25 | G27: ='01_C&P'!W25 | H27: ='01_C&P'!X25 | I27: ='01_C&P'!Y25 | J27: ='01_C&P'!Z25
A28: ='01_C&P'!A26 -> 45840 | B28: ='01_C&P'!B26 -> DEMOLICION DE LOSA PARA INSTALACIONES | C28: ='01_C&P'!C26 -> gl | D28: ='01_C&P'!D26 -> 1 | E28: ='01_C&P'!U26 | F28: ='01_C&P'!V26 | G28: ='01_C&P'!W26 | H28: ='01_C&P'!X26 | I28: ='01_C&P'!Y26 | J28: ='01_C&P'!Z26
A29: ='01_C&P'!A27 -> 45871 | B29: ='01_C&P'!B27 -> DEMOLICION DE FUNDACIONES PARA REFORZAR ESTRUCTURA | C29: ='01_C&P'!C27 -> gl | D29: ='01_C&P'!D27 -> 1 | E29: ='01_C&P'!U27 | F29: ='01_C&P'!V27 | G29: ='01_C&P'!W27 | H29: ='01_C&P'!X27 | I29: ='01_C&P'!Y27 | J29: ='01_C&P'!Z27
A30: ='01_C&P'!A28 -> 45902 | B30: ='01_C&P'!B28 -> RETIRO DE PORTON | C30: ='01_C&P'!C28 -> unid. | D30: ='01_C&P'!D28 -> 1 | E30: ='01_C&P'!U28 | F30: ='01_C&P'!V28 | G30: ='01_C&P'!W28 | H30: ='01_C&P'!X28 | I30: ='01_C&P'!Y28 | J30: ='01_C&P'!Z28
A31: ='01_C&P'!A29 -> 45932 | B31: ='01_C&P'!B29 -> RETIRO DE CARPINTERIAS | C31: ='01_C&P'!C29 -> gl | D31: ='01_C&P'!D29 -> 1 | E31: ='01_C&P'!U29 | F31: ='01_C&P'!V29 | G31: ='01_C&P'!W29 | H31: ='01_C&P'!X29 | I31: ='01_C&P'!Y29 | J31: ='01_C&P'!Z29
A32: ='01_C&P'!A30 -> 45963 | B32: ='01_C&P'!B30 -> RETIRO DE PUERTA PRINCIPAL | C32: ='01_C&P'!C30 -> unid. | D32: ='01_C&P'!D30 -> 1 | E32: ='01_C&P'!U30 | F32: ='01_C&P'!V30 | G32: ='01_C&P'!W30 | H32: ='01_C&P'!X30 | I32: ='01_C&P'!Y30 | J32: ='01_C&P'!Z30
A33: ='01_C&P'!A31 -> 45993 | B33: ='01_C&P'!B31 -> RETIRO DE SOLADO EN PLANTA BAJA | C33: ='01_C&P'!C31 -> m² | D33: ='01_C&P'!D31 -> 118 | E33: ='01_C&P'!U31 | F33: ='01_C&P'!V31 | G33: ='01_C&P'!W31 | H33: ='01_C&P'!X31 | I33: ='01_C&P'!Y31 | J33: ='01_C&P'!Z31
... A35: ='01_C&P'!A33 -> 2.14 | B35: ='01_C&P'!B33 -> DEMOLICION TOTAL DE ITEMS ANTERIORES | C35: ='01_C&P'!C33 -> gl | D35: ='01_C&P'!D33 -> 1 | E35: ='01_C&P'!U33 -> 0 | F35: ='01_C&P'!V33 -> 35013641 | G35: ='01_C&P'!W33 -> 35013641 | H35: ='01_C&P'!X33 -> 0 | I35: ='01_C&P'!Y33 -> 35013641 | J35: ='01_C&P'!Z33 -> 35013641
A36: ='01_C&P'!A34 -> 3-ESTRUCTURA | C36: ='01_C&P'!C34 | E36: ='01_C&P'!E34 | G36: ='01_C&P'!G34 | I36: ='01_C&P'!I34
A37: ='01_C&P'!A35 -> FUNDACIONES
A38: ='01_C&P'!A36 -> 3.0-1 | B38: ='01_C&P'!B36 -> EXCAVACION DE BASES PARA REFORZAR ESTRUCTURA | C38: ='01_C&P'!C36 -> unid. | D38: ='01_C&P'!D36 -> 14 | E38: ='01_C&P'!U36 -> 0 | F38: ='01_C&P'!V36 -> 969800.46 | G38: ='01_C&P'!W36 -> 969800.46 | H38: ='01_C&P'!X36 -> 0 | I38: ='01_C&P'!Y36 -> 13577206 | J38: ='01_C&P'!Z36 -> 13577206
A39: ='01_C&P'!A37 -> 3.0-2 | B39: ='01_C&P'!B37 -> EJECUCION DE BASES DE H 30 100x100 + TRONCO 25X25x100 + TENSORES 30x40cm | C39: ='01_C&P'!C37 -> unid. | D39: ='01_C&P'!D37 -> 14 | E39: ='01_C&P'!U37 -> 206681.2 | F39: ='01_C&P'!V37 -> 734814.41 | G39: ='01_C&P'!W37 -> 941495.61 | H39: ='01_C&P'!X37 -> 2893536.9 | I39: ='01_C&P'!Y37 -> 10287402 | J39: ='01_C&P'!Z37 -> 13180939
A40: ='01_C&P'!A38 -> 3.0-3 | B40: ='01_C&P'!B38 -> RELLENO DE FUNDACIONES (TOSCA + HORMIGON EN PLATEA DE FUNDACION) | C40: ='01_C&P'!C38 -> unid. | D40: ='01_C&P'!D38 -> 14 | E40: ='01_C&P'!U38 -> 125774.59 | F40: ='01_C&P'!V38 -> 264491.04 | G40: ='01_C&P'!W38 -> 390265.63 | H40: ='01_C&P'!X38 -> 1760844.3 | I40: ='01_C&P'!Y38 -> 3702874.5 | J40: ='01_C&P'!Z38 -> 5463718.8
A41: ='01_C&P'!A39 -> SOBRE PLANTA BAJA | C41: ='01_C&P'!C39 | E41: ='01_C&P'!E39 | G41: ='01_C&P'!G39 | I41: ='01_C&P'!I39
A42: ='01_C&P'!A40 -> 3.1-1 | B42: ='01_C&P'!B40 -> VIGAS H30 SOBRE PLANTA BAJA 0,15x0,35 (Hierros 6 ∅8 con estribos ∅ 6 c/14) | C42: ='01_C&P'!C40 -> m | D42: ='01_C&P'!D40 -> 29 | E42: ='01_C&P'!U40 -> 17958.966 | F42: ='01_C&P'!V40 -> 192096.17 | G42: ='01_C&P'!W40 -> 210055.13 | H42: ='01_C&P'!X40 -> 520810 | I42: ='01_C&P'!Y40 -> 5570788.9 | J42: ='01_C&P'!Z40 -> 6091598.9
A43: ='01_C&P'!A41 -> 3.1-2 | B43: ='01_C&P'!B41 -> VIGAS METALICAS + COLUMNA METALICA | C43: ='01_C&P'!C41 -> m | D43: ='01_C&P'!D41 -> 8.3 | E43: ='01_C&P'!U41 -> 139757.45 | F43: ='01_C&P'!V41 -> 297419.64 | G43: ='01_C&P'!W41 -> 437177.09 | H43: ='01_C&P'!X41 -> 1159986.8 | I43: ='01_C&P'!Y41 -> 2468583 | J43: ='01_C&P'!Z41 -> 3628569.8
...

Sheet RESUMEN VENTA
A1: CASA LUGONES
A2: Arq. Andres Barone
A3: Pilar, 12 de septiembre de 2025,
A5: PLANILLA DE RESUMÉN DE PRESUPUESTO
H6: TC = | I6: 1450
D7: MAT. | E7: M. O. | F7: SUBTOTAL | G7: SUP | H7: VALOR / m ($) | I7: VALOR / m (u$u)
A8: 1- TAREAS PRELIMINARES | D8: =SUM('01_VENTA'!H11:H20) -> 800000 | E8: =SUM('01_VENTA'!I11:I20) -> 20489239 | F8: =SUM('01_VENTA'!J11:J20) -> 21289239 | G8: 1 | H8: =F8/G8 -> 21289239 | I8: =H8/$I$6 -> 14682.234
A9: 2- DEMOLICION | D9: ='01_VENTA'!H35 -> 0 | E9: ='01_VENTA'!I35 -> 35013641 | F9: ='01_VENTA'!J35 -> 35013641 | G9: 1 | H9: =F9/G9 -> 35013641 | I9: =H9/$I$6 -> 24147.338
A10: ='01_VENTA'!A36 -> 3-ESTRUCTURA
A11: ='01_VENTA'!A37 -> FUNDACIONES | D11: =SUM('01_VENTA'!H38:H40) -> 4654381.2 | E11: =SUM('01_VENTA'!I38:I40) -> 27567483 | F11: =SUM('01_VENTA'!J38:J40) -> 32221864 | G11: 125 | H11: =F11/G11 -> 257774.91 | I11: =H11/$I$6 -> 177.7758 | J11: =SUM(I11:I25) -> 2379.0751 | K11: SUP TOTAL
A12: ='01_VENTA'!A41 -> SOBRE PLANTA BAJA | D12: =SUM('01_VENTA'!H42:H46) -> 4598881.8 | E12: =SUM('01_VENTA'!I42:I46) -> 16048528 | F12: =SUM('01_VENTA'!J42:J46) -> 20647410 | G12: 77 | H12: =F12/G12 -> 268148.18 | I12: =H12/$I$6 -> 184.92978 | K12: INTERIOR
A13: ='01_VENTA'!A47 -> SOBRE PLANTA ALTA | D13: =SUM('01_VENTA'!H48:H51) -> 5516213.5 | E13: =SUM('01_VENTA'!I48:I51) -> 17334512 | F13: =SUM('01_VENTA'!J48:J51) -> 22850725 | G13: 71 | H13: =F13/G13 -> 321841.2 | I13: =H13/$I$6 -> 221.95945 | K13: INTERIOR
A14: ='01_VENTA'!A52 -> CAJA DE ESCALERA | D14: =SUM('01_VENTA'!H53:H57) -> 2106487.5 | E14: =SUM('01_VENTA'!I53:I57) -> 14961689 | F14: =SUM('01_VENTA'!J53:J57) -> 17068177 | G14: =7*3 -> 21 | H14: =F14/G14 -> 812770.32 | I14: =H14/$I$6 -> 560.53125 | K14: 7m3 x 3 | L14: PB+PA+TERRAZA
A15: ='01_VENTA'!A58 -> 4-ALBAÑILERIA
A16: ='01_VENTA'!A59 -> PLANTA BAJA | D16: =SUM('01_VENTA'!H60:H71) -> 5449369.2 | E16: =SUM('01_VENTA'!I60:I71) -> 20713339 | F16: =SUM('01_VENTA'!J60:J71) -> 26162708 | G16: 75 | H16: =F16/G16 -> 348836.11 | I16: =H16/$I$6 -> 240.57663
A17: ='01_VENTA'!A72 -> PLANTA PRIMER PISO | D17: =SUM('01_VENTA'!H73:H79) -> 6517161.3 | E17: =SUM('01_VENTA'!I73:I79) -> 23771121 | F17: =SUM('01_VENTA'!J73:J79) -> 30288282 | G17: 71 | H17: =F17/G17 -> 426595.52 | I17: =H17/$I$6 -> 294.20381
A18: ='01_VENTA'!A80 -> CAJA DE ESCALERA | D18: =SUM('01_VENTA'!H81:H85) -> 1239632.7 | E18: =SUM('01_VENTA'!I81:I85) -> 4665621.9 | F18: =SUM('01_VENTA'!J81:J85) -> 5905254.6 | G18: =7*3 -> 21 | H18: =F18/G18 -> 281202.6 | I18: =H18/$I$6 -> 193.93283
A19: ='01_VENTA'!A86 -> 5-INSTALACIONES
A20: ='01_VENTA'!A87 -> SANITARIA | D20: =SUM('01_VENTA'!H88:H92) -> 7381522 | E20: =SUM('01_VENTA'!I88:I92) -> 18379972 | F20: =SUM('01_VENTA'!J88:J92) -> 25761494 | G20: =109+70 -> 179 | H20: =F20/G20 -> 143918.96 | I20: =H20/$I$6 -> 99.254455 | K20: INTERIOR + EXTERIOR
A21: ='01_VENTA'!A93 -> ELECTRICA | D21: =SUM('01_VENTA'!H94:H95) -> 3889274.1 | E21: =SUM('01_VENTA'!I94:I95) -> 5286549.9 | F21: =SUM('01_VENTA'!J94:J95) -> 9175824 | G21: 147 | H21: =F21/G21 -> 62420.571 | I21: =H21/$I$6 -> 43.04867 | K21: INTERIOR
A22: ='01_VENTA'!A96 -> ACONDICIONAMIENTO TERMICO | D22: =SUM('01_VENTA'!H97:H98) -> 3464471 | E22: =SUM('01_VENTA'!I97:I98) -> 5282767.6 | F22: =SUM('01_VENTA'!J97:J98) -> 8747238.6 | G22: 147 | H22: =F22/G22 -> 59505.024 | I22: =H22/$I$6 -> 41.037948 | K22: INTERIOR
A23: ='01_VENTA'!A99 -> 6- CIELORRASOS | D23: =SUM('01_VENTA'!H100) -> 0 | E23: =SUM('01_VENTA'!I100) -> 13426623 | F23: =SUM('01_VENTA'!J100) -> 13426623 | G23: 147 | H23: =F23/G23 -> 91337.571 | I23: =H23/$I$6 -> 62.991428
A24: ='01_VENTA'!A101 -> 7- TERMINACIONES | D24: =SUM('01_VENTA'!H102:H108) -> 13217348 | E24: =SUM('01_VENTA'!I102:I108) -> 23912067 | F24: =SUM('01_VENTA'!J102:J108) -> 37129415 | G24: 147 | H24: =F24/G24 -> 252581.05 | I24: =H24/$I$6 -> 174.19383
A25: ='01_VENTA'!A109 -> 8-CUBIERTA | D25: =SUM('01_VENTA'!H110:H111) -> 2533024.2 | E25: =SUM('01_VENTA'!I110:I111) -> 7776036.5 | F25: =SUM('01_VENTA'!J110:J111) -> 10309061 | G25: 84 | H25: =F25/G25 -> 122726.91 | I25: =H25/$I$6 -> 84.63925
E26: TOTAL = | F26: =SUM(F8:F25) -> 3.1599696e+08
E27: TOTAL (u$u) = | F27: =F26/I6 -> 217928.93
F29: =G12+G13+G14 -> 169
F30: =F27/F29 -> 1289.5203 | G30: =(F27-I8-I9)/F29 -> 1059.7595

Sheet 2.14
A1: ='01_C&P'!A1 -> CASA LUGONES
A3: ='01_C&P'!A33 -> 2.14 | B3: =IF($A3=0,"",VLOOKUP($A3,'01_C&P'!$A$9:$D$172,2,FALSE)) -> DEMOLICION TOTAL DE ITEMS ANTERIORES | H3: =IF($A3=0,"",VLOOKUP($A3,'01_C&P'!$A$9:$D$172,4,FALSE)) -> 1 | I3: =IF($A3=0,"",VLOOKUP($A3,'01_C&P'!$A$9:$D$172,3,FALSE)) -> gl
A5: MATERIALES
A6: Código | B6: Descripción | C6: Unidad | D6: Cantidad | F6: Desperdicio | G6: Cantidad + Desperdicio | H6: Precio Unitario | I6: Subtotal
B7: =IF($A7=0,"",VLOOKUP($A7,'00_Mat'!$A$4:$J$1135,2,FALSE)) | C7: =IF($A7=0,"",VLOOKUP($A7,'00_Mat'!$A$4:$J$1135,3,FALSE)) | F7: 0.1 | G7: =ROUNDUP((D7+(D7*F7)),0) -> 0 | H7: =IF($A7=0,"",VLOOKUP($A7,'00_Mat'!$A$4:$J$1135,5,FALSE)) | I7: =H7*G7 -> 0
B8: =IF($A8=0,"",VLOOKUP($A8,'00_Mat'!$A$4:$J$1135,2,FALSE)) | C8: =IF($A8=0,"",VLOOKUP($A8,'00_Mat'!$A$4:$J$1135,3,FALSE)) | F8: 0.1 | G8: =ROUNDUP((D8+(D8*F8)),0) -> 0 | H8: =IF($A8=0,"",VLOOKUP($A8,'00_Mat'!$A$4:$J$1135,5,FALSE)) | I8: =H8*G8 -> 0
B9: =IF($A9=0,"",VLOOKUP($A9,'00_Mat'!$A$4:$J$1135,2,FALSE)) | C9: =IF($A9=0,"",VLOOKUP($A9,'00_Mat'!$A$4:$J$1135,3,FALSE)) | F9: 0.1 | G9: =ROUNDUP((D9+(D9*F9)),0) -> 0 | H9: =IF($A9=0,"",VLOOKUP($A9,'00_Mat'!$A$4:$J$1135,5,FALSE)) | I9: =H9*G9 -> 0
B10: =IF($A10=0,"",VLOOKUP($A10,'00_Mat'!$A$4:$J$1135,2,FALSE)) | C10: =IF($A10=0,"",VLOOKUP($A10,'00_Mat'!$A$4:$J$1135,3,FALSE)) | F10: 0.1 | G10: =ROUNDUP((D10+(D10*F10)),0) -> 0 | H10: =IF($A10=0,"",VLOOKUP($A10,'00_Mat'!$A$4:$J$1135,5,FALSE)) | I10: =H10*G10 -> 0
B11: =IF($A11=0,"",VLOOKUP($A11,'00_Mat'!$A$4:$J$1135,2,FALSE)) | C11: =IF($A11=0,"",VLOOKUP($A11,'00_Mat'!$A$4:$J$1135,3,FALSE)) | F11: 0.1 | G11: =ROUNDUP((D11+(D11*F11)),0) -> 0 | H11: =IF($A11=0,"",VLOOKUP($A11,'00_Mat'!$A$4:$J$1135,5,FALSE)) | I11: =H11*G11 -> 0
B12: =IF($A12=0,"",VLOOKUP($A12,'00_Mat'!$A$4:$J$1135,2,FALSE)) | C12: =IF($A12=0,"",VLOOKUP($A12,'00_Mat'!$A$4:$J$1135,3,FALSE)) | F12: 0.1 | G12: =ROUNDUP((D12+(D12*F12)),0) -> 0 | H12: =IF($A12=0,"",VLOOKUP($A12,'00_Mat'!$A$4:$J$1135,5,FALSE)) | I12: =H12*G12 -> 0
B13: =IF($A13=0,"",VLOOKUP($A13,'00_Mat'!$A$4:$J$1135,2,FALSE)) | C13: =IF($A13=0,"",VLOOKUP($A13,'00_Mat'!$A$4:$J$1135,3,FALSE)) | F13: 0.1 | G13: =ROUNDUP((D13+(D13*F13)),0) -> 0 | H13: =IF($A13=0,"",VLOOKUP($A13,'00_Mat'!$A$4:$J$1135,5,FALSE)) | I13: =H13*G13 -> 0
B14: =IF($A14=0,"",VLOOKUP($A14,'00_Mat'!$A$4:$J$1135,2,FALSE)) | C14: =IF($A14=0,"",VLOOKUP($A14,'00_Mat'!$A$4:$J$1135,3,FALSE)) | F14: 0.1 | G14: =ROUNDUP((D14+(D14*F14)),0) -> 0 | H14: =IF($A14=0,"",VLOOKUP($A14,'00_Mat'!$A$4:$J$1135,5,FALSE)) | I14: =H14*G14 -> 0
B15: =IF($A15=0,"",VLOOKUP($A15,'00_Mat'!$A$4:$J$1135,2,FALSE)) | C15: =IF($A15=0,"",VLOOKUP($A15,'00_Mat'!$A$4:$J$1135,3,FALSE)) | F15: 0.1 | G15: =ROUNDUP((D15+(D15*F15)),0) -> 0 | H15: =IF($A15=0,"",VLOOKUP($A15,'00_Mat'!$A$4:$J$1135,5,FALSE)) | I15: =H15*G15 -> 0
B16: =IF($A16=0,"",VLOOKUP($A16,'00_Mat'!$A$4:$J$1135,2,FALSE)) | C16: =IF($A16=0,"",VLOOKUP($A16,'00_Mat'!$A$4:$J$1135,3,FALSE)) | F16: 0.1 | G16: =ROUNDUP((D16+(D16*F16)),0) -> 0 | H16: =IF($A16=0,"",VLOOKUP($A16,'00_Mat'!$A$4:$J$1135,5,FALSE)) | I16: =H16*G16 -> 0
B17: =IF($A17=0,"",VLOOKUP($A17,'00_Mat'!$A$4:$J$1135,2,FALSE)) | C17: =IF($A17=0,"",VLOOKUP($A17,'00_Mat'!$A$4:$J$1135,3,FALSE)) | F17: 0.1 | G17: =ROUNDUP((D17+(D17*F17)),0) -> 0 | H17: =IF($A17=0,"",VLOOKUP($A17,'00_Mat'!$A$4:$J$1135,5,FALSE)) | I17: =H17*G17 -> 0
B18: =IF($A18=0,"",VLOOKUP($A18,'00_Mat'!$A$4:$J$1135,2,FALSE)) | C18: =IF($A18=0,"",VLOOKUP($A18,'00_Mat'!$A$4:$J$1135,3,FALSE)) | F18: 0.1 | G18: =ROUNDUP((D18+(D18*F18)),0) -> 0 | H18: =IF($A18=0,"",VLOOKUP($A18,'00_Mat'!$A$4:$J$1135,5,FALSE)) | I18: =H18*G18 -> 0
A20: TOTAL MATERIALES | I20: =SUM(I7:I18) -> 0
A21: =$I$3 -> gl | I21: =$H$3 -> 1
A22: TOTAL x | B22: =A21 -> gl | I22: =I20/I21 -> 0
A25: MANO DE OBRA - PERSONAS
A26: Código | B26: Descripción | C26: Unidad | D26: Cantidad | E26: Dias | F26: Desperdicio | G26: Cantidad + Desperdicio | H26: Precio Unitario | I26: Subtotal
A27: mo-ca | B27: =IF($A27=0,"",VLOOKUP($A27,'00_MO'!$A$4:$D$7,2,FALSE)) -> Capataz | C27: =IF($A27=0,"",VLOOKUP($A27,'00_MO'!$A$4:$D$7,3,FALSE)) -> u | D27: 1 | E27: 15 | F27: 0.25 | G27: =ROUNDUP(((D27*E27)*(1+F27)),0) -> 19 | H27: =IF($A27=0,"",VLOOKUP($A27,'00_MO'!$A$4:$D$7,4,FALSE)) -> 90000 | I27: =G27*H27 -> 1710000
A28: mo-of | B28: =IF($A28=0,"",VLOOKUP($A28,'00_MO'!$A$4:$D$7,2,FALSE)) -> Oficial | C28: =IF($A28=0,"",VLOOKUP($A28,'00_MO'!$A$4:$D$7,3,FALSE)) -> u | D28: 2 | E28: 15 | F28: 0.25 | G28: =ROUNDUP(((D28*E28)*(1+F28)),0) -> 38 | H28: =IF($A28=0,"",VLOOKUP($A28,'00_MO'!$A$4:$D$7,4,FALSE)) -> 75000 | I28: =G28*H28 -> 2850000
A29: mo-ay | B29: =IF($A29=0,"",VLOOKUP($A29,'00_MO'!$A$4:$D$7,2,FALSE)) -> Ayudante | C29: =IF($A29=0,"",VLOOKUP($A29,'00_MO'!$A$4:$D$7,3,FALSE)) -> u | D29: 1 | E29: 15 | F29: 0.25 | G29: =ROUNDUP(((D29*E29)*(1+F29)),0) -> 19 | H29: =IF($A29=0,"",VLOOKUP($A29,'00_MO'!$A$4:$D$7,4,FALSE)) -> 60000 | I29: =H29*G29 -> 1140000
A30: mo-ay | B30: =IF($A30=0,"",VLOOKUP($A30,'00_MO'!$A$4:$D$7,2,FALSE)) -> Ayudante | C30: =IF($A30=0,"",VLOOKUP($A30,'00_MO'!$A$4:$D$7,3,FALSE)) -> u | D30: 1 | E30: 7 | F30: 0.1 | G30: =ROUNDUP(((D30*E30)*(1+F30)),0) -> 8 | H30: =IF($A30=0,"",VLOOKUP($A30,'00_MO'!$A$4:$D$7,4,FALSE)) -> 60000 | I30: =H30*G30 -> 480000 | J30: PICADO DE INSTALACIONES SANITARIAS
B31: =IF($A31=0,"",VLOOKUP($A31,'00_MO'!$A$4:$D$7,2,FALSE)) | C31: =IF($A31=0,"",VLOOKUP($A31,'00_MO'!$A$4:$D$7,3,FALSE)) | G31: =ROUNDUP(((D31*E31)*(1+F31)),0) -> 0 | H31: =IF($A31=0,"",VLOOKUP($A31,'00_MO'!$A$4:$D$7,4,FALSE))
B32: =IF($A32=0,"",VLOOKUP($A32,'00_MO'!$A$4:$D$7,2,FALSE)) | C32: =IF($A32=0,"",VLOOKUP($A32,'00_MO'!$A$4:$D$7,3,FALSE)) | G32: =ROUNDUP(((D32*E32)*(1+F32)),0) -> 0 | H32: =IF($A32=0,"",VLOOKUP($A32,'00_MO'!$A$4:$D$7,4,FALSE))
A34: TOTAL | I34: =SUM(I27:I32) -> 6180000
A35: =$I$3 -> gl | I35: =$H$3 -> 1
A36: TOTAL x | B36: =A35 -> gl | I36: =I34/I35 -> 6180000
A39: MANO DE OBRA - EQUIPOS
A40: Código | B40: Descripción | C40: Unidad | D40: Cantidad | E40: Dias | F40: Desperdicio | G40: Cantidad + Desperdicio | H40: Precio Unitario | I40: Subtotal
A41: e-vol | B41: =IF($A41=0,"",VLOOKUP($A41,'00_Eq'!$A$4:$D$100,2,FALSE)) -> Volquete | C41: =IF($A41=0,"",VLOOKUP($A41,'00_Eq'!$A$4:$D$100,3,FALSE)) -> u | D41: 21 | E41: 1 | F41: 0.25 | G41: =ROUNDUP(((D41*E41)*(1+F41)),0) -> 27 | H41: =IF($A41=0,"",VLOOKUP($A41,'00_Eq'!$A$4:$D$100,4,FALSE)) -> 200000 | I41: =G41*H41 -> 5400000 | J41: PARA LOSA DE FUNDACION EXISTENTE
A42: E-MAR | B42: =IF($A42=0,"",VLOOKUP($A42,'00_Eq'!$A$4:$D$100,2,FALSE)) -> Martillete | C42: =IF($A42=0,"",VLOOKUP($A42,'00_Eq'!$A$4:$D$100,3,FALSE)) -> u | D42: 1 | E42: 21 | F42: 0.25 | G42: =ROUNDUP(((D42*E42)*(1+F42)),0) -> 27 | H42: =IF($A42=0,"",VLOOKUP($A42,'00_Eq'!$A$4:$D$100,4,FALSE)) -> 60000 | I42: =G42*H42 -> 1620000 | J42: PARA COLUMAS, VIGAS EN PB Y LOSA SOBRE PB
B43: =IF($A43=0,"",VLOOKUP($A43,'00_Eq'!$A$4:$D$100,2,FALSE)) | C43: =IF($A43=0,"",VLOOKUP($A43,'00_Eq'!$A$4:$D$100,3,FALSE)) | G43: =ROUNDUP(((D43*E43)*(1+F43)),0) -> 0 | H43: =IF($A43=0,"",VLOOKUP($A43,'00_Eq'!$A$4:$D$100,4,FALSE)) | I43: =G43*H43 -> 0
A44: E-MAR | B44: =IF($A44=0,"",VLOOKUP($A44,'00_Eq'!$A$4:$D$100,2,FALSE)) -> Martillete | C44: =IF($A44=0,"",VLOOKUP($A44,'00_Eq'!$A$4:$D$100,3,FALSE)) -> u | D44: 1 | E44: 7 | F44: 0.1 | G44: =ROUNDUP(((D44*E44)*(1+F44)),0) -> 8 | H44: =IF($A44=0,"",VLOOKUP($A44,'00_Eq'!$A$4:$D$100,4,FALSE)) -> 60000 | I44: =G44*H44 -> 480000 | J44: PARA INSTALACONES SANITARIAS
B45: =IF($A45=0,"",VLOOKUP($A45,'00_Eq'!$A$4:$D$100,2,FALSE)) | C45: =IF($A45=0,"",VLOOKUP($A45,'00_Eq'!$A$4:$D$100,3,FALSE)) | G45: =ROUNDUP(((D45*E45)*(1+F45)),0) -> 0 | H45: =IF($A45=0,"",VLOOKUP($A45,'00_Eq'!$A$4:$D$100,4,FALSE))
B46: =IF($A46=0,"",VLOOKUP($A46,'00_Eq'!$A$4:$D$100,2,FALSE)) | C46: =IF($A46=0,"",VLOOKUP($A46,'00_Eq'!$A$4:$D$100,3,FALSE)) | G46: =ROUNDUP(((D46*E46)*(1+F46)),0) -> 0 | H46: =IF($A46=0,"",VLOOKUP($A46,'00_Eq'!$A$4:$D$100,4,FALSE))
A48: TOTAL | I48: =SUM(I41:I46) -> 7500000
A49: =$I$3 -> gl | I49: =$H$3 -> 1
...

Sheet 3.0-1
A1: ='01_C&P'!A1 -> CASA LUGONES
A3: ='01_C&P'!A36 -> 3.0-1 | B3: =IF($A3=0,"",VLOOKUP($A3,'01_C&P'!$A$9:$D$172,2,FALSE)) -> EXCAVACION DE BASES PARA REFORZAR ESTRUCTURA | H3: =IF($A3=0,"",VLOOKUP($A3,'01_C&P'!$A$9:$D$172,4,FALSE)) -> 14 | I3: =IF($A3=0,"",VLOOKUP($A3,'01_C&P'!$A$9:$D$172,3,FALSE)) -> unid.
A5: MATERIALES
A6: Código | B6: Descripción | C6: Unidad | D6: Cantidad | F6: Desperdicio | G6: Cantidad + Desperdicio | H6: Precio Unitario | I6: Subtotal
B7: =IF($A7=0,"",VLOOKUP($A7,'00_Mat'!$A$4:$J$1135,2,FALSE)) | C7: =IF($A7=0,"",VLOOKUP($A7,'00_Mat'!$A$4:$J$1135,3,FALSE)) | G7: =ROUNDUP((D7+(D7*F7)),0) -> 0 | H7: =IF($A7=0,"",VLOOKUP($A7,'00_Mat'!$A$4:$J$1135,5,FALSE)) | I7: =H7*G7 -> 0
B8: =IF($A8=0,"",VLOOKUP($A8,'00_Mat'!$A$4:$J$1135,2,FALSE)) | C8: =IF($A8=0,"",VLOOKUP($A8,'00_Mat'!$A$4:$J$1135,3,FALSE)) | G8: =ROUNDUP((D8+(D8*F8)),0) -> 0 | H8: =IF($A8=0,"",VLOOKUP($A8,'00_Mat'!$A$4:$J$1135,5,FALSE)) | I8: =H8*G8 -> 0
B9: =IF($A9=0,"",VLOOKUP($A9,'00_Mat'!$A$4:$J$1135,2,FALSE)) | C9: =IF($A9=0,"",VLOOKUP($A9,'00_Mat'!$A$4:$J$1135,3,FALSE)) | G9: =ROUNDUP((D9+(D9*F9)),0) -> 0 | H9: =IF($A9=0,"",VLOOKUP($A9,'00_Mat'!$A$4:$J$1135,5,FALSE)) | I9: =H9*G9 -> 0
B10: =IF($A10=0,"",VLOOKUP($A10,'00_Mat'!$A$4:$J$1135,2,FALSE)) | C10: =IF($A10=0,"",VLOOKUP($A10,'00_Mat'!$A$4:$J$1135,3,FALSE)) | G10: =ROUNDUP((D10+(D10*F10)),0) -> 0 | H10: =IF($A10=0,"",VLOOKUP($A10,'00_Mat'!$A$4:$J$1135,5,FALSE)) | I10: =H10*G10 -> 0
B11: =IF($A11=0,"",VLOOKUP($A11,'00_Mat'!$A$4:$J$1135,2,FALSE)) | C11: =IF($A11=0,"",VLOOKUP($A11,'00_Mat'!$A$4:$J$1135,3,FALSE)) | G11: =ROUNDUP((D11+(D11*F11)),0) -> 0 | H11: =IF($A11=0,"",VLOOKUP($A11,'00_Mat'!$A$4:$J$1135,5,FALSE)) | I11: =H11*G11 -> 0
B12: =IF($A12=0,"",VLOOKUP($A12,'00_Mat'!$A$4:$J$1135,2,FALSE)) | C12: =IF($A12=0,"",VLOOKUP($A12,'00_Mat'!$A$4:$J$1135,3,FALSE)) | G12: =ROUNDUP((D12+(D12*F12)),0) -> 0 | H12: =IF($A12=0,"",VLOOKUP($A12,'00_Mat'!$A$4:$J$1135,5,FALSE)) | I12: =H12*G12 -> 0
B13: =IF($A13=0,"",VLOOKUP($A13,'00_Mat'!$A$4:$J$1135,2,FALSE)) | C13: =IF($A13=0,"",VLOOKUP($A13,'00_Mat'!$A$4:$J$1135,3,FALSE)) | G13: =ROUNDUP((D13+(D13*F13)),0) -> 0 | H13: =IF($A13=0,"",VLOOKUP($A13,'00_Mat'!$A$4:$J$1135,5,FALSE)) | I13: =H13*G13 -> 0
B14: =IF($A14=0,"",VLOOKUP($A14,'00_Mat'!$A$4:$J$1135,2,FALSE)) | C14: =IF($A14=0,"",VLOOKUP($A14,'00_Mat'!$A$4:$J$1135,3,FALSE)) | G14: =ROUNDUP((D14+(D14*F14)),0) -> 0 | H14: =IF($A14=0,"",VLOOKUP($A14,'00_Mat'!$A$4:$J$1135,5,FALSE)) | I14: =H14*G14 -> 0
B15: =IF($A15=0,"",VLOOKUP($A15,'00_Mat'!$A$4:$J$1135,2,FALSE)) | C15: =IF($A15=0,"",VLOOKUP($A15,'00_Mat'!$A$4:$J$1135,3,FALSE)) | G15: =ROUNDUP((D15+(D15*F15)),0) -> 0 | H15: =IF($A15=0,"",VLOOKUP($A15,'00_Mat'!$A$4:$J$1135,5,FALSE)) | I15: =H15*G15 -> 0
B16: =IF($A16=0,"",VLOOKUP($A16,'00_Mat'!$A$4:$J$1135,2,FALSE)) | C16: =IF($A16=0,"",VLOOKUP($A16,'00_Mat'!$A$4:$J$1135,3,FALSE)) | G16: =ROUNDUP((D16+(D16*F16)),0) -> 0 | H16: =IF($A16=0,"",VLOOKUP($A16,'00_Mat'!$A$4:$J$1135,5,FALSE)) | I16: =H16*G16 -> 0
B17: =IF($A17=0,"",VLOOKUP($A17,'00_Mat'!$A$4:$J$1135,2,FALSE)) | C17: =IF($A17=0,"",VLOOKUP($A17,'00_Mat'!$A$4:$J$1135,3,FALSE)) | G17: =ROUNDUP((D17+(D17*F17)),0) -> 0 | H17: =IF($A17=0,"",VLOOKUP($A17,'00_Mat'!$A$4:$J$1135,5,FALSE)) | I17: =H17*G17 -> 0
B18: =IF($A18=0,"",VLOOKUP($A18,'00_Mat'!$A$4:$J$1135,2,FALSE)) | C18: =IF($A18=0,"",VLOOKUP($A18,'00_Mat'!$A$4:$J$1135,3,FALSE)) | G18: =ROUNDUP((D18+(D18*F18)),0) -> 0 | H18: =IF($A18=0,"",VLOOKUP($A18,'00_Mat'!$A$4:$J$1135,5,FALSE)) | I18: =H18*G18 -> 0
... B21: =IF($A21=0,"",VLOOKUP($A21,'00_Mat'!$A$4:$J$1135,2,FALSE)) | C21: =IF($A21=0,"",VLOOKUP($A21,'00_Mat'!$A$4:$J$1135,3,FALSE)) | G21: =ROUNDUP((D21+(D21*F21)),0) -> 0 | H21: =IF($A21=0,"",VLOOKUP($A21,'00_Mat'!$A$4:$J$1135,5,FALSE)) | I21: =H21*G21 -> 0
A23: TOTAL MATERIALES | I23: =SUM(I7:I18) -> 0
A24: =$I$3 -> unid. | I24: =$H$3 -> 14
A25: TOTAL x | B25: =A24 -> unid. | I25: =I23/I24 -> 0
A28: MANO DE OBRA - PERSONAS
A29: Código | B29: Descripción | C29: Unidad | D29: Cantidad | E29: Dias | F29: Desperdicio | G29: Cantidad + Desperdicio | H29: Precio Unitario | I29: Subtotal
A30: MO-CA | B30: =IF($A30=0,"",VLOOKUP($A30,'00_MO'!$A$4:$D$7,2,FALSE)) -> Capataz | C30: =IF($A30=0,"",VLOOKUP($A30,'00_MO'!$A$4:$D$7,3,FALSE)) -> u | D30: 1 | E30: 12 | F30: 0.25 | G30: =ROUNDUP(((D30*E30)*(1+F30)),0) -> 15 | H30: =IF($A30=0,"",VLOOKUP($A30,'00_MO'!$A$4:$D$7,4,FALSE)) -> 90000 | I30: =G30*H30 -> 1350000
A31: MO-OF | B31: =IF($A31=0,"",VLOOKUP($A31,'00_MO'!$A$4:$D$7,2,FALSE)) -> Oficial | C31: =IF($A31=0,"",VLOOKUP($A31,'00_MO'!$A$4:$D$7,3,FALSE)) -> u | D31: 2 | E31: 12 | F31: 0.25 | G31: =ROUNDUP(((D31*E31)*(1+F31)),0) -> 30 | H31: =IF($A31=0,"",VLOOKUP($A31,'00_MO'!$A$4:$D$7,4,FALSE)) -> 75000 | I31: =G31*H31 -> 2250000
A32: MO-AY | B32: =IF($A32=0,"",VLOOKUP($A32,'00_MO'!$A$4:$D$7,2,FALSE)) -> Ayudante | C32: =IF($A32=0,"",VLOOKUP($A32,'00_MO'!$A$4:$D$7,3,FALSE)) -> u | D32: 1 | E32: 12 | F32: 0.25 | G32: =ROUNDUP(((D32*E32)*(1+F32)),0) -> 15 | H32: =IF($A32=0,"",VLOOKUP($A32,'00_MO'!$A$4:$D$7,4,FALSE)) -> 60000 | I32: =G32*H32 -> 900000
B33: =IF($A33=0,"",VLOOKUP($A33,'00_MO'!$A$4:$D$7,2,FALSE)) | C33: =IF($A33=0,"",VLOOKUP($A33,'00_MO'!$A$4:$D$7,3,FALSE)) | G33: =ROUNDUP(((D33*E33)*(1+F33)),0) -> 0 | H33: =IF($A33=0,"",VLOOKUP($A33,'00_MO'!$A$4:$D$7,4,FALSE)) | I33: =G33*H33 -> 0
B34: =IF($A34=0,"",VLOOKUP($A34,'00_MO'!$A$4:$D$7,2,FALSE)) | C34: =IF($A34=0,"",VLOOKUP($A34,'00_MO'!$A$4:$D$7,3,FALSE)) | G34: =ROUNDUP(((D34*E34)*(1+F34)),0) -> 0 | H34: =IF($A34=0,"",VLOOKUP($A34,'00_MO'!$A$4:$D$7,4,FALSE)) | I34: =G34*H34 -> 0
B35: =IF($A35=0,"",VLOOKUP($A35,'00_MO'!$A$4:$D$7,2,FALSE)) | C35: =IF($A35=0,"",VLOOKUP($A35,'00_MO'!$A$4:$D$7,3,FALSE)) | G35: =ROUNDUP(((D35*E35)*(1+F35)),0) -> 0 | H35: =IF($A35=0,"",VLOOKUP($A35,'00_MO'!$A$4:$D$7,4,FALSE)) | I35: =G35*H35 -> 0
A37: TOTAL | I37: =SUM(I30:I35) -> 4500000
A38: =$I$3 -> unid. | I38: =$H$3 -> 14
A39: TOTAL x | B39: =A38 -> unid. | I39: =I37/I38 -> 321428.57
A42: MANO DE OBRA - EQUIPOS
A43: Código | B43: Descripción | C43: Unidad | D43: Cantidad | E43: Dias | F43: Desperdicio | G43: Cantidad + Desperdicio | H43: Precio Unitario | I43: Subtotal
A44: E-RET | B44: =IF($A44=0,"",VLOOKUP($A44,'00_Eq'!$A$4:$D$100,2,FALSE)) -> Retiro x camion | C44: =IF($A44=0,"",VLOOKUP($A44,'00_Eq'!$A$4:$D$100,3,FALSE)) -> u | D44: 1 | E44: 3 | F44: 0.25 | G44: =ROUNDUP(((D44*E44)*(1+F44)),0) -> 4 | H44: =IF($A44=0,"",VLOOKUP($A44,'00_Eq'!$A$4:$D$100,4,FALSE)) -> 250000 | I44: =G44*H44 -> 1000000
B45: =IF($A45=0,"",VLOOKUP($A45,'00_Eq'!$A$4:$D$100,2,FALSE)) | C45: =IF($A45=0,"",VLOOKUP($A45,'00_Eq'!$A$4:$D$100,3,FALSE)) | G45: =ROUNDUP(((D45*E45)*(1+F45)),0) -> 0 | H45: =IF($A45=0,"",VLOOKUP($A45,'00_Eq'!$A$4:$D$100,4,FALSE)) | I45: =G45*H45 -> 0
B46: =IF($A46=0,"",VLOOKUP($A46,'00_Eq'!$A$4:$D$100,2,FALSE)) | C46: =IF($A46=0,"",VLOOKUP($A46,'00_Eq'!$A$4:$D$100,3,FALSE)) | G46: =ROUNDUP(((D46*E46)*(1+F46)),0) -> 0 | H46: =IF($A46=0,"",VLOOKUP($A46,'00_Eq'!$A$4:$D$100,4,FALSE)) | I46: =G46*H46 -> 0
B47: =IF($A47=0,"",VLOOKUP($A47,'00_Eq'!$A$4:$D$100,2,FALSE)) | C47: =IF($A47=0,"",VLOOKUP($A47,'00_Eq'!$A$4:$D$100,3,FALSE)) | G47: =ROUNDUP(((D47*E47)*(1+F47)),0) -> 0 | H47: =IF($A47=0,"",VLOOKUP($A47,'00_Eq'!$A$4:$D$100,4,FALSE)) | I47: =G47*H47 -> 0
B48: =IF($A48=0,"",VLOOKUP($A48,'00_Eq'!$A$4:$D$100,2,FALSE)) | C48: =IF($A48=0,"",VLOOKUP($A48,'00_Eq'!$A$4:$D$100,3,FALSE)) | G48: =ROUNDUP(((D48*E48)*(1+F48)),0) -> 0 | H48: =IF($A48=0,"",VLOOKUP($A48,'00_Eq'!$A$4:$D$100,4,FALSE))
B49: =IF($A49=0,"",VLOOKUP($A49,'00_Eq'!$A$4:$D$100,2,FALSE)) | C49: =IF($A49=0,"",VLOOKUP($A49,'00_Eq'!$A$4:$D$100,3,FALSE)) | G49: =ROUNDUP(((D49*E49)*(1+F49)),0) -> 0 | H49: =IF($A49=0,"",VLOOKUP($A49,'00_Eq'!$A$4:$D$100,4,FALSE))
A51: TOTAL | I51: =SUM(I44:I49) -> 1000000
...

Sheet 3.0-2
A1: ='01_C&P'!A1 -> CASA LUGONES
A3: ='01_C&P'!A37 -> 3.0-2 | B3: =IF($A3=0,"",VLOOKUP($A3,'01_C&P'!$A$9:$D$172,2,FALSE)) -> EJECUCION DE BASES DE H 30 100x100 + TRONCO 25X25x100 + TENSORES 30x40cm | H3: =IF($A3=0,"",VLOOKUP($A3,'01_C&P'!$A$9:$D$172,4,FALSE)) -> 14 | I3: =IF($A3=0,"",VLOOKUP($A3,'01_C&P'!$A$9:$D$172,3,FALSE)) -> unid. | L3: REFERENCIA: VIVIENDAS
A5: MATERIALES
A6: Código | B6: Descripción | C6: Unidad | D6: Cantidad | F6: Desperdicio | G6: Cantidad + Desperdicio | H6: Precio Unitario | I6: Subtotal | O6: m3 | P6: CANTIDAD
A7: H30 | B7: =IF($A7=0,"",VLOOKUP($A7,'00_Mat'!$A$4:$J$1135,2,FALSE)) -> Hormigon H30 | C7: =IF($A7=0,"",VLOOKUP($A7,'00_Mat'!$A$4:$J$1135,3,FALSE)) -> m3 | D7: =O7+O8+O9+O10 -> 11.4065 | F7: 0.1 | G7: =ROUNDUP((D7+(D7*F7)),0) -> 13 | H7: =IF($A7=0,"",VLOOKUP($A7,'00_Mat'!$A$4:$J$1135,5,FALSE)) -> 125280 | I7: =H7*G7 -> 1628640 | J7: BASES + TRONCO | L7: 5 bases excentricas 1x1 | N7: 100x100X30 | O7: =(1*1*0.3)*5 -> 1.5 | P7: 5
A8: HADN12 | B8: =IF($A8=0,"",VLOOKUP($A8,'00_Mat'!$A$4:$J$1135,2,FALSE)) -> Hierros ADN 420 Φ 12 | C8: =IF($A8=0,"",VLOOKUP($A8,'00_Mat'!$A$4:$J$1135,3,FALSE)) -> u | D8: =P7*((16*0.8)/12) -> 5.3333333 | F8: 0.1 | G8: =ROUNDUP((D8+(D8*F8)),0) -> 6 | H8: =IF($A8=0,"",VLOOKUP($A8,'00_Mat'!$A$4:$J$1135,5,FALSE)) -> 20442.5 | I8: =H8*G8 -> 122655 | L8: 9 bases medianera | N8: 60x120*30 | O8: =(0.6*1.2*0.3)*9 -> 1.944 | P8: 9
A9: HADN12 | B9: =IF($A9=0,"",VLOOKUP($A9,'00_Mat'!$A$4:$J$1135,2,FALSE)) -> Hierros ADN 420 Φ 12 | C9: =IF($A9=0,"",VLOOKUP($A9,'00_Mat'!$A$4:$J$1135,3,FALSE)) -> u | D9: =((0.8*4)*H3)/12 -> 3.7333333 | E9: TRONCOS | F9: 0.1 | G9: =ROUNDUP((D9+(D9*F9)),0) -> 5 | H9: =IF($A9=0,"",VLOOKUP($A9,'00_Mat'!$A$4:$J$1135,5,FALSE)) -> 20442.5 | I9: =H9*G9 -> 102212.5 | L9: columnas medianera | N9: 20x65 | O9: =(0.2+0.65*1)*9 -> 7.65 | P9: 9
A10: HADN16 | B10: =IF($A10=0,"",VLOOKUP($A10,'00_Mat'!$A$4:$J$1135,2,FALSE)) -> Hierros ADN 420 Φ 16 | C10: =IF($A10=0,"",VLOOKUP($A10,'00_Mat'!$A$4:$J$1135,3,FALSE)) -> u | D10: =((0.8*4)*P8)/12 -> 2.4 | E10: TRONCO MED | F10: 0.1 | G10: =ROUNDUP((D10+(D10*F10)),0) -> 3 | H10: =IF($A10=0,"",VLOOKUP($A10,'00_Mat'!$A$4:$J$1135,5,FALSE)) -> 36603.12 | I10: =H10*G10 -> 109809.36 | L10: columnas excentricas | N10: 30x30 | O10: =(0.25*0.25*1)*5 -> 0.3125 | P10: 5
A11: HADN6 | B11: =IF($A11=0,"",VLOOKUP($A11,'00_Mat'!$A$4:$J$1135,2,FALSE)) -> Hierros ADN 420 Φ 6 | C11: =IF($A11=0,"",VLOOKUP($A11,'00_Mat'!$A$4:$J$1135,3,FALSE)) -> u | D11: =((1.8*10)/12)*P9 -> 13.5 | E11: TRONCO MED | F11: 0.1 | G11: =ROUNDUP((D11+(D11*F11)),0) -> 15 | H11: =IF($A11=0,"",VLOOKUP($A11,'00_Mat'!$A$4:$J$1135,5,FALSE)) -> 5250 | I11: =H11*G11 -> 78750
A12: HADN6 | B12: =IF($A12=0,"",VLOOKUP($A12,'00_Mat'!$A$4:$J$1135,2,FALSE)) -> Hierros ADN 420 Φ 6 | C12: =IF($A12=0,"",VLOOKUP($A12,'00_Mat'!$A$4:$J$1135,3,FALSE)) -> u | D12: =((1.3*10)/12)*P10 -> 5.4166667 | E12: TRONCO EX | F12: 0.1 | G12: =ROUNDUP((D12+(D12*F12)),0) -> 6 | H12: =IF($A12=0,"",VLOOKUP($A12,'00_Mat'!$A$4:$J$1135,5,FALSE)) -> 5250 | I12: =H12*G12 -> 31500
A13: H30 | B13: =IF($A13=0,"",VLOOKUP($A13,'00_Mat'!$A$4:$J$1135,2,FALSE)) -> Hormigon H30 | C13: =IF($A13=0,"",VLOOKUP($A13,'00_Mat'!$A$4:$J$1135,3,FALSE)) -> m3 | D13: =N19 -> 3.36 | F13: 0.1 | G13: =ROUNDUP((D13+(D13*F13)),0) -> 4 | H13: =IF($A13=0,"",VLOOKUP($A13,'00_Mat'!$A$4:$J$1135,5,FALSE)) -> 125280 | I13: =H13*G13 -> 501120 | J13: TENSORES
A14: HADN10 | B14: =IF($A14=0,"",VLOOKUP($A14,'00_Mat'!$A$4:$J$1135,2,FALSE)) -> Hierros ADN 420Φ 10 | C14: =IF($A14=0,"",VLOOKUP($A14,'00_Mat'!$A$4:$J$1135,3,FALSE)) -> u | D14: =(28*6)/12 -> 14 | F14: 0.1 | G14: =ROUNDUP((D14+(D14*F14)),0) -> 16 | H14: =IF($A14=0,"",VLOOKUP($A14,'00_Mat'!$A$4:$J$1135,5,FALSE)) -> 10000 | I14: =H14*G14 -> 160000
A15: HADN6 | B15: =IF($A15=0,"",VLOOKUP($A15,'00_Mat'!$A$4:$J$1135,2,FALSE)) -> Hierros ADN 420 Φ 6 | C15: =IF($A15=0,"",VLOOKUP($A15,'00_Mat'!$A$4:$J$1135,3,FALSE)) -> u | D15: =((28/0.15)*1.3)/12 -> 20.222222 | F15: 0.1 | G15: =ROUNDUP((D15+(D15*F15)),0) -> 23 | H15: =IF($A15=0,"",VLOOKUP($A15,'00_Mat'!$A$4:$J$1135,5,FALSE)) -> 5250 | I15: =H15*G15 -> 120750
A16: A-NY20050m2 | B16: =IF($A16=0,"",VLOOKUP($A16,'00_Mat'!$A$4:$J$1135,2,FALSE)) -> Nylon 200 Micrones (50 m2 x rollo) | C16: =IF($A16=0,"",VLOOKUP($A16,'00_Mat'!$A$4:$J$1135,3,FALSE)) | D16: 1 | F16: 0 | G16: =ROUNDUP((D16+(D16*F16)),0) -> 1 | H16: =IF($A16=0,"",VLOOKUP($A16,'00_Mat'!$A$4:$J$1135,5,FALSE)) -> 38100 | I16: =H16*G16 -> 38100
B17: =IF($A17=0,"",VLOOKUP($A17,'00_Mat'!$A$4:$J$1135,2,FALSE)) | C17: =IF($A17=0,"",VLOOKUP($A17,'00_Mat'!$A$4:$J$1135,3,FALSE)) | G17: =ROUNDUP((D17+(D17*F17)),0) -> 0 | H17: =IF($A17=0,"",VLOOKUP($A17,'00_Mat'!$A$4:$J$1135,5,FALSE)) | I17: =H17*G17 -> 0 | L17: TENSORES CALCULADOS COMO VIGAS DE ENCADENADO
B18: =IF($A18=0,"",VLOOKUP($A18,'00_Mat'!$A$4:$J$1135,2,FALSE)) | C18: =IF($A18=0,"",VLOOKUP($A18,'00_Mat'!$A$4:$J$1135,3,FALSE)) | G18: =ROUNDUP((D18+(D18*F18)),0) -> 0 | H18: =IF($A18=0,"",VLOOKUP($A18,'00_Mat'!$A$4:$J$1135,5,FALSE)) | I18: =H18*G18 -> 0
B19: =IF($A19=0,"",VLOOKUP($A19,'00_Mat'!$A$4:$J$1135,2,FALSE)) | C19: =IF($A19=0,"",VLOOKUP($A19,'00_Mat'!$A$4:$J$1135,3,FALSE)) | G19: =ROUNDUP((D19+(D19*F19)),0) -> 0 | H19: =IF($A19=0,"",VLOOKUP($A19,'00_Mat'!$A$4:$J$1135,5,FALSE)) | I19: =H19*G19 -> 0 | L19: 28M DE TENSORES | N19: =0.3*0.4*28 -> 3.36 | O19: m3
B20: =IF($A20=0,"",VLOOKUP($A20,'00_Mat'!$A$4:$J$1135,2,FALSE)) | C20: =IF($A20=0,"",VLOOKUP($A20,'00_Mat'!$A$4:$J$1135,3,FALSE)) | G20: =ROUNDUP((D20+(D20*F20)),0) -> 0 | H20: =IF($A20=0,"",VLOOKUP($A20,'00_Mat'!$A$4:$J$1135,5,FALSE)) | I20: =H20*G20 -> 0
B21: =IF($A21=0,"",VLOOKUP($A21,'00_Mat'!$A$4:$J$1135,2,FALSE)) | C21: =IF($A21=0,"",VLOOKUP($A21,'00_Mat'!$A$4:$J$1135,3,FALSE)) | G21: =ROUNDUP((D21+(D21*F21)),0) -> 0 | H21: =IF($A21=0,"",VLOOKUP($A21,'00_Mat'!$A$4:$J$1135,5,FALSE)) | I21: =H21*G21 -> 0
B22: =IF($A22=0,"",VLOOKUP($A22,'00_Mat'!$A$4:$J$1135,2,FALSE)) | C22: =IF($A22=0,"",VLOOKUP($A22,'00_Mat'!$A$4:$J$1135,3,FALSE)) | G22: =ROUNDUP((D22+(D22*F22)),0) -> 0 | H22: =IF($A22=0,"",VLOOKUP($A22,'00_Mat'!$A$4:$J$1135,5,FALSE)) | I22: =H22*G22 -> 0
A24: TOTAL MATERIALES | I24: =SUM(I7:I19) -> 2893536.9
A25: =$I$3 -> unid. | I25: =$H$3 -> 14
A26: TOTAL x | B26: =A25 -> unid. | I26: =I24/I25 -> 206681.2
A29: MANO DE OBRA - PERSONAS
A30: Código | B30: Descripción | C30: Unidad | D30: Cantidad | E30: Dias | F30: Desperdicio | G30: Cantidad + Desperdicio | H30: Precio Unitario | I30: Subtotal
A31: MO-CA | B31: =IF($A31=0,"",VLOOKUP($A31,'00_MO'!$A$4:$D$7,2,FALSE)) -> Capataz | C31: =IF($A31=0,"",VLOOKUP($A31,'00_MO'!$A$4:$D$7,3,FALSE)) -> u | D31: 1 | E31: =7+3 -> 10 | F31: 0.25 | G31: =ROUNDUP(((D31*E31)*(1+F31)),0) -> 13 | H31: =IF($A31=0,"",VLOOKUP($A31,'00_MO'!$A$4:$D$7,4,FALSE)) -> 90000 | I31: =G31*H31 -> 1170000 | L31: 1/2 dia x base y 3 dias totales de tensores
A32: MO-OF | B32: =IF($A32=0,"",VLOOKUP($A32,'00_MO'!$A$4:$D$7,2,FALSE)) -> Oficial | C32: =IF($A32=0,"",VLOOKUP($A32,'00_MO'!$A$4:$D$7,3,FALSE)) -> u | D32: 2 | E32: =7+3 -> 10 | F32: 0.25 | G32: =ROUNDUP(((D32*E32)*(1+F32)),0) -> 25 | H32: =IF($A32=0,"",VLOOKUP($A32,'00_MO'!$A$4:$D$7,4,FALSE)) -> 75000 | I32: =G32*H32 -> 1875000
A33: MO-AY | B33: =IF($A33=0,"",VLOOKUP($A33,'00_MO'!$A$4:$D$7,2,FALSE)) -> Ayudante | C33: =IF($A33=0,"",VLOOKUP($A33,'00_MO'!$A$4:$D$7,3,FALSE)) -> u | D33: 1 | E33: =7+3 -> 10 | F33: 0.25 | G33: =ROUNDUP(((D33*E33)*(1+F33)),0) -> 13 | H33: =IF($A33=0,"",VLOOKUP($A33,'00_MO'!$A$4:$D$7,4,FALSE)) -> 60000 | I33: =G33*H33 -> 780000
B34: =IF($A34=0,"",VLOOKUP($A34,'00_MO'!$A$4:$D$7,2,FALSE)) | C34: =IF($A34=0,"",VLOOKUP($A34,'00_MO'!$A$4:$D$7,3,FALSE)) | G34: =ROUNDUP(((D34*E34)*(1+F34)),0) -> 0 | H34: =IF($A34=0,"",VLOOKUP($A34,'00_MO'!$A$4:$D$7,4,FALSE)) | I34: =G34*H34 -> 0
B35: =IF($A35=0,"",VLOOKUP($A35,'00_MO'!$A$4:$D$7,2,FALSE)) | C35: =IF($A35=0,"",VLOOKUP($A35,'00_MO'!$A$4:$D$7,3,FALSE)) | G35: =ROUNDUP(((D35*E35)*(1+F35)),0) -> 0 | H35: =IF($A35=0,"",VLOOKUP($A35,'00_MO'!$A$4:$D$7,4,FALSE)) | I35: =G35*H35 -> 0
B36: =IF($A36=0,"",VLOOKUP($A36,'00_MO'!$A$4:$D$7,2,FALSE)) | C36: =IF($A36=0,"",VLOOKUP($A36,'00_MO'!$A$4:$D$7,3,FALSE)) | G36: =ROUNDUP(((D36*E36)*(1+F36)),0) -> 0 | H36: =IF($A36=0,"",VLOOKUP($A36,'00_MO'!$A$4:$D$7,4,FALSE)) | I36: =G36*H36 -> 0
A38: TOTAL | I38: =SUM(I31:I36) -> 3825000
A39: =$I$3 -> unid. | I39: =$H$3 -> 14
A40: TOTAL x | B40: =A39 -> unid. | I40: =I38/I39 -> 273214.29
A43: MANO DE OBRA - EQUIPOS
A44: Código | B44: Descripción | C44: Unidad | D44: Cantidad | E44: Dias | F44: Desperdicio | G44: Cantidad + Desperdicio | H44: Precio Unitario | I44: Subtotal
B45: =IF($A45=0,"",VLOOKUP($A45,'00_Eq'!$A$4:$D$100,2,FALSE)) | C45: =IF($A45=0,"",VLOOKUP($A45,'00_Eq'!$A$4:$D$100,3,FALSE)) | G45: =ROUNDUP(((D45*E45)*(1+F45)),0) -> 0 | H45: =IF($A45=0,"",VLOOKUP($A45,'00_Eq'!$A$4:$D$100,4,FALSE)) | I45: =G45*H45 -> 0
B46: =IF($A46=0,"",VLOOKUP($A46,'00_Eq'!$A$4:$D$100,2,FALSE)) | C46: =IF($A46=0,"",VLOOKUP($A46,'00_Eq'!$A$4:$D$100,3,FALSE)) | G46: =ROUNDUP(((D46*E46)*(1+F46)),0) -> 0 | H46: =IF($A46=0,"",VLOOKUP($A46,'00_Eq'!$A$4:$D$100,4,FALSE)) | I46: =G46*H46 -> 0
