Workbook

Sheet 00_Mat
A1: MATERIALES
A3: CODIGO | B3: MATERIALES CORRALON | C3: UNIDAD | D3: PRECIO CON IVA | E3: PRECIO SIN IVA | F3: DESCUENTO | G3: PRECIO CON DESCUENTO | I3: REFERENCIA | J3: FECHA
A4: ARG | B4: Arena a granel (1m3) | C4: m3 | D4: 29403 | E4: =D4/1.21 -> 24300 | I4: Su Corralon | J4: 45406
A5: AR | B5: Bolson de Arena (1m3) | C5: m3 | E5: 31040 | I5: Su Corralon | J5: 45824
A6: PIEG | B6: Piedra a granel (1m3) | C6: m3 | D6: 58995 | E6: =D6/1.21 -> 48756.198 | I6: Su Corralon | J6: 45406
A7: PIEP | B7: Bolson de Piedra partida (1m3) | C7: m3 | E7: 74566 | I7: Su Corralon | J7: 45824
A8: PIE | B8: Bolson de Piedra (1m3) | C8: m3 | D8: 60000 | E8: =D8/1.21 -> 49586.777 | I8: Su Corralon | J8: 45777
A9: CEM | B9: Bolsa Cemento "Loma Negra" 50 k (u) | C9: u | E9: 10675 | I9: Su Corralon | J9: 45824
A10: CAL | B10: Bolsa Cal "Cacique" 25 k (u) | C10: u | D10: 6500 | E10: =D10/1.21 -> 5371.9008 | I10: ML | J10: 45785
A11: PLASTICOR | B11: Bolsa Plasticor 40k (u) | C11: u | D11: 8500 | E11: =D11/1.21 -> 7024.7934 | I11: ML | J11: 45785
A12: CER | B12: Ceresita 20 k (u) | C12: u | D12: 45000 | E12: =D12/1.21 -> 37190.083 | I12: Su Corralon | J12: 45771
A13: LP18 | B13: Ladrillo Portante 18 (u) | C13: u | E13: 1377 | I13: Su Corralon | J13: 45824
A14: LP12 | B14: Ladrillo Portante 12 (u) | C14: u | E14: 1110.2 | I14: Su Corralon | J14: 45824
A15: LH18 | B15: Ladrillo Hueco 18 (u) | C15: u | E15: 598 | I15: Su Corralon | J15: 45478
A16: LH12 | B16: Ladrillo Hueco 12 (u) | C16: u | E16: 726 | I16: Su Corralon | J16: 45824
A17: LH8 | B17: Ladrillo Hueco 8 (u) | C17: u | E17: 568.7 | I17: Su Corralon | J17: 45824
A18: LCOM | B18: Ladrillo Comun | C18: u | E18: 190.61 | I18: Su Corralon | J18: 45824
A19: LCOMVIST | B19: Ladrillo Comun Vista | C19: u | D19: 240 | E19: =D19/1.21 -> 198.34711 | I19: Su Corralon | J19: 45771
A20: LPINT | B20: Pavimento Intertrabado | C20: m2 | E20: 37600 | I20: Su Corralon | J20: 45824
A21: LGB | B21: Garden Block 38x38x8cm (1m2) | C21: m2 | E21: 22500 | I21: ml | J21: 45877
A22: LDC | B22: Deck Liston Hormigon Cemento Piso Durmiente 100 X 12 Cms (1m2) | E22: 41000 | I22: ml | J22: 45877
A23: YES | B23: Bolsa Yeso Tuyango 30 k (u) | C23: u | D23: 13879 | E23: =D23/1.21 -> 11470.248 | I23: Su Corralon | J23: 45400
A24: ES | B24: Cascote / Escombro (m3) | C24: m3 | D24: 19360 | E24: =D24/1.21 -> 16000 | I24: Su Corralon | J24: 45412
A25: TOS8 | B25: Tosca | C25: m3 | E25: 30000 | I25: NICO | J25: 45498
A26: TOS30 | B26: Tosca | C26: m3 | E26: 9500 | I26: NICO | J26: 45498
A27: TN | B27: BOLSON Tierra negra | C27: m3 | E27: 33275 | I27: Su Corralon | J27: 45824
A28: CL2 | B28: Clavos 2" punta paris (k) | C28: k | E28: 3739.67 | I28: Naclelio | J28: 45496
A29: CL2.5 | B29: Clavos 2,5" punta paris (k) | C29: k | E29: 3739.67 | I29: Naclelio | J29: 45496
A30: AL | B30: Alambre Fardo (k) | C30: k | E30: 4326.45 | I30: Naclelio | J30: 45496
A31: ES24 | B31: Cascote / Escombro cada 24 m3 (m3) | C31: m3 | D31: 16500 | E31: =D31/1.21 -> 13636.364 | I31: Su Corralon | J31: 45412
A32: DISCO PORC | B32: Disco Amoladora para porcelanato. marca aliafor | E32: 20000 | I32: ML | J32: 45783
A33: DISCO | B33: Disco Ascerradora | C33: u | E33: 120000
A34: DIS | B34: Disco corte | C34: u | E34: 40000
A35: VI7 | B35: Vigueta pretensada de hormigon 7m | C35: u | E35: 34000 | I35: ML | J35: 45817
A36: VI6 | B36: Vigueta pretensada de hormigon 6m | C36: u | E36: 30111 | I36: Su Corralon | J36: 45824
A37: VI-EPS | B37: Ladrillos Telgopor 12x40x100 | C37: u | E37: 36603.12 | I37: Su Corralon | J37: 45824
A38: P-pro | B38: Protex 215 x 1kg | C38: u | D38: =E38*1.21 -> 21780 | E38: 18000 | I38: Tecnolibertador | J38: 45776
A39: z-sell | B39: Adhesivo Zocalos Sellador Rellenador Atrim 420gr | C39: u | E39: 13000
A40: ME | B40: MECHA ROTOPERCUTORA | C40: u | E40: 5000
A41: EPS | B41: EPS aislante para techos 1x1 30mm 15 Kg Pack 5u | C41: u | E41: 60000 | I41: ML | J41: 45824
...

Sheet 00_MO
A1: MANO DE OBRA
A3: CODIGO | B3: MATERIALES CORRALON | C3: UNIDAD | D3: PRECIO SIN IVA | E3: FECHA
A4: MO-CA | B4: Capataz | C4: u | D4: 50000 | E4: 45877
A5: MO-PU | B5: Puntero | C5: u | D5: 45000 | E5: 45877
A6: MO-OF | B6: Oficial | C6: u | D6: 40000 | E6: 45877
A7: MO-AY | B7: Ayudante | C7: u | D7: 30000 | E7: 45877
A8: MO-G | B8: Gervacio | C8: u | D8: 80000 | E8: 45877

Sheet 00_Eq
A1: EQUIPOS
A3: CODIGO | B3: MATERIALES CORRALON | C3: UNIDAD | D3: PRECIO SIN IVA | E3: FECHA
A4: E-MC | B4: Mini Cargadora | C4: u | D4: 420000 | E4: 45804
A5: E-MCM | B5: Mini Cargadora con martillo | C5: u | D5: 550000 | E5: 45804
A6: E-ME | B6: Mini Excavadora | C6: u | D6: 550000 | E6: 45804
A7: E-MP | B7: Motopison | C7: u | D7: 40000
A8: E-RP | B8: Retropala | C8: u | D8: 450000
A9: E-VC | B9: Vibrocompactador | C9: u | D9: 400000
A10: E-MN | B10: Motoniveladora | C10: u | D10: 600000
A11: E-CAMCH | B11: Camion Chasis | C11: u | D11: 150000
A12: E-REG | B12: Regador | C12: u | D12: 200000
A13: E-MAR | B13: Martillete | C13: u | D13: 45000
A14: E-ASC | B14: Ascerradora | C14: u | D14: 60000 | E14: 45890
A15: E-RET | B15: Retiro x camion | C15: u | D15: 140000 | E15: 45890
A16: E-MR | B16: Mini Retro | C16: u | D16: 480000 | E16: 45804
A17: MS-TM3 | B17: TOSCA x M3 | C17: m3 | D17: 30000 | E17: 45804
A18: MS-TCA | B18: TOSCA X CAMION | C18: m3 | D18: =D17*8 -> 240000 | E18: 45804
A19: MS-ER | B19: EXCAVACION Y RETIRO | C19: m3 | D19: 21000 | E19: 45804
A20: MS-TC | B20: TOSCA COMPACTADA | C20: m3 | D20: 25000 | E20: 45804
A21: MS-ARBOL | B21: RETIRO DE ARBOL | C21: u | D21: 570000 | E21: 45804
A22: E-CAM | B22: Camioneta | C22: u | D22: 100000
A23: E-TRAS | B23: TRASLADO DE MAQUINARIA | C23: u | D23: 300000

Sheet 00_Sub
A1: SUBCONTRATOS
A3: CODIGO | B3: SUBCONTRATOS | C3: UNIDAD | D3: PRECIO SIN IVA
A4: SUB-PI | B4: Pintura Interior: 1Mano Enduido + Yeso, 1 Mano Enduido, 2 a 3 Manos de Pintura | C4: m2 | D4: 16000 | F4: 45789
A5: SUB-PIC | B5: Pintura Interior Cielorraso | C5: m2 | D5: 10000 | F5: 45789
A6: SUB-PET | B6: Pintura Exterior Tarquini | C6: m2 | D6: 12000 | F6: 45789
A7: SUB-PE | B7: Pintura Exterior | C7: m2 | D7: 10000
A8: SUB-PI | B8: Pintura Interior | C8: m2 | D8: 8000
A9: SUB-END | B9: Enduido | C9: m2 | D9: 8000
A10: SUB-PPS | B10: Pintura Puerta Simple Hoja | C10: u | D10: 25000
A11: SUB-PPD | B11: Pintura Puerta Doble Hoja | C11: u | D11: 50000
A12: SUB-CIE | B12: Instalacion de Cielorraso Durlock. Incluye Materiales. | C12: m2 | D12: 37000 | F12: 45791
A13: SUB-CIEDES | B13: Instalacion de Cielorraso Desmontable. Incluye Materiales. | C13: m2 | D13: 37000 | F13: 45791
A14: SUB-CIECO | B14: Instalacion de Cielorraso Durlock Cortineros. Incluye Materiales. | C14: m | D14: 45000 | F14: 45791
A15: SUB-CIECA | B15: Instalacion de Cajon Durlock. Incluye Materiales. | C15: m | D15: 20000 | F15: 45791
A16: SUB-CIEGL | B16: Instalacion de Cielorraso Durlock Garganta Led. Incluye Materiales. | C16: m | D16: 45000 | F16: 45791
A17: SUB-TAB | B17: Instalacion de Tabique Durlock. Incluye Materiales. | C17: m2 | D17: 48000 | F17: 45791
A18: SUB-BZ | B18: Instlacion Buña Z. Incluye Materiales. | C18: m | D18: 16000 | F18: 45791
A19: SUB-CAN | B19: Instalacion Cantonera. Incluye Materiales. | C19: m | D19: 16000 | F19: 45791
A20: SUB-E-BOC | B20: Boca. Incluye Materiales. | C20: boca | D20: 100000 | E20: MDO Y MAT | F20: 45800 | G20: CABEZA
A21: SUB-E-COL | B21: Colocacion de artefatcos | C21: u | D21: 7000 | E21: MDO | F21: 45800 | G21: CABEZA
A22: SUB-E-AAC | B22: Alimentacion aire acondicionado con split. | C22: u | D22: 100000 | E22: MDO Y MAT | F22: 45800 | G22: CABEZA
A23: SUB-E-TAB | B23: Instalacion de Tablero para 100 bocas (casa chica). Incluye alimentacion desde el pilar. | C23: u | D23: 100000 | E23: MDO | F23: 45800 | G23: CABEZA
A24: SUB-ZING | B24: Zinguero | C24: u | D24: 700000
A25: SUB-PIS | B25: Pisero | C25: m² | D25: 7000 | F25: 45800 | G25: CEFERINO
A26: SUB-COR | B26: CORDON | C26: m | D26: 10000 | F26: 45800 | G26: CEFERINO
A29: CODIGO | B29: MOVIMIENTO DE SUELOS | C29: UNIDAD | D29: PRECIO SIN IVA
A30: MS-MC | B30: MINICARGADORA | C30: u | D30: 420000
A31: MS-MCM | B31: MINICARGADORA CON MARTILLO | C31: u | D31: 550000
A32: MS-MR | B32: MINIRETRO EXCAVADORA | C32: u | D32: 550000
A33: MS-T | B33: TRASLADO DE MAQUINARIA | C33: u | D33: 300000
A34: MS-RV | B34: RETIRO X VIAJE | C34: u | D34: 140000
A35: MS-TM3 | B35: TOSCA x M3 | C35: m3 | D35: 30000
A36: MS-TCA | B36: TOSCA X CAMION | C36: m3 | D36: =D35*8 -> 240000
A37: MS-ER | B37: EXCAVACION Y RETIRO | C37: m3 | D37: 21000
A38: MS-TC | B38: TOSCA COMPACTADA | C38: m3 | D38: 25000
A39: MS-ARBOL | B39: RETIRO DE ARBOL | C39: u | D39: 570000
A42: BQ | B42: BAÑO QUIMICO | C42: U | D42: 120000
A44: Perfracion | B44: Perforacion para bobas de 7.5 HP de 17m3/h materiales y mo | D44: 2800000 | F44: 14614.9 | G44: cac antes | H44: 2250000
F45: 1692950 | G45: cac ahora | H45: =F45*H44/F44 -> 2.6063384e+08

Sheet 00_JEF + ESTR
A1: JEFATURA DE OBRA (mes)
A3: Jefatura de Obra | B3: =SUM(B4:B5) -> 3000000
A4: x | B4: 1000000
A5: Jefe de Obra | B5: 2000000
A6: Gastos Estructura | B6: =SUM(B7:B11) -> 1550000
A7: Nafta Jefe de Obra | B7: 250000
A8: Nafta x | B8: 100000
A10: Guille | B10: 200000
A11: Herramientas | B11: 1000000
B13: =SUM(B6+B3) -> 4550000

Sheet 01_C&P
A1: NOMBRE DE LA OBRA
A3: PLANILLA COMPUTO Y PRESPUPUESTO
A5: ITEM | B5: DESCRIPCIÓN | C5: UNIDAD | D5: CANTIDAD | E5: SUBTOTAL 01: GASTOS DIRECTOS | O5: SUBTOTAL 02: GASTOS INDIRECTOS | R5: SUBTOTAL 03: BENEFICIOS | U5: TOTAL (NETO)
E6: V.UNITARIO | L6: V.GENERAL | O6: V. GENERAL | R6: V. GENERAL | U6: V. UNITARIO | X6: V.GENERAL
E7: MAT. | F7: M.O.: JORNALES | G7: M.O.: EQUIPOS | H7: M.O.: MATERIALES | I7: M.O.: SUBCONTRATOS | J7: M.O. | K7: GENERAL | L7: MAT. | M7: M.O | N7: GENERAL | O7: MAT. | P7: M.O. | Q7: GENERAL | R7: MAT. | S7: M.O. | T7: GENERAL | U7: MAT. | V7: M.O | W7: GENERAL | X7: MAT. | Y7: M.O | Z7: GENERAL
A8: 1- TAREAS PRELIMINARES
A9: 45292 | B9: OBRADOR | C9: mes | D9: 4 | I9: 400000 | J9: =SUM(F9:I9) -> 400000 | K9: =SUM(E9,J9) -> 400000 | L9: =$D9*E9 -> 0 | M9: =$D9*(SUM(F9:I9)) -> 1600000 | N9: =L9+M9 -> 1600000 | O9: =(O$39*L9)/L$39 -> 0 | P9: =(P$39*M9)/M$39 -> 2000000 | Q9: =O9+P9 -> 2000000 | R9: =(R$39*O9)/O$39 -> 0 | S9: =(S$39*P9)/P$39 -> 3000000 | T9: =R9+S9 -> 3000000 | U9: =X9/D9 -> 0 | V9: =Y9/D9 -> 811500 | W9: =U9+V9 -> 811500 | X9: =(X$39*R9)/R$39 -> 0 | Y9: =(Y$39*S9)/S$39 -> 3246000 | Z9: =X9+Y9 -> 3246000
A10: 45323 | B10: REPLANTEO Y NIVELACION | C10: gl | D10: 1 | F10: =300000*10 -> 3000000 | J10: =SUM(F10:I10) -> 3000000 | K10: =SUM(E10,J10) -> 3000000 | L10: =$D10*E10 -> 0 | M10: =$D10*(SUM(F10:I10)) -> 3000000 | N10: =L10+M10 -> 3000000 | O10: =(O$39*L10)/L$39 -> 0 | P10: =(P$39*M10)/M$39 -> 3750000 | Q10: =O10+P10 -> 3750000 | R10: =(R$39*O10)/O$39 -> 0 | S10: =(S$39*P10)/P$39 -> 5625000 | T10: =R10+S10 -> 5625000 | U10: =X10/D10 -> 0 | V10: =Y10/D10 -> 6086250 | W10: =U10+V10 -> 6086250 | X10: =(X$39*R10)/R$39 -> 0 | Y10: =(Y$39*S10)/S$39 -> 6086250 | Z10: =X10+Y10 -> 6086250
A11: 45352 | B11: BAÑO QUIMICO | C11: mes | D11: 4 | I11: 80000 | J11: =SUM(F11:I11) -> 80000 | K11: =SUM(E11,J11) -> 80000 | L11: =$D11*E11 -> 0 | M11: =$D11*(SUM(F11:I11)) -> 320000 | N11: =L11+M11 -> 320000 | O11: =(O$39*L11)/L$39 -> 0 | P11: =(P$39*M11)/M$39 -> 400000 | Q11: =O11+P11 -> 400000 | R11: =(R$39*O11)/O$39 -> 0 | S11: =(S$39*P11)/P$39 -> 600000 | T11: =R11+S11 -> 600000 | U11: =X11/D11 -> 0 | V11: =Y11/D11 -> 162300 | W11: =U11+V11 -> 162300 | X11: =(X$39*R11)/R$39 -> 0 | Y11: =(Y$39*S11)/S$39 -> 649200 | Z11: =X11+Y11 -> 649200
A12: 45383 | B12: CERCO DE OBRA (Malla de seguridad permietral) | C12: mes | D12: 4 | F12: 200000 | H12: =(26300*4)+(20000*((D24/1)/12)) -> 365366.67 | J12: =SUM(F12:I12) -> 565366.67 | K12: =SUM(E12,J12) -> 565366.67 | L12: =$D12*E12 -> 0 | M12: =$D12*(SUM(F12:I12)) -> 2261466.7 | N12: =L12+M12 -> 2261466.7 | O12: =(O$39*L12)/L$39 -> 0 | P12: =(P$39*M12)/M$39 -> 2826833.3 | Q12: =O12+P12 -> 2826833.3 | R12: =(R$39*O12)/O$39 -> 0 | S12: =(S$39*P12)/P$39 -> 4240250 | T12: =R12+S12 -> 4240250 | U12: =X12/D12 -> 0 | V12: =Y12/D12 -> 1146987.6 | W12: =U12+V12 -> 1146987.6 | X12: =(X$39*R12)/R$39 -> 0 | Y12: =(Y$39*S12)/S$39 -> 4587950.5 | Z12: =X12+Y12 -> 4587950.5
A13: 45413 | B13: LIMPIZA PERIODICA DE OBRA | C13: mes | D13: 4 | F13: 600000 | J13: =SUM(F13:I13) -> 600000 | K13: =SUM(E13,J13) -> 600000 | L13: =$D13*E13 -> 0 | M13: =$D13*(SUM(F13:I13)) -> 2400000 | N13: =L13+M13 -> 2400000 | O13: =(O$39*L13)/L$39 -> 0 | P13: =(P$39*M13)/M$39 -> 3000000 | Q13: =O13+P13 -> 3000000 | R13: =(R$39*O13)/O$39 -> 0 | S13: =(S$39*P13)/P$39 -> 4500000 | T13: =R13+S13 -> 4500000 | U13: =X13/D13 -> 0 | V13: =Y13/D13 -> 1217250 | W13: =U13+V13 -> 1217250 | X13: =(X$39*R13)/R$39 -> 0 | Y13: =(Y$39*S13)/S$39 -> 4869000 | Z13: =X13+Y13 -> 4869000
A14: 45444 | B14: ACARREO DE MATERIALES | C14: mes | D14: 4 | F14: 600000 | J14: =SUM(F14:I14) -> 600000 | K14: =SUM(E14,J14) -> 600000 | L14: =$D14*E14 -> 0 | M14: =$D14*(SUM(F14:I14)) -> 2400000 | N14: =L14+M14 -> 2400000 | O14: =(O$39*L14)/L$39 -> 0 | P14: =(P$39*M14)/M$39 -> 3000000 | Q14: =O14+P14 -> 3000000 | R14: =(R$39*O14)/O$39 -> 0 | S14: =(S$39*P14)/P$39 -> 4500000 | T14: =R14+S14 -> 4500000 | U14: =X14/D14 -> 0 | V14: =Y14/D14 -> 1217250 | W14: =U14+V14 -> 1217250 | X14: =(X$39*R14)/R$39 -> 0 | Y14: =(Y$39*S14)/S$39 -> 4869000 | Z14: =X14+Y14 -> 4869000
A15: 45474 | B15: LIMPIEZA FINAL DE OBRA | C15: gl | D15: 1 | F15: 880000 | J15: =SUM(F15:I15) -> 880000 | K15: =SUM(E15,J15) -> 880000 | L15: =$D15*E15 -> 0 | M15: =$D15*(SUM(F15:I15)) -> 880000 | N15: =L15+M15 -> 880000 | O15: =(O$39*L15)/L$39 -> 0 | P15: =(P$39*M15)/M$39 -> 1100000 | Q15: =O15+P15 -> 1100000 | R15: =(R$39*O15)/O$39 -> 0 | S15: =(S$39*P15)/P$39 -> 1650000 | T15: =R15+S15 -> 1650000 | U15: =X15/D15 -> 0 | V15: =Y15/D15 -> 1785300 | W15: =U15+V15 -> 1785300 | X15: =(X$39*R15)/R$39 -> 0 | Y15: =(Y$39*S15)/S$39 -> 1785300 | Z15: =X15+Y15 -> 1785300
A16: 2- MOVIMEINTO DE SUELOS
A17: 45293 | B17: RETIRO DE ARBOLES DE MENOR PORTE (No incluye los tres arboles existentes de gran porte) | C17: gl | D17: 1 | E17: 0 | F17: 0 | G17: 0 | H17: 0 | I17: =200000+120000 -> 320000 | J17: =SUM(F17:I17) -> 320000 | K17: =SUM(E17,J17) -> 320000 | L17: =$D17*E17 -> 0 | M17: =$D17*(SUM(F17:I17)) -> 320000 | N17: =L17+M17 -> 320000 | O17: =(O$39*L17)/L$39 -> 0 | P17: =(P$39*M17)/M$39 -> 400000 | Q17: =O17+P17 -> 400000 | R17: =(R$39*O17)/O$39 -> 0 | S17: =(S$39*P17)/P$39 -> 600000 | T17: =R17+S17 -> 600000 | U17: =X17/D17 -> 0 | V17: =Y17/D17 -> 649200 | W17: =U17+V17 -> 649200 | X17: =(X$39*R17)/R$39 -> 0 | Y17: =(Y$39*S17)/S$39 -> 649200 | Z17: =X17+Y17 -> 649200
A18: 45324 | B18: EXCAVACION Y RETIRO DE SUELO VEGETAL EXISTENTE (Escalones 20 cm de altura con pendiente de 5cm. Secotor de intertrabado/ garden block + contrapiso + tosca = 50 cm. Sector de Cantero 20 cm) | C18: m³ | D18: =D86 -> 1513.12 | E18: ='2.2.'!I22 -> 0 | F18: ='2.2.'!I36 -> 1480.3849 | G18: ='2.2.'!I50 -> 0 | H18: ='2.2.'!I64 -> 0 | I18: ='2.2.'!I78 -> 25533.335 | J18: =SUM(F18:I18) -> 27013.72 | K18: =SUM(E18,J18) -> 27013.72 | L18: =$D18*E18 -> 0 | M18: =$D18*(SUM(F18:I18)) -> 40875000 | N18: =L18+M18 -> 40875000 | O18: =(O$39*L18)/L$39 -> 0 | P18: =(P$39*M18)/M$39 -> 51093750 | Q18: =O18+P18 -> 51093750 | R18: =(R$39*O18)/O$39 -> 0 | S18: =(S$39*P18)/P$39 -> 76640625 | T18: =R18+S18 -> 76640625 | U18: =X18/D18 -> 0 | V18: =Y18/D18 -> 54804.084 | W18: =U18+V18 -> 54804.084 | X18: =(X$39*R18)/R$39 -> 0 | Y18: =(Y$39*S18)/S$39 -> 82925156 | Z18: =X18+Y18 -> 82925156
A19: 45353 | B19: RELLENO, COMPACTACION Y NIVELACION CON SUELO SELECCIONADO TIPO A4 (En sectores de intertrabado y deck de cemento) | C19: m³ | D19: =C91 -> 278.991 | E19: ='2.3.'!I22 -> 46238.051 | F19: ='2.3.'!I36 -> 0 | G19: ='2.3.'!I50 -> 0 | H19: ='2.3.'!I64 -> 0 | I19: ='2.3.'!I78 -> 28603.073 | J19: =SUM(F19:I19) -> 28603.073 | K19: =SUM(E19,J19) -> 74841.124 | L19: =$D19*E19 -> 12900000 | M19: =$D19*(SUM(F19:I19)) -> 7980000 | N19: =L19+M19 -> 20880000 | O19: =(O$39*L19)/L$39 -> 12900000 | P19: =(P$39*M19)/M$39 -> 9975000 | Q19: =O19+P19 -> 22875000 | R19: =(R$39*O19)/O$39 -> 14835000 | S19: =(S$39*P19)/P$39 -> 14962500 | T19: =R19+S19 -> 29797500 | U19: =X19/D19 -> 57534.006 | V19: =Y19/D19 -> 58028.485 | W19: =U19+V19 -> 115562.49 | X19: =(X$39*R19)/R$39 -> 16051470 | Y19: =(Y$39*S19)/S$39 -> 16189425 | Z19: =X19+Y19 -> 32240895
A20: 3- SOLADOS
A21: 45660 | B21: EJECUCION DE CONTRAPISO DE H8 EN VEREDA ATERRAZADA | C21: m² | D21: =D80+D82+D84 -> 719.3 | E21: ='3.1'!I22 -> 17349.49 | F21: ='3.1'!I36 -> 1751.703 | G21: ='3.1'!I50 -> 0 | H21: ='3.1'!I64 -> 0 | I21: ='3.1'!I78 -> 0 | J21: =SUM(F21:I21) -> 1751.703 | K21: =SUM(E21,J21) -> 19101.193 | L21: =$D21*E21 -> 12479488 | M21: =$D21*(SUM(F21:I21)) -> 1260000 | N21: =L21+M21 -> 13739488 | O21: =(O$39*L21)/L$39 -> 12479488 | P21: =(P$39*M21)/M$39 -> 1575000 | Q21: =O21+P21 -> 14054488 | R21: =(R$39*O21)/O$39 -> 14351411 | S21: =(S$39*P21)/P$39 -> 2362500 | T21: =R21+S21 -> 16713911 | U21: =X21/D21 -> 21587.97 | V21: =Y21/D21 -> 3553.7676 | W21: =U21+V21 -> 25141.738 | X21: =(X$39*R21)/R$39 -> 15528227 | Y21: =(Y$39*S21)/S$39 -> 2556225 | Z21: =X21+Y21 -> 18084452
A22: 45691 | B22: EJECUCION DE CONTRAPISO DE H8 EN VEREDA SOBRE LATERAL DE CALLE | C22: m² | D22: =D79 -> 314 | E22: =E21 -> 17349.49 | F22: =F21 -> 1751.703 | G22: =G21 -> 0 | H22: =H21 -> 0 | I22: =I21 -> 0 | J22: =SUM(F22:I22) -> 1751.703 | K22: =SUM(E22,J22) -> 19101.193 | L22: =$D22*E22 -> 5447739.8 | M22: =$D22*(SUM(F22:I22)) -> 550034.76 | N22: =L22+M22 -> 5997774.5 | O22: =(O$39*L22)/L$39 -> 5447739.8 | P22: =(P$39*M22)/M$39 -> 687543.44 | Q22: =O22+P22 -> 6135283.2 | R22: =(R$39*O22)/O$39 -> 6264900.7 | S22: =(S$39*P22)/P$39 -> 1031315.2 | T22: =R22+S22 -> 7296215.9 | U22: =X22/D22 -> 21587.97 | V22: =Y22/D22 -> 3553.7676 | W22: =U22+V22 -> 25141.738 | X22: =(X$39*R22)/R$39 -> 6778622.6 | Y22: =(Y$39*S22)/S$39 -> 1115883 | Z22: =X22+Y22 -> 7894505.6
A23: 45719 | B23: EJECUCION DE ESCALON DE HORMIGON ARMADO CURVO CON ZAPATA PARA CONTECION DE SUELO | C23: m | D23: =E97 -> 435.5 | E23: ='3.3'!I22 -> 21203.057 | F23: ='3.3'!I36 -> 8128.5878 | G23: ='3.3'!I50 -> 14466.131 | H23: ='3.3'!I64 -> 0 | I23: ='3.3'!I78 -> 0 | J23: =SUM(F23:I23) -> 22594.719 | K23: =SUM(E23,J23) -> 43797.776 | L23: =$D23*E23 -> 9233931.5 | M23: =$D23*(SUM(F23:I23)) -> 9840000 | N23: =L23+M23 -> 19073931 | O23: =(O$39*L23)/L$39 -> 9233931.5 | P23: =(P$39*M23)/M$39 -> 12300000 | Q23: =O23+P23 -> 21533931 | R23: =(R$39*O23)/O$39 -> 10619021 | S23: =(S$39*P23)/P$39 -> 18450000 | T23: =R23+S23 -> 29069021 | U23: =X23/D23 -> 26382.964 | V23: =Y23/D23 -> 45839.036 | W23: =U23+V23 -> 72222 | X23: =(X$39*R23)/R$39 -> 11489781 | Y23: =(Y$39*S23)/S$39 -> 19962900 | Z23: =X23+Y23 -> 31452681
A24: 45750 | B24: CORDON PERIMETRAL DE 10X10 SOBRE LATERAL DE CALLE | C24: m | D24: =D96 -> 156.1 | E24: ='3.4'!I22 -> 3836.6019 | F24: ='3.4'!I36 -> 3651.5054 | G24: ='3.4'!I50 -> 5381.1659 | H24: ='3.4'!I64 -> 0 | I24: ='3.4'!I78 -> 0 | J24: =SUM(F24:I24) -> 9032.6714 | K24: =SUM(E24,J24) -> 12869.273 | L24: =$D24*E24 -> 598893.55 | M24: =$D24*(SUM(F24:I24)) -> 1410000 | N24: =L24+M24 -> 2008893.6 | O24: =(O$39*L24)/L$39 -> 598893.55 | P24: =(P$39*M24)/M$39 -> 1762500 | Q24: =O24+P24 -> 2361393.6 | R24: =(R$39*O24)/O$39 -> 688727.59 | S24: =(S$39*P24)/P$39 -> 2643750 | T24: =R24+S24 -> 3332477.6 | U24: =X24/D24 -> 4773.8837 | V24: =Y24/D24 -> 18325.032 | W24: =U24+V24 -> 23098.916 | X24: =(X$39*R24)/R$39 -> 745203.25 | Y24: =(Y$39*S24)/S$39 -> 2860537.5 | Z24: =X24+Y24 -> 3605740.7
A25: 45780 | B25: COLOCACION DE GARDEN BLOCK | C25: m² | D25: =E69 -> 427 | E25: ='3.5'!I22 -> 28832.787 | F25: ='3.5'!I36 -> 8454.3326 | G25: ='3.5'!I50 -> 0 | H25: ='3.5'!I64 -> 0 | I25: ='3.5'!I78 -> 0 | J25: =SUM(F25:I25) -> 8454.3326 | K25: =SUM(E25,J25) -> 37287.119 | L25: =$D25*E25 -> 12311600 | M25: =$D25*(SUM(F25:I25)) -> 3610000 | N25: =L25+M25 -> 15921600 | O25: =(O$39*L25)/L$39 -> 12311600 | P25: =(P$39*M25)/M$39 -> 4512500 | Q25: =O25+P25 -> 16824100 | R25: =(R$39*O25)/O$39 -> 14158340 | S25: =(S$39*P25)/P$39 -> 6768750 | T25: =R25+S25 -> 20927090 | U25: =X25/D25 -> 35876.637 | V25: =Y25/D25 -> 17151.727 | W25: =U25+V25 -> 53028.364 | X25: =(X$39*R25)/R$39 -> 15319324 | Y25: =(Y$39*S25)/S$39 -> 7323787.5 | Z25: =X25+Y25 -> 22643111
A26: 45811 | B26: COLOCACION DE BLOQUES INTERTRABADO DE CEMENTO | C26: m² | D26: =E67 -> 1006 | E26: ='3.6'!I22 -> 47531.098 | F26: ='3.6'!I36 -> 7932.4056 | G26: ='3.6'!I50 -> 0 | H26: ='3.6'!I64 -> 0 | I26: ='3.6'!I78 -> 0 | J26: =SUM(F26:I26) -> 7932.4056 | K26: =SUM(E26,J26) -> 55463.504 | L26: =$D26*E26 -> 47816285 | M26: =$D26*(SUM(F26:I26)) -> 7980000 | N26: =L26+M26 -> 55796285 | O26: =(O$39*L26)/L$39 -> 47816285 | P26: =(P$39*M26)/M$39 -> 9975000 | Q26: =O26+P26 -> 57791285 | R26: =(R$39*O26)/O$39 -> 54988728 | S26: =(S$39*P26)/P$39 -> 14962500 | T26: =R26+S26 -> 69951228 | U26: =X26/D26 -> 59142.946 | V26: =Y26/D26 -> 16092.868 | W26: =U26+V26 -> 75235.814 | X26: =(X$39*R26)/R$39 -> 59497803 | Y26: =(Y$39*S26)/S$39 -> 16189425 | Z26: =X26+Y26 -> 75687228
A27: 45841 | B27: COLOCACION DE PISO DECK DE CEMENTO | C27: m² | D27: =E66 -> 27.3 | E27: ='3.7'!I22 -> 48058.608 | F27: ='3.7'!I36 -> 6959.707 | G27: ='3.7'!I50 -> 0 | H27: ='3.7'!I64 -> 0 | I27: ='3.7'!I78 -> 0 | J27: =SUM(F27:I27) -> 6959.707 | K27: =SUM(E27,J27) -> 55018.315 | L27: =$D27*E27 -> 1312000 | M27: =$D27*(SUM(F27:I27)) -> 190000 | N27: =L27+M27 -> 1502000 | O27: =(O$39*L27)/L$39 -> 1312000 | P27: =(P$39*M27)/M$39 -> 237500 | Q27: =O27+P27 -> 1549500 | R27: =(R$39*O27)/O$39 -> 1508800 | S27: =(S$39*P27)/P$39 -> 356250 | T27: =R27+S27 -> 1865050 | U27: =X27/D27 -> 59799.326 | V27: =Y27/D27 -> 14119.505 | W27: =U27+V27 -> 73918.832 | X27: =(X$39*R27)/R$39 -> 1632521.6 | Y27: =(Y$39*S27)/S$39 -> 385462.5 | Z27: =X27+Y27 -> 2017984.1
A28: 4- INSTALACIONES
A29: 45661 | B29: INSTALACION DE RIEGO. (Incluye manguera, abrazaderas, aspesrores) | C29: m² | D29: =E64 -> 2060 | E29: ='4.1'!I22 -> 1155 | F29: ='4.1'!I36 -> 0 | G29: ='4.1'!I50 -> 0 | H29: ='4.1'!I64 -> 0 | I29: ='4.1'!I78 -> 750 | J29: =SUM(F29:I29) -> 750 | K29: =SUM(E29,J29) -> 1905 | L29: =$D29*E29 -> 2379300 | M29: =$D29*(SUM(F29:I29)) -> 1545000 | N29: =L29+M29 -> 3924300 | O29: =(O$39*L29)/L$39 -> 2379300 | P29: =(P$39*M29)/M$39 -> 1931250 | Q29: =O29+P29 -> 4310550 | R29: =(R$39*O29)/O$39 -> 2736195 | S29: =(S$39*P29)/P$39 -> 2896875 | T29: =R29+S29 -> 5633070 | U29: =X29/D29 -> 1437.1665 | V29: =Y29/D29 -> 1521.5625 | W29: =U29+V29 -> 2958.729 | X29: =(X$39*R29)/R$39 -> 2960563 | Y29: =(Y$39*S29)/S$39 -> 3134418.8 | Z29: =X29+Y29 -> 6094981.7
A30: 4.1-2 | B30: PERFORACION CON BOMBA DE RIEGO DE UN 1/2 CABALLO + CISTERNA DE 500 Lts | C30: gl | D30: 1 | E30: ='4.1-2'!I22 -> 1400519.4 | F30: ='4.1-2'!I36 -> 0 | G30: ='4.1-2'!I50 -> 0 | H30: ='4.1-2'!I64 -> 0 | I30: ='4.1-2'!I78 -> 2800000 | J30: =SUM(F30:I30) -> 2800000 | K30: =SUM(E30,J30) -> 4200519.4 | L30: =$D30*E30 -> 1400519.4 | M30: =$D30*(SUM(F30:I30)) -> 2800000 | N30: =L30+M30 -> 4200519.4 | O30: =(O$39*L30)/L$39 -> 1400519.4 | P30: =(P$39*M30)/M$39 -> 3500000 | Q30: =O30+P30 -> 4900519.4 | R30: =(R$39*O30)/O$39 -> 1610597.3 | S30: =(S$39*P30)/P$39 -> 5250000 | T30: =R30+S30 -> 6860597.3 | U30: =X30/D30 -> 1742666.3 | V30: =Y30/D30 -> 5680500 | W30: =U30+V30 -> 7423166.3 | X30: =(X$39*R30)/R$39 -> 1742666.3 | Y30: =(Y$39*S30)/S$39 -> 5680500 | Z30: =X30+Y30 -> 7423166.3
A31: 45692 | B31: INSTALACION DE CANILLAS DE SERVICIO (no incluye materiales ni mano de caños) | C31: unid | D31: 4 | E31: ='4.2'!I22 -> 15000 | F31: ='4.2'!I36 -> 20000 | G31: ='4.2'!I50 -> 0 | H31: ='4.2'!I64 -> 0 | I31: ='4.2'!I78 -> 0 | J31: =SUM(F31:I31) -> 20000 | K31: =SUM(E31,J31) -> 35000 | L31: =$D31*E31 -> 60000 | M31: =$D31*(SUM(F31:I31)) -> 80000 | N31: =L31+M31 -> 140000 | O31: =(O$39*L31)/L$39 -> 60000 | P31: =(P$39*M31)/M$39 -> 100000 | Q31: =O31+P31 -> 160000 | R31: =(R$39*O31)/O$39 -> 69000 | S31: =(S$39*P31)/P$39 -> 150000 | T31: =R31+S31 -> 219000 | U31: =X31/D31 -> 18664.5 | V31: =Y31/D31 -> 40575 | W31: =U31+V31 -> 59239.5 | X31: =(X$39*R31)/R$39 -> 74658 | Y31: =(Y$39*S31)/S$39 -> 162300 | Z31: =X31+Y31 -> 236958
A32: 45720 | B32: BOCAS DE ILUMINACION. (No incluye artefactos) | C32: unid | D32: 80 | E32: ='4.3'!I22 -> 44000 | F32: ='4.3'!I36 -> 0 | G32: ='4.3'!I50 -> 0 | H32: ='4.3'!I64 -> 0 | I32: ='4.3'!I78 -> 65000 | J32: =SUM(F32:I32) -> 65000 | K32: =SUM(E32,J32) -> 109000 | L32: =$D32*E32 -> 3520000 | M32: =$D32*(SUM(F32:I32)) -> 5200000 | N32: =L32+M32 -> 8720000 | O32: =(O$39*L32)/L$39 -> 3520000 | P32: =(P$39*M32)/M$39 -> 6500000 | Q32: =O32+P32 -> 10020000 | R32: =(R$39*O32)/O$39 -> 4048000 | S32: =(S$39*P32)/P$39 -> 9750000 | T32: =R32+S32 -> 13798000 | U32: =X32/D32 -> 54749.2 | V32: =Y32/D32 -> 131868.75 | W32: =U32+V32 -> 186617.95 | X32: =(X$39*R32)/R$39 -> 4379936 | Y32: =(Y$39*S32)/S$39 -> 10549500 | Z32: =X32+Y32 -> 14929436
A33: 45751 | B33: ILUMINACION ENTIERRO DE CABLE SUBTERRANEO CUBIERTO CON LADRILLOS Y MALLA (no incluye empalmes) | C33: m | D33: 250 | E33: =((750000+25000+30000)*1.2)/D33 -> 3864 | F33: 0 | G33: 0 | H33: 0 | I33: 4400 | J33: =SUM(F33:I33) -> 4400 | K33: =SUM(E33,J33) -> 8264 | L33: =$D33*E33 -> 966000 | M33: =$D33*(SUM(F33:I33)) -> 1100000 | N33: =L33+M33 -> 2066000 | O33: =(O$39*L33)/L$39 -> 966000 | P33: =(P$39*M33)/M$39 -> 1375000 | Q33: =O33+P33 -> 2341000 | R33: =(R$39*O33)/O$39 -> 1110900 | S33: =(S$39*P33)/P$39 -> 2062500 | T33: =R33+S33 -> 3173400 | U33: =X33/D33 -> 4807.9752 | V33: =Y33/D33 -> 8926.5 | W33: =U33+V33 -> 13734.475 | X33: =(X$39*R33)/R$39 -> 1201993.8 | Y33: =(Y$39*S33)/S$39 -> 2231625 | Z33: =X33+Y33 -> 3433618.8
A34: 45781 | B34: INSTALACION ELECTRICA DE TABLERO Y PILAR | C34: unid | D34: 1 | E34: ='4.5'!I22 -> 2000000 | F34: ='4.5'!I36 -> 0 | G34: ='4.5'!I50 -> 0 | H34: ='4.5'!I64 -> 0 | I34: ='4.5'!I78 -> 1000000 | J34: =SUM(F34:I34) -> 1000000 | K34: =SUM(E34,J34) -> 3000000 | L34: =$D34*E34 -> 2000000 | M34: =$D34*(SUM(F34:I34)) -> 1000000 | N34: =L34+M34 -> 3000000 | O34: =(O$39*L34)/L$39 -> 2000000 | P34: =(P$39*M34)/M$39 -> 1250000 | Q34: =O34+P34 -> 3250000 | R34: =(R$39*O34)/O$39 -> 2300000 | S34: =(S$39*P34)/P$39 -> 1875000 | T34: =R34+S34 -> 4175000 | U34: =X34/D34 -> 2488600 | V34: =Y34/D34 -> 2028750 | W34: =U34+V34 -> 4517350 | X34: =(X$39*R34)/R$39 -> 2488600 | Y34: =(Y$39*S34)/S$39 -> 2028750 | Z34: =X34+Y34 -> 4517350
A35: 5- CANTEROS
A36: 45662 | B36: CANTEROS (A razon de redondear el presupuesto se toma una medida y cantidad estimada de 4,5x2m h 40cm) | C36: unid | D36: 58 | E36: ='5.1'!I22 -> 611965.52 | F36: ='5.1'!I36 -> 104827.59 | G36: ='5.1'!I50 -> 108620.69 | H36: ='5.1'!I64 -> 0 | I36: ='5.1'!I78 -> 0 | J36: =SUM(F36:I36) -> 213448.28 | K36: =SUM(E36,J36) -> 825413.79 | L36: =$D36*E36 -> 35494000 | M36: =$D36*(SUM(F36:I36)) -> 12380000 | N36: =L36+M36 -> 47874000 | O36: =(O$39*L36)/L$39 -> 35494000 | P36: =(P$39*M36)/M$39 -> 15475000 | Q36: =O36+P36 -> 50969000 | R36: =(R$39*O36)/O$39 -> 40818100 | S36: =(S$39*P36)/P$39 -> 23212500 | T36: =R36+S36 -> 64030600 | U36: =X36/D36 -> 761468.69 | V36: =Y36/D36 -> 433033.19 | W36: =U36+V36 -> 1194501.9 | X36: =(X$39*R36)/R$39 -> 44165184 | Y36: =(Y$39*S36)/S$39 -> 25115925 | Z36: =X36+Y36 -> 69281109
A37: 6- MUELLE
A38: 45694 | B38: MUELLE | C38: gl | D38: 1 | J38: =SUM(F38:I38) -> 0 | K38: =SUM(E38,J38) -> 0 | L38: =$D38*E38 -> 0 | M38: =$D38*(SUM(F38:I38)) -> 0 | N38: =L38+M38 -> 0 | O38: =(O$39*L38)/L$39 -> 0 | P38: =(P$39*M38)/M$39 -> 0 | Q38: =O38+P38 -> 0 | R38: =(R$39*O38)/O$39 -> 0 | S38: =(S$39*P38)/P$39 -> 0 | T38: =R38+S38 -> 0 | U38: =X38/D38 -> 0 | V38: =Y38/D38 -> 0 | W38: =U38+V38 -> 0 | X38: =(X$39*R38)/R$39 -> 0 | Y38: =(Y$39*S38)/S$39 -> 0 | Z38: =X38+Y38 -> 0
L39: =SUM(L9:L38) -> 1.4791976e+08 | M39: =SUM(M9:M38) -> 1.109815e+08 | O39: =Q65 -> 1.4791976e+08 | P39: =Q47 -> 1.3872688e+08 | R39: =Q68 -> 1.7010772e+08 | S39: =Q50 -> 2.0809032e+08 | X39: =Q71 -> 1.8405655e+08 | Y39: =Q53 -> 225153721 | Z39: =SUM(Z9:Z38) -> 4.0921027e+08
Z41: =SUM(Y39+X39) -> 4.0921027e+08
M42: MANO DE OBRA
M43: SUBTOTAL 01 - COSTOS DIRECTOS | Q43: =SUM(M9:M38) -> 1.109815e+08
...

Sheet 01_VENTA
A1: EL ENCUENTRO
A2: Arq. Andres Yanibeli
A3: Pilar, 21 de Agosto de 2025.
A5: PLANILLA COMPUTO Y PRESPUPUESTO
A7: ITEM | B7: DESCRIPCIÓN | C7: UNIDAD | D7: CANTIDAD | E7: TOTAL (NETO)
E8: V. UNITARIO | H8: V.GENERAL
E9: MAT. | F9: M.O | G9: GENERAL | H9: MAT. | I9: M.O | J9: GENERAL
A10: ='01_C&P'!A8 -> 1- TAREAS PRELIMINARES | C10: ='01_C&P'!C8 | D10: ='01_C&P'!D8
A11: ='01_C&P'!A9 -> 45292 | B11: ='01_C&P'!B9 -> OBRADOR | C11: ='01_C&P'!C9 -> mes | D11: ='01_C&P'!D9 -> 4 | E11: ='01_C&P'!U9 -> 0 | F11: ='01_C&P'!V9 -> 811500 | G11: =E11+F11 -> 811500 | H11: =E11*D11 -> 0 | I11: =D11*F11 -> 3246000 | J11: =H11+I11 -> 3246000
A12: ='01_C&P'!A10 -> 45323 | B12: ='01_C&P'!B10 -> REPLANTEO Y NIVELACION | C12: ='01_C&P'!C10 -> gl | D12: ='01_C&P'!D10 -> 1 | E12: ='01_C&P'!U10 -> 0 | F12: ='01_C&P'!V10 -> 6086250 | G12: =E12+F12 -> 6086250 | H12: =E12*D12 -> 0 | I12: =D12*F12 -> 6086250 | J12: =H12+I12 -> 6086250
A13: ='01_C&P'!A11 -> 45352 | B13: ='01_C&P'!B11 -> BAÑO QUIMICO | C13: ='01_C&P'!C11 -> mes | D13: ='01_C&P'!D11 -> 4 | E13: ='01_C&P'!U11 -> 0 | F13: ='01_C&P'!V11 -> 162300 | G13: =E13+F13 -> 162300 | H13: =E13*D13 -> 0 | I13: =D13*F13 -> 649200 | J13: =H13+I13 -> 649200
A14: ='01_C&P'!A12 -> 45383 | B14: ='01_C&P'!B12 -> CERCO DE OBRA (Malla de seguridad permietral) | C14: ='01_C&P'!C12 -> mes | D14: ='01_C&P'!D12 -> 4 | E14: ='01_C&P'!U12 -> 0 | F14: ='01_C&P'!V12 -> 1146987.6 | G14: =E14+F14 -> 1146987.6 | H14: =E14*D14 -> 0 | I14: =D14*F14 -> 4587950.5 | J14: =H14+I14 -> 4587950.5
A15: ='01_C&P'!A13 -> 45413 | B15: ='01_C&P'!B13 -> LIMPIZA PERIODICA DE OBRA | C15: ='01_C&P'!C13 -> mes | D15: ='01_C&P'!D13 -> 4 | E15: ='01_C&P'!U13 -> 0 | F15: ='01_C&P'!V13 -> 1217250 | G15: =E15+F15 -> 1217250 | H15: =E15*D15 -> 0 | I15: =D15*F15 -> 4869000 | J15: =H15+I15 -> 4869000
A16: ='01_C&P'!A14 -> 45444 | B16: ='01_C&P'!B14 -> ACARREO DE MATERIALES | C16: ='01_C&P'!C14 -> mes | D16: ='01_C&P'!D14 -> 4 | E16: ='01_C&P'!U14 -> 0 | F16: ='01_C&P'!V14 -> 1217250 | G16: =E16+F16 -> 1217250 | H16: =E16*D16 -> 0 | I16: =D16*F16 -> 4869000 | J16: =H16+I16 -> 4869000
A17: ='01_C&P'!A15 -> 45474 | B17: ='01_C&P'!B15 -> LIMPIEZA FINAL DE OBRA | C17: ='01_C&P'!C15 -> gl | D17: ='01_C&P'!D15 -> 1 | E17: ='01_C&P'!U15 -> 0 | F17: ='01_C&P'!V15 -> 1785300 | G17: =E17+F17 -> 1785300 | H17: =E17*D17 -> 0 | I17: =D17*F17 -> 1785300 | J17: =H17+I17 -> 1785300
A18: ='01_C&P'!A16 -> 2- MOVIMEINTO DE SUELOS | C18: ='01_C&P'!C16 | D18: ='01_C&P'!D16 | E18: ='01_C&P'!U16 | F18: ='01_C&P'!V16
A19: ='01_C&P'!A17 -> 45293 | B19: ='01_C&P'!B17 -> RETIRO DE ARBOLES DE MENOR PORTE (No incluye los tres arboles existentes de gran porte) | C19: ='01_C&P'!C17 -> gl | D19: ='01_C&P'!D17 -> 1 | E19: ='01_C&P'!U17 -> 0 | F19: ='01_C&P'!V17 -> 649200 | G19: =E19+F19 -> 649200 | H19: =E19*D19 -> 0 | I19: =D19*F19 -> 649200 | J19: =H19+I19 -> 649200
A20: ='01_C&P'!A18 -> 45324 | B20: ='01_C&P'!B18 -> EXCAVACION Y RETIRO DE SUELO VEGETAL EXISTENTE (Escalones 20 cm de altura con pendiente de 5cm. Secotor de intertrabado/ garden block + contrapiso + tosca = 50 cm. Sector de Cantero 20 cm) | C20: ='01_C&P'!C18 -> m³ | D20: ='01_C&P'!D18 -> 1513.12 | E20: ='01_C&P'!U18 -> 0 | F20: ='01_C&P'!V18 -> 54804.084 | G20: =E20+F20 -> 54804.084 | H20: =E20*D20 -> 0 | I20: =D20*F20 -> 82925156 | J20: =H20+I20 -> 82925156
A21: ='01_C&P'!A19 -> 45353 | B21: ='01_C&P'!B19 -> RELLENO, COMPACTACION Y NIVELACION CON SUELO SELECCIONADO TIPO A4 (En sectores de intertrabado y deck de cemento) | C21: ='01_C&P'!C19 -> m³ | D21: ='01_C&P'!D19 -> 278.991 | E21: ='01_C&P'!U19 -> 57534.006 | F21: ='01_C&P'!V19 -> 58028.485 | G21: =E21+F21 -> 115562.49 | H21: =E21*D21 -> 16051470 | I21: =D21*F21 -> 16189425 | J21: =H21+I21 -> 32240895
A22: ='01_C&P'!A20 -> 3- SOLADOS | C22: ='01_C&P'!C20 | D22: ='01_C&P'!D20 | E22: ='01_C&P'!U20 | F22: ='01_C&P'!V20
A23: ='01_C&P'!A21 -> 45660 | B23: ='01_C&P'!B21 -> EJECUCION DE CONTRAPISO DE H8 EN VEREDA ATERRAZADA | C23: ='01_C&P'!C21 -> m² | D23: ='01_C&P'!D21 -> 719.3 | E23: ='01_C&P'!U21 -> 21587.97 | F23: ='01_C&P'!V21 -> 3553.7676 | G23: =E23+F23 -> 25141.738 | H23: =E23*D23 -> 15528227 | I23: =D23*F23 -> 2556225 | J23: =H23+I23 -> 18084452
A24: ='01_C&P'!A22 -> 45691 | B24: ='01_C&P'!B22 -> EJECUCION DE CONTRAPISO DE H8 EN VEREDA SOBRE LATERAL DE CALLE | C24: ='01_C&P'!C22 -> m² | D24: ='01_C&P'!D22 -> 314 | E24: ='01_C&P'!U22 -> 21587.97 | F24: ='01_C&P'!V22 -> 3553.7676 | G24: =E24+F24 -> 25141.738 | H24: =E24*D24 -> 6778622.6 | I24: =D24*F24 -> 1115883 | J24: =H24+I24 -> 7894505.6
A25: ='01_C&P'!A23 -> 45719 | B25: ='01_C&P'!B23 -> EJECUCION DE ESCALON DE HORMIGON ARMADO CURVO CON ZAPATA PARA CONTECION DE SUELO | C25: ='01_C&P'!C23 -> m | D25: ='01_C&P'!D23 -> 435.5 | E25: ='01_C&P'!U23 -> 26382.964 | F25: ='01_C&P'!V23 -> 45839.036 | G25: =E25+F25 -> 72222 | H25: =E25*D25 -> 11489781 | I25: =D25*F25 -> 19962900 | J25: =H25+I25 -> 31452681
A26: ='01_C&P'!A24 -> 45750 | B26: ='01_C&P'!B24 -> CORDON PERIMETRAL DE 10X10 SOBRE LATERAL DE CALLE | C26: ='01_C&P'!C24 -> m | D26: ='01_C&P'!D24 -> 156.1 | E26: ='01_C&P'!U24 -> 4773.8837 | F26: ='01_C&P'!V24 -> 18325.032 | G26: =E26+F26 -> 23098.916 | H26: =E26*D26 -> 745203.25 | I26: =D26*F26 -> 2860537.5 | J26: =H26+I26 -> 3605740.7
A27: ='01_C&P'!A25 -> 45780 | B27: ='01_C&P'!B25 -> COLOCACION DE GARDEN BLOCK | C27: ='01_C&P'!C25 -> m² | D27: ='01_C&P'!D25 -> 427 | E27: ='01_C&P'!U25 -> 35876.637 | F27: ='01_C&P'!V25 -> 17151.727 | G27: =E27+F27 -> 53028.364 | H27: =E27*D27 -> 15319324 | I27: =D27*F27 -> 7323787.5 | J27: =H27+I27 -> 22643111
A28: ='01_C&P'!A26 -> 45811 | B28: ='01_C&P'!B26 -> COLOCACION DE BLOQUES INTERTRABADO DE CEMENTO | C28: ='01_C&P'!C26 -> m² | D28: ='01_C&P'!D26 -> 1006 | E28: ='01_C&P'!U26 -> 59142.946 | F28: ='01_C&P'!V26 -> 16092.868 | G28: =E28+F28 -> 75235.814 | H28: =E28*D28 -> 59497803 | I28: =D28*F28 -> 16189425 | J28: =H28+I28 -> 75687228
A29: ='01_C&P'!A27 -> 45841 | B29: ='01_C&P'!B27 -> COLOCACION DE PISO DECK DE CEMENTO | C29: ='01_C&P'!C27 -> m² | D29: ='01_C&P'!D27 -> 27.3 | E29: ='01_C&P'!U27 -> 59799.326 | F29: ='01_C&P'!V27 -> 14119.505 | G29: =E29+F29 -> 73918.832 | H29: =E29*D29 -> 1632521.6 | I29: =D29*F29 -> 385462.5 | J29: =H29+I29 -> 2017984.1
A30: ='01_C&P'!A28 -> 4- INSTALACIONES | C30: ='01_C&P'!C28 | D30: ='01_C&P'!D28 | E30: ='01_C&P'!U28 | F30: ='01_C&P'!V28
A31: ='01_C&P'!A29 -> 45661 | B31: ='01_C&P'!B29 -> INSTALACION DE RIEGO. (Incluye manguera, abrazaderas, aspesrores) | C31: ='01_C&P'!C29 -> m² | D31: ='01_C&P'!D29 -> 2060 | E31: ='01_C&P'!U29 -> 1437.1665 | F31: ='01_C&P'!V29 -> 1521.5625 | G31: =E31+F31 -> 2958.729 | H31: =E31*D31 -> 2960563 | I31: =D31*F31 -> 3134418.8 | J31: =H31+I31 -> 6094981.7
A32: ='01_C&P'!A30 -> 4.1-2 | B32: ='01_C&P'!B30 -> PERFORACION CON BOMBA DE RIEGO DE UN 1/2 CABALLO + CISTERNA DE 500 Lts | C32: ='01_C&P'!C30 -> gl | D32: ='01_C&P'!D30 -> 1 | E32: ='01_C&P'!U30 -> 1742666.3 | F32: ='01_C&P'!V30 -> 5680500 | G32: =E32+F32 -> 7423166.3 | H32: =E32*D32 -> 1742666.3 | I32: =D32*F32 -> 5680500 | J32: =H32+I32 -> 7423166.3
A33: ='01_C&P'!A31 -> 45692 | B33: ='01_C&P'!B31 -> INSTALACION DE CANILLAS DE SERVICIO (no incluye materiales ni mano de caños) | C33: ='01_C&P'!C31 -> unid | D33: ='01_C&P'!D31 -> 4 | E33: ='01_C&P'!U31 -> 18664.5 | F33: ='01_C&P'!V31 -> 40575 | G33: =E33+F33 -> 59239.5 | H33: =E33*D33 -> 74658 | I33: =D33*F33 -> 162300 | J33: =H33+I33 -> 236958
A34: ='01_C&P'!A32 -> 45720 | B34: ='01_C&P'!B32 -> BOCAS DE ILUMINACION. (No incluye artefactos) | C34: ='01_C&P'!C32 -> unid | D34: ='01_C&P'!D32 -> 80 | E34: ='01_C&P'!U32 -> 54749.2 | F34: ='01_C&P'!V32 -> 131868.75 | G34: =E34+F34 -> 186617.95 | H34: =E34*D34 -> 4379936 | I34: =D34*F34 -> 10549500 | J34: =H34+I34 -> 14929436
A35: ='01_C&P'!A33 -> 45751 | B35: ='01_C&P'!B33 -> ILUMINACION ENTIERRO DE CABLE SUBTERRANEO CUBIERTO CON LADRILLOS Y MALLA (no incluye empalmes) | C35: ='01_C&P'!C33 -> m | D35: ='01_C&P'!D33 -> 250 | E35: ='01_C&P'!U33 -> 4807.9752 | F35: ='01_C&P'!V33 -> 8926.5 | G35: =E35+F35 -> 13734.475 | H35: =E35*D35 -> 1201993.8 | I35: =D35*F35 -> 2231625 | J35: =H35+I35 -> 3433618.8
A36: ='01_C&P'!A34 -> 45781 | B36: ='01_C&P'!B34 -> INSTALACION ELECTRICA DE TABLERO Y PILAR | C36: ='01_C&P'!C34 -> unid | D36: ='01_C&P'!D34 -> 1 | E36: ='01_C&P'!U34 -> 2488600 | F36: ='01_C&P'!V34 -> 2028750 | G36: =E36+F36 -> 4517350 | H36: =E36*D36 -> 2488600 | I36: =D36*F36 -> 2028750 | J36: =H36+I36 -> 4517350
A37: ='01_C&P'!A35 -> 5- CANTEROS | C37: ='01_C&P'!C35 | D37: ='01_C&P'!D35 | E37: ='01_C&P'!U35 | F37: ='01_C&P'!V35
A38: ='01_C&P'!A36 -> 45662 | B38: ='01_C&P'!B36 -> CANTEROS (A razon de redondear el presupuesto se toma una medida y cantidad estimada de 4,5x2m h 40cm) | C38: ='01_C&P'!C36 -> unid | D38: ='01_C&P'!D36 -> 58 | E38: ='01_C&P'!U36 -> 761468.69 | F38: ='01_C&P'!V36 -> 433033.19 | G38: =E38+F38 -> 1194501.9 | H38: =E38*D38 -> 44165184 | I38: =D38*F38 -> 25115925 | J38: =H38+I38 -> 69281109
H39: =SUM(H11:H38) -> 1.8405655e+08 | I39: =SUM(I11:I38) -> 225153721 | J39: =SUM(J11:J38) -> 4.0921027e+08
A40: 6-PROYECTO EJECUTIVO
A41: 45663 | B41: VALOR DE PROYECTO EJECUTIVO 10% DE LA TOTALIDAD DE LA OBRA | C41: =J39*0.1 -> 40921027 | H41: TOTAL + PROYECTO EJECUTIVO | J41: =SUM(J39+C41) -> 4.501313e+08
A43: ITEM | B43: DESCRIPCIÓN | C43: UNIDAD | D43: CANTIDAD | E43: TOTAL (NETO)
...

Sheet 2.2.
A1: ='01_C&P'!A1 -> NOMBRE DE LA OBRA
A3: ='01_C&P'!A18 -> 45324 | B3: =IF($A3=0,"",VLOOKUP($A3,'01_C&P'!$A$9:$D$91,2,FALSE)) -> EXCAVACION Y RETIRO DE SUELO VEGETAL EXISTENTE (Escalones 20 cm de altura con pendiente de 5cm. Secotor de intertrabado/ garden block + contrapiso + tosca = 50 cm. Sector de Cantero 20 cm) | H3: =IF($A3=0,"",VLOOKUP($A3,'01_C&P'!$A$9:$D$91,4,FALSE)) -> 1513.12 | I3: =IF($A3=0,"",VLOOKUP($A3,'01_C&P'!$A$9:$D$91,3,FALSE)) -> m³
L4: =H3*1.5/6 -> 378.28
A5: MATERIALES
A6: Código | B6: Descripción | C6: Unidad | D6: Cantidad | F6: Desperdicio | G6: Cantidad + Desperdicio | H6: Precio Unitario | I6: Subtotal | L6: =H3/12 -> 126.09333
B7: =IF($A7=0,"",VLOOKUP($A7,'00_Mat'!$A$4:$J$1136,2,FALSE)) | C7: =IF($A7=0,"",VLOOKUP($A7,'00_Mat'!$A$4:$J$1136,3,FALSE)) | G7: =ROUNDUP((D7+(D7*F7)),0) -> 0 | H7: =IF($A7=0,"",VLOOKUP($A7,'00_Mat'!$A$4:$J$1136,5,FALSE)) | I7: =G7*H7 -> 0
B8: =IF($A8=0,"",VLOOKUP($A8,'00_Mat'!$A$4:$J$1136,2,FALSE)) | C8: =IF($A8=0,"",VLOOKUP($A8,'00_Mat'!$A$4:$J$1136,3,FALSE)) | G8: =ROUNDUP((D8+(D8*F8)),0) -> 0 | H8: =IF($A8=0,"",VLOOKUP($A8,'00_Mat'!$A$4:$J$1136,5,FALSE))
B9: =IF($A9=0,"",VLOOKUP($A9,'00_Mat'!$A$4:$J$1136,2,FALSE)) | C9: =IF($A9=0,"",VLOOKUP($A9,'00_Mat'!$A$4:$J$1136,3,FALSE)) | G9: =ROUNDUP((D9+(D9*F9)),0) -> 0 | H9: =IF($A9=0,"",VLOOKUP($A9,'00_Mat'!$A$4:$J$1136,5,FALSE))
B10: =IF($A10=0,"",VLOOKUP($A10,'00_Mat'!$A$4:$J$1136,2,FALSE)) | C10: =IF($A10=0,"",VLOOKUP($A10,'00_Mat'!$A$4:$J$1136,3,FALSE)) | G10: =ROUNDUP((D10+(D10*F10)),0) -> 0 | H10: =IF($A10=0,"",VLOOKUP($A10,'00_Mat'!$A$4:$J$1136,5,FALSE))
B11: =IF($A11=0,"",VLOOKUP($A11,'00_Mat'!$A$4:$J$1136,2,FALSE)) | C11: =IF($A11=0,"",VLOOKUP($A11,'00_Mat'!$A$4:$J$1136,3,FALSE)) | G11: =ROUNDUP((D11+(D11*F11)),0) -> 0 | H11: =IF($A11=0,"",VLOOKUP($A11,'00_Mat'!$A$4:$J$1136,5,FALSE))
B12: =IF($A12=0,"",VLOOKUP($A12,'00_Mat'!$A$4:$J$1136,2,FALSE)) | C12: =IF($A12=0,"",VLOOKUP($A12,'00_Mat'!$A$4:$J$1136,3,FALSE)) | G12: =ROUNDUP((D12+(D12*F12)),0) -> 0 | H12: =IF($A12=0,"",VLOOKUP($A12,'00_Mat'!$A$4:$J$1136,5,FALSE))
B13: =IF($A13=0,"",VLOOKUP($A13,'00_Mat'!$A$4:$J$1136,2,FALSE)) | C13: =IF($A13=0,"",VLOOKUP($A13,'00_Mat'!$A$4:$J$1136,3,FALSE)) | G13: =ROUNDUP((D13+(D13*F13)),0) -> 0 | H13: =IF($A13=0,"",VLOOKUP($A13,'00_Mat'!$A$4:$J$1136,5,FALSE))
B14: =IF($A14=0,"",VLOOKUP($A14,'00_Mat'!$A$4:$J$1136,2,FALSE)) | C14: =IF($A14=0,"",VLOOKUP($A14,'00_Mat'!$A$4:$J$1136,3,FALSE)) | G14: =ROUNDUP((D14+(D14*F14)),0) -> 0 | H14: =IF($A14=0,"",VLOOKUP($A14,'00_Mat'!$A$4:$J$1136,5,FALSE))
B15: =IF($A15=0,"",VLOOKUP($A15,'00_Mat'!$A$4:$J$1136,2,FALSE)) | C15: =IF($A15=0,"",VLOOKUP($A15,'00_Mat'!$A$4:$J$1136,3,FALSE)) | G15: =ROUNDUP((D15+(D15*F15)),0) -> 0 | H15: =IF($A15=0,"",VLOOKUP($A15,'00_Mat'!$A$4:$J$1136,5,FALSE))
B16: =IF($A16=0,"",VLOOKUP($A16,'00_Mat'!$A$4:$J$1136,2,FALSE)) | C16: =IF($A16=0,"",VLOOKUP($A16,'00_Mat'!$A$4:$J$1136,3,FALSE)) | G16: =ROUNDUP((D16+(D16*F16)),0) -> 0 | H16: =IF($A16=0,"",VLOOKUP($A16,'00_Mat'!$A$4:$J$1136,5,FALSE))
B17: =IF($A17=0,"",VLOOKUP($A17,'00_Mat'!$A$4:$J$1136,2,FALSE)) | C17: =IF($A17=0,"",VLOOKUP($A17,'00_Mat'!$A$4:$J$1136,3,FALSE)) | G17: =ROUNDUP((D17+(D17*F17)),0) -> 0 | H17: =IF($A17=0,"",VLOOKUP($A17,'00_Mat'!$A$4:$J$1136,5,FALSE))
B18: =IF($A18=0,"",VLOOKUP($A18,'00_Mat'!$A$4:$J$1136,2,FALSE)) | C18: =IF($A18=0,"",VLOOKUP($A18,'00_Mat'!$A$4:$J$1136,3,FALSE)) | G18: =ROUNDUP((D18+(D18*F18)),0) -> 0 | H18: =IF($A18=0,"",VLOOKUP($A18,'00_Mat'!$A$4:$J$1136,5,FALSE))
A20: TOTAL MATERIALES | I20: =SUM(I7:I18) -> 0
A21: =$I$3 -> m³ | I21: =$H$3 -> 1513.12
A22: TOTAL x | B22: =A21 -> m³ | I22: =I20/I21 -> 0
A25: MANO DE OBRA - PERSONAS
A26: Código | B26: Descripción | C26: Unidad | D26: Cantidad | E26: Dias | F26: Desperdicio | G26: Cantidad + Desperdicio | H26: Precio Unitario | I26: Subtotal
A27: MO-CA | B27: =IF($A27=0,"",VLOOKUP($A27,'00_MO'!$A$4:$D$7,2,FALSE)) -> Capataz | C27: =IF($A27=0,"",VLOOKUP($A27,'00_MO'!$A$4:$D$7,3,FALSE)) -> u | D27: 1 | E27: =E70 -> 25.218667 | F27: 0.1 | G27: =ROUNDUP(((D27*E27)*(1+F27)),0) -> 28 | H27: =IF($A27=0,"",VLOOKUP($A27,'00_MO'!$A$4:$D$7,4,FALSE)) -> 50000 | I27: =G27*H27 -> 1400000
A28: MO-OF | B28: =IF($A28=0,"",VLOOKUP($A28,'00_MO'!$A$4:$D$7,2,FALSE)) -> Oficial | C28: =IF($A28=0,"",VLOOKUP($A28,'00_MO'!$A$4:$D$7,3,FALSE)) -> u | G28: =ROUNDUP(((D28*E28)*(1+F28)),0) -> 0 | H28: =IF($A28=0,"",VLOOKUP($A28,'00_MO'!$A$4:$D$7,4,FALSE)) -> 40000 | I28: =G28*H28 -> 0
A29: MO-AY | B29: =IF($A29=0,"",VLOOKUP($A29,'00_MO'!$A$4:$D$7,2,FALSE)) -> Ayudante | C29: =IF($A29=0,"",VLOOKUP($A29,'00_MO'!$A$4:$D$7,3,FALSE)) -> u | D29: 1 | E29: =E70 -> 25.218667 | F29: 0.1 | G29: =ROUNDUP(((D29*E29)*(1+F29)),0) -> 28 | H29: =IF($A29=0,"",VLOOKUP($A29,'00_MO'!$A$4:$D$7,4,FALSE)) -> 30000 | I29: =G29*H29 -> 840000
B30: =IF($A30=0,"",VLOOKUP($A30,'00_MO'!$A$4:$D$7,2,FALSE)) | C30: =IF($A30=0,"",VLOOKUP($A30,'00_MO'!$A$4:$D$7,3,FALSE)) | G30: =ROUNDUP(((D30*E30)*(1+F30)),0) -> 0 | H30: =IF($A30=0,"",VLOOKUP($A30,'00_MO'!$A$4:$D$7,4,FALSE))
B31: =IF($A31=0,"",VLOOKUP($A31,'00_MO'!$A$4:$D$7,2,FALSE)) | C31: =IF($A31=0,"",VLOOKUP($A31,'00_MO'!$A$4:$D$7,3,FALSE)) | G31: =ROUNDUP(((D31*E31)*(1+F31)),0) -> 0 | H31: =IF($A31=0,"",VLOOKUP($A31,'00_MO'!$A$4:$D$7,4,FALSE))
B32: =IF($A32=0,"",VLOOKUP($A32,'00_MO'!$A$4:$D$7,2,FALSE)) | C32: =IF($A32=0,"",VLOOKUP($A32,'00_MO'!$A$4:$D$7,3,FALSE)) | G32: =ROUNDUP(((D32*E32)*(1+F32)),0) -> 0 | H32: =IF($A32=0,"",VLOOKUP($A32,'00_MO'!$A$4:$D$7,4,FALSE))
A34: TOTAL | I34: =SUM(I27:I32) -> 2240000
A35: =$I$3 -> m³ | I35: =$H$3 -> 1513.12
A36: TOTAL x | B36: =A35 -> m³ | I36: =I34/I35 -> 1480.3849
A39: MANO DE OBRA - EQUIPOS
A40: Código | B40: Descripción | C40: Unidad | D40: Cantidad | E40: Dias | F40: Desperdicio | G40: Cantidad + Desperdicio | H40: Precio Unitario | I40: Subtotal
B41: =IF($A41=0,"",VLOOKUP($A41,'00_Eq'!$A$4:$D$101,2,FALSE)) | C41: =IF($A41=0,"",VLOOKUP($A41,'00_Eq'!$A$4:$D$101,3,FALSE)) | G41: =ROUNDUP(((D41*E41)*(1+F41)),0) -> 0 | H41: =IF($A41=0,"",VLOOKUP($A41,'00_Eq'!$A$4:$D$101,4,FALSE)) | I41: =G41*H41 -> 0
B42: =IF($A42=0,"",VLOOKUP($A42,'00_Eq'!$A$4:$D$101,2,FALSE)) | C42: =IF($A42=0,"",VLOOKUP($A42,'00_Eq'!$A$4:$D$101,3,FALSE)) | G42: =ROUNDUP(((D42*E42)*(1+F42)),0) -> 0 | H42: =IF($A42=0,"",VLOOKUP($A42,'00_Eq'!$A$4:$D$101,4,FALSE)) | I42: =G42*H42 -> 0
B43: =IF($A43=0,"",VLOOKUP($A43,'00_Eq'!$A$4:$D$101,2,FALSE)) | C43: =IF($A43=0,"",VLOOKUP($A43,'00_Eq'!$A$4:$D$101,3,FALSE)) | G43: =ROUNDUP(((D43*E43)*(1+F43)),0) -> 0 | H43: =IF($A43=0,"",VLOOKUP($A43,'00_Eq'!$A$4:$D$101,4,FALSE)) | I43: =G43*H43 -> 0
B44: =IF($A44=0,"",VLOOKUP($A44,'00_Eq'!$A$4:$D$101,2,FALSE)) | C44: =IF($A44=0,"",VLOOKUP($A44,'00_Eq'!$A$4:$D$101,3,FALSE)) | G44: =ROUNDUP(((D44*E44)*(1+F44)),0) -> 0 | H44: =IF($A44=0,"",VLOOKUP($A44,'00_Eq'!$A$4:$D$101,4,FALSE)) | I44: =G44*H44 -> 0
B45: =IF($A45=0,"",VLOOKUP($A45,'00_Eq'!$A$4:$D$101,2,FALSE)) | C45: =IF($A45=0,"",VLOOKUP($A45,'00_Eq'!$A$4:$D$101,3,FALSE)) | G45: =ROUNDUP(((D45*E45)*(1+F45)),0) -> 0 | H45: =IF($A45=0,"",VLOOKUP($A45,'00_Eq'!$A$4:$D$101,4,FALSE))
B46: =IF($A46=0,"",VLOOKUP($A46,'00_Eq'!$A$4:$D$101,2,FALSE)) | C46: =IF($A46=0,"",VLOOKUP($A46,'00_Eq'!$A$4:$D$101,3,FALSE)) | G46: =ROUNDUP(((D46*E46)*(1+F46)),0) -> 0 | H46: =IF($A46=0,"",VLOOKUP($A46,'00_Eq'!$A$4:$D$101,4,FALSE))
A48: TOTAL | I48: =SUM(I41:I46) -> 0
...

Sheet 2.3.
A1: ='01_C&P'!A1 -> NOMBRE DE LA OBRA
A3: ='01_C&P'!A19 -> 45353 | B3: =IF($A3=0,"",VLOOKUP($A3,'01_C&P'!$A$9:$D$91,2,FALSE)) -> RELLENO, COMPACTACION Y NIVELACION CON SUELO SELECCIONADO TIPO A4 (En sectores de intertrabado y deck de cemento) | H3: =IF($A3=0,"",VLOOKUP($A3,'01_C&P'!$A$9:$D$91,4,FALSE)) -> 278.991 | I3: =IF($A3=0,"",VLOOKUP($A3,'01_C&P'!$A$9:$D$91,3,FALSE)) -> m³
A5: MATERIALES
A6: Código | B6: Descripción | C6: Unidad | D6: Cantidad | F6: Desperdicio | G6: Cantidad + Desperdicio | H6: Precio Unitario | I6: Subtotal | L6: CAMIONES
A7: TOS8 | B7: =IF($A7=0,"",VLOOKUP($A7,'00_Mat'!$A$4:$J$1136,2,FALSE)) -> Tosca | C7: =IF($A7=0,"",VLOOKUP($A7,'00_Mat'!$A$4:$J$1136,3,FALSE)) -> m3 | D7: =(H3)*1.4 -> 390.5874 | F7: 0.1 | G7: =ROUNDUP((D7+(D7*F7)),0) -> 430 | H7: =IF($A7=0,"",VLOOKUP($A7,'00_Mat'!$A$4:$J$1136,5,FALSE)) -> 30000 | I7: =G7*H7 -> 12900000 | L7: =H3/6 -> 46.4985
B8: =IF($A8=0,"",VLOOKUP($A8,'00_Mat'!$A$4:$J$1136,2,FALSE)) | C8: =IF($A8=0,"",VLOOKUP($A8,'00_Mat'!$A$4:$J$1136,3,FALSE)) | G8: =ROUNDUP((D8+(D8*F8)),0) -> 0 | H8: =IF($A8=0,"",VLOOKUP($A8,'00_Mat'!$A$4:$J$1136,5,FALSE))
B9: =IF($A9=0,"",VLOOKUP($A9,'00_Mat'!$A$4:$J$1136,2,FALSE)) | C9: =IF($A9=0,"",VLOOKUP($A9,'00_Mat'!$A$4:$J$1136,3,FALSE)) | G9: =ROUNDUP((D9+(D9*F9)),0) -> 0 | H9: =IF($A9=0,"",VLOOKUP($A9,'00_Mat'!$A$4:$J$1136,5,FALSE))
B10: =IF($A10=0,"",VLOOKUP($A10,'00_Mat'!$A$4:$J$1136,2,FALSE)) | C10: =IF($A10=0,"",VLOOKUP($A10,'00_Mat'!$A$4:$J$1136,3,FALSE)) | G10: =ROUNDUP((D10+(D10*F10)),0) -> 0 | H10: =IF($A10=0,"",VLOOKUP($A10,'00_Mat'!$A$4:$J$1136,5,FALSE))
B11: =IF($A11=0,"",VLOOKUP($A11,'00_Mat'!$A$4:$J$1136,2,FALSE)) | C11: =IF($A11=0,"",VLOOKUP($A11,'00_Mat'!$A$4:$J$1136,3,FALSE)) | G11: =ROUNDUP((D11+(D11*F11)),0) -> 0 | H11: =IF($A11=0,"",VLOOKUP($A11,'00_Mat'!$A$4:$J$1136,5,FALSE))
B12: =IF($A12=0,"",VLOOKUP($A12,'00_Mat'!$A$4:$J$1136,2,FALSE)) | C12: =IF($A12=0,"",VLOOKUP($A12,'00_Mat'!$A$4:$J$1136,3,FALSE)) | G12: =ROUNDUP((D12+(D12*F12)),0) -> 0 | H12: =IF($A12=0,"",VLOOKUP($A12,'00_Mat'!$A$4:$J$1136,5,FALSE))
B13: =IF($A13=0,"",VLOOKUP($A13,'00_Mat'!$A$4:$J$1136,2,FALSE)) | C13: =IF($A13=0,"",VLOOKUP($A13,'00_Mat'!$A$4:$J$1136,3,FALSE)) | G13: =ROUNDUP((D13+(D13*F13)),0) -> 0 | H13: =IF($A13=0,"",VLOOKUP($A13,'00_Mat'!$A$4:$J$1136,5,FALSE))
B14: =IF($A14=0,"",VLOOKUP($A14,'00_Mat'!$A$4:$J$1136,2,FALSE)) | C14: =IF($A14=0,"",VLOOKUP($A14,'00_Mat'!$A$4:$J$1136,3,FALSE)) | G14: =ROUNDUP((D14+(D14*F14)),0) -> 0 | H14: =IF($A14=0,"",VLOOKUP($A14,'00_Mat'!$A$4:$J$1136,5,FALSE))
B15: =IF($A15=0,"",VLOOKUP($A15,'00_Mat'!$A$4:$J$1136,2,FALSE)) | C15: =IF($A15=0,"",VLOOKUP($A15,'00_Mat'!$A$4:$J$1136,3,FALSE)) | G15: =ROUNDUP((D15+(D15*F15)),0) -> 0 | H15: =IF($A15=0,"",VLOOKUP($A15,'00_Mat'!$A$4:$J$1136,5,FALSE))
B16: =IF($A16=0,"",VLOOKUP($A16,'00_Mat'!$A$4:$J$1136,2,FALSE)) | C16: =IF($A16=0,"",VLOOKUP($A16,'00_Mat'!$A$4:$J$1136,3,FALSE)) | G16: =ROUNDUP((D16+(D16*F16)),0) -> 0 | H16: =IF($A16=0,"",VLOOKUP($A16,'00_Mat'!$A$4:$J$1136,5,FALSE))
B17: =IF($A17=0,"",VLOOKUP($A17,'00_Mat'!$A$4:$J$1136,2,FALSE)) | C17: =IF($A17=0,"",VLOOKUP($A17,'00_Mat'!$A$4:$J$1136,3,FALSE)) | G17: =ROUNDUP((D17+(D17*F17)),0) -> 0 | H17: =IF($A17=0,"",VLOOKUP($A17,'00_Mat'!$A$4:$J$1136,5,FALSE))
B18: =IF($A18=0,"",VLOOKUP($A18,'00_Mat'!$A$4:$J$1136,2,FALSE)) | C18: =IF($A18=0,"",VLOOKUP($A18,'00_Mat'!$A$4:$J$1136,3,FALSE)) | G18: =ROUNDUP((D18+(D18*F18)),0) -> 0 | H18: =IF($A18=0,"",VLOOKUP($A18,'00_Mat'!$A$4:$J$1136,5,FALSE))
A20: TOTAL MATERIALES | I20: =SUM(I7:I18) -> 12900000
A21: =$I$3 -> m³ | I21: =$H$3 -> 278.991
A22: TOTAL x | B22: =A21 -> m³ | I22: =I20/I21 -> 46238.051
A25: MANO DE OBRA - PERSONAS
A26: Código | B26: Descripción | C26: Unidad | D26: Cantidad | E26: Dias | F26: Desperdicio | G26: Cantidad + Desperdicio | H26: Precio Unitario | I26: Subtotal
A27: MO-CA | B27: =IF($A27=0,"",VLOOKUP($A27,'00_MO'!$A$4:$D$7,2,FALSE)) -> Capataz | C27: =IF($A27=0,"",VLOOKUP($A27,'00_MO'!$A$4:$D$7,3,FALSE)) -> u | D27: 1 | E27: =E69 | F27: 0.1 | G27: =ROUNDUP(((D27*E27)*(1+F27)),0) -> 0 | H27: =IF($A27=0,"",VLOOKUP($A27,'00_MO'!$A$4:$D$7,4,FALSE)) -> 50000 | I27: =G27*H27 -> 0
A28: MO-OF | B28: =IF($A28=0,"",VLOOKUP($A28,'00_MO'!$A$4:$D$7,2,FALSE)) -> Oficial | C28: =IF($A28=0,"",VLOOKUP($A28,'00_MO'!$A$4:$D$7,3,FALSE)) -> u | G28: =ROUNDUP(((D28*E28)*(1+F28)),0) -> 0 | H28: =IF($A28=0,"",VLOOKUP($A28,'00_MO'!$A$4:$D$7,4,FALSE)) -> 40000 | I28: =G28*H28 -> 0
A29: MO-AY | B29: =IF($A29=0,"",VLOOKUP($A29,'00_MO'!$A$4:$D$7,2,FALSE)) -> Ayudante | C29: =IF($A29=0,"",VLOOKUP($A29,'00_MO'!$A$4:$D$7,3,FALSE)) -> u | D29: 1 | E29: =E69 | F29: 0.1 | G29: =ROUNDUP(((D29*E29)*(1+F29)),0) -> 0 | H29: =IF($A29=0,"",VLOOKUP($A29,'00_MO'!$A$4:$D$7,4,FALSE)) -> 30000 | I29: =G29*H29 -> 0
B30: =IF($A30=0,"",VLOOKUP($A30,'00_MO'!$A$4:$D$7,2,FALSE)) | C30: =IF($A30=0,"",VLOOKUP($A30,'00_MO'!$A$4:$D$7,3,FALSE)) | G30: =ROUNDUP(((D30*E30)*(1+F30)),0) -> 0 | H30: =IF($A30=0,"",VLOOKUP($A30,'00_MO'!$A$4:$D$7,4,FALSE))
B31: =IF($A31=0,"",VLOOKUP($A31,'00_MO'!$A$4:$D$7,2,FALSE)) | C31: =IF($A31=0,"",VLOOKUP($A31,'00_MO'!$A$4:$D$7,3,FALSE)) | G31: =ROUNDUP(((D31*E31)*(1+F31)),0) -> 0 | H31: =IF($A31=0,"",VLOOKUP($A31,'00_MO'!$A$4:$D$7,4,FALSE))
B32: =IF($A32=0,"",VLOOKUP($A32,'00_MO'!$A$4:$D$7,2,FALSE)) | C32: =IF($A32=0,"",VLOOKUP($A32,'00_MO'!$A$4:$D$7,3,FALSE)) | G32: =ROUNDUP(((D32*E32)*(1+F32)),0) -> 0 | H32: =IF($A32=0,"",VLOOKUP($A32,'00_MO'!$A$4:$D$7,4,FALSE))
A34: TOTAL | I34: =SUM(I27:I32) -> 0
A35: =$I$3 -> m³ | I35: =$H$3 -> 278.991
A36: TOTAL x | B36: =A35 -> m³ | I36: =I34/I35 -> 0
A39: MANO DE OBRA - EQUIPOS
A40: Código | B40: Descripción | C40: Unidad | D40: Cantidad | E40: Dias | F40: Desperdicio | G40: Cantidad + Desperdicio | H40: Precio Unitario | I40: Subtotal
B41: =IF($A41=0,"",VLOOKUP($A41,'00_Eq'!$A$4:$D$101,2,FALSE)) | C41: =IF($A41=0,"",VLOOKUP($A41,'00_Eq'!$A$4:$D$101,3,FALSE)) | G41: =ROUNDUP(((D41*E41)*(1+F41)),0) -> 0 | H41: =IF($A41=0,"",VLOOKUP($A41,'00_Eq'!$A$4:$D$101,4,FALSE)) | I41: =G41*H41 -> 0
B42: =IF($A42=0,"",VLOOKUP($A42,'00_Eq'!$A$4:$D$101,2,FALSE)) | C42: =IF($A42=0,"",VLOOKUP($A42,'00_Eq'!$A$4:$D$101,3,FALSE)) | G42: =ROUNDUP(((D42*E42)*(1+F42)),0) -> 0 | H42: =IF($A42=0,"",VLOOKUP($A42,'00_Eq'!$A$4:$D$101,4,FALSE)) | I42: =G42*H42 -> 0
B43: =IF($A43=0,"",VLOOKUP($A43,'00_Eq'!$A$4:$D$101,2,FALSE)) | C43: =IF($A43=0,"",VLOOKUP($A43,'00_Eq'!$A$4:$D$101,3,FALSE)) | G43: =ROUNDUP(((D43*E43)*(1+F43)),0) -> 0
B44: =IF($A44=0,"",VLOOKUP($A44,'00_Eq'!$A$4:$D$101,2,FALSE)) | C44: =IF($A44=0,"",VLOOKUP($A44,'00_Eq'!$A$4:$D$101,3,FALSE)) | G44: =ROUNDUP(((D44*E44)*(1+F44)),0) -> 0
B45: =IF($A45=0,"",VLOOKUP($A45,'00_Eq'!$A$4:$D$101,2,FALSE)) | C45: =IF($A45=0,"",VLOOKUP($A45,'00_Eq'!$A$4:$D$101,3,FALSE)) | G45: =ROUNDUP(((D45*E45)*(1+F45)),0) -> 0 | H45: =IF($A45=0,"",VLOOKUP($A45,'00_Eq'!$A$4:$D$101,4,FALSE))
B46: =IF($A46=0,"",VLOOKUP($A46,'00_Eq'!$A$4:$D$101,2,FALSE)) | C46: =IF($A46=0,"",VLOOKUP($A46,'00_Eq'!$A$4:$D$101,3,FALSE)) | G46: =ROUNDUP(((D46*E46)*(1+F46)),0) -> 0 | H46: =IF($A46=0,"",VLOOKUP($A46,'00_Eq'!$A$4:$D$101,4,FALSE))
A48: TOTAL | I48: =SUM(I41:I46) -> 0
A49: =$I$3 -> m³ | I49: =$H$3 -> 278.991
...

Sheet 3.1
A1: ='01_C&P'!A1 -> NOMBRE DE LA OBRA
A3: ='01_C&P'!A21 -> 45660 | B3: =IF($A3=0,"",VLOOKUP($A3,'01_C&P'!$A$9:$D$91,2,FALSE)) -> EJECUCION DE CONTRAPISO DE H8 EN VEREDA ATERRAZADA | H3: =IF($A3=0,"",VLOOKUP($A3,'01_C&P'!$A$9:$D$91,4,FALSE)) -> 719.3 | I3: =IF($A3=0,"",VLOOKUP($A3,'01_C&P'!$A$9:$D$91,3,FALSE)) -> m²
A5: MATERIALES
A6: Código | B6: Descripción | C6: Unidad | D6: Cantidad | F6: Desperdicio | G6: Cantidad + Desperdicio | H6: Precio Unitario | I6: Subtotal
A7: A-NY200100m2 | B7: =IF($A7=0,"",VLOOKUP($A7,'00_Mat'!$A$4:$J$1136,2,FALSE)) -> Nylon 200 Micrones (100 m2 x rollo) | C7: =IF($A7=0,"",VLOOKUP($A7,'00_Mat'!$A$4:$J$1136,3,FALSE)) -> u | D7: =H3/100 -> 7.193 | F7: 0 | G7: =ROUNDUP((D7+(D7*F7)),0) -> 8 | H7: =IF($A7=0,"",VLOOKUP($A7,'00_Mat'!$A$4:$J$1136,5,FALSE)) -> 81655 | I7: =G7*H7 -> 653240
A8: m5,5 | B8: =IF($A8=0,"",VLOOKUP($A8,'00_Mat'!$A$4:$J$1136,2,FALSE)) -> Malla Φ 5,5 (2 m x 5 m) (hierros cada 0,18 x 0,18 m) - menos de 50 u (u) | C8: =IF($A8=0,"",VLOOKUP($A8,'00_Mat'!$A$4:$J$1136,3,FALSE)) -> u | D8: =H3/(2*5) -> 71.93 | F8: 0.1 | G8: =ROUNDUP((D8+(D8*F8)),0) -> 80 | H8: =IF($A8=0,"",VLOOKUP($A8,'00_Mat'!$A$4:$J$1136,5,FALSE)) -> 34628.099 | I8: =G8*H8 -> 2770247.9 | J8: evaluar opcion sin malla
A9: H8 | B9: =IF($A9=0,"",VLOOKUP($A9,'00_Mat'!$A$4:$J$1136,2,FALSE)) -> Hormigon H8 | C9: =IF($A9=0,"",VLOOKUP($A9,'00_Mat'!$A$4:$J$1136,3,FALSE)) -> m3 | D9: =H3*0.1 -> 71.93 | F9: 0.1 | G9: =ROUNDUP((D9+(D9*F9)),0) -> 80 | H9: =IF($A9=0,"",VLOOKUP($A9,'00_Mat'!$A$4:$J$1136,5,FALSE)) -> 101500 | I9: =G9*H9 -> 8120000
A10: HBP | B10: =IF($A10=0,"",VLOOKUP($A10,'00_Mat'!$A$4:$J$1136,2,FALSE)) -> BOMBA PLUMA | C10: =IF($A10=0,"",VLOOKUP($A10,'00_Mat'!$A$4:$J$1136,3,FALSE)) -> m3 | D10: =D9 -> 71.93 | F10: 0.1 | G10: =ROUNDUP((D10+(D10*F10)),0) -> 80 | H10: =IF($A10=0,"",VLOOKUP($A10,'00_Mat'!$A$4:$J$1136,5,FALSE)) -> 5200 | I10: =G10*H10 -> 416000
A11: HBPT | B11: =IF($A11=0,"",VLOOKUP($A11,'00_Mat'!$A$4:$J$1136,2,FALSE)) -> TRASLADO BOMBA PLUMA | C11: =IF($A11=0,"",VLOOKUP($A11,'00_Mat'!$A$4:$J$1136,3,FALSE)) -> u | D11: 1 | F11: 0 | G11: =ROUNDUP((D11+(D11*F11)),0) -> 1 | H11: =IF($A11=0,"",VLOOKUP($A11,'00_Mat'!$A$4:$J$1136,5,FALSE)) -> 520000 | I11: =G11*H11 -> 520000
B12: =IF($A12=0,"",VLOOKUP($A12,'00_Mat'!$A$4:$J$1136,2,FALSE)) | C12: =IF($A12=0,"",VLOOKUP($A12,'00_Mat'!$A$4:$J$1136,3,FALSE)) | G12: =ROUNDUP((D12+(D12*F12)),0) -> 0 | H12: =IF($A12=0,"",VLOOKUP($A12,'00_Mat'!$A$4:$J$1136,5,FALSE)) | I12: =G12*H12 -> 0
B13: =IF($A13=0,"",VLOOKUP($A13,'00_Mat'!$A$4:$J$1136,2,FALSE)) | C13: =IF($A13=0,"",VLOOKUP($A13,'00_Mat'!$A$4:$J$1136,3,FALSE)) | G13: =ROUNDUP((D13+(D13*F13)),0) -> 0 | H13: =IF($A13=0,"",VLOOKUP($A13,'00_Mat'!$A$4:$J$1136,5,FALSE))
B14: =IF($A14=0,"",VLOOKUP($A14,'00_Mat'!$A$4:$J$1136,2,FALSE)) | C14: =IF($A14=0,"",VLOOKUP($A14,'00_Mat'!$A$4:$J$1136,3,FALSE)) | G14: =ROUNDUP((D14+(D14*F14)),0) -> 0 | H14: =IF($A14=0,"",VLOOKUP($A14,'00_Mat'!$A$4:$J$1136,5,FALSE))
B15: =IF($A15=0,"",VLOOKUP($A15,'00_Mat'!$A$4:$J$1136,2,FALSE)) | C15: =IF($A15=0,"",VLOOKUP($A15,'00_Mat'!$A$4:$J$1136,3,FALSE)) | G15: =ROUNDUP((D15+(D15*F15)),0) -> 0 | H15: =IF($A15=0,"",VLOOKUP($A15,'00_Mat'!$A$4:$J$1136,5,FALSE))
B16: =IF($A16=0,"",VLOOKUP($A16,'00_Mat'!$A$4:$J$1136,2,FALSE)) | C16: =IF($A16=0,"",VLOOKUP($A16,'00_Mat'!$A$4:$J$1136,3,FALSE)) | G16: =ROUNDUP((D16+(D16*F16)),0) -> 0 | H16: =IF($A16=0,"",VLOOKUP($A16,'00_Mat'!$A$4:$J$1136,5,FALSE))
B17: =IF($A17=0,"",VLOOKUP($A17,'00_Mat'!$A$4:$J$1136,2,FALSE)) | C17: =IF($A17=0,"",VLOOKUP($A17,'00_Mat'!$A$4:$J$1136,3,FALSE)) | G17: =ROUNDUP((D17+(D17*F17)),0) -> 0 | H17: =IF($A17=0,"",VLOOKUP($A17,'00_Mat'!$A$4:$J$1136,5,FALSE))
B18: =IF($A18=0,"",VLOOKUP($A18,'00_Mat'!$A$4:$J$1136,2,FALSE)) | C18: =IF($A18=0,"",VLOOKUP($A18,'00_Mat'!$A$4:$J$1136,3,FALSE)) | G18: =ROUNDUP((D18+(D18*F18)),0) -> 0 | H18: =IF($A18=0,"",VLOOKUP($A18,'00_Mat'!$A$4:$J$1136,5,FALSE))
A20: TOTAL MATERIALES | I20: =SUM(I7:I18) -> 12479488 | L20: camiones
A21: =$I$3 -> m² | I21: =$H$3 -> 719.3 | L21: =D9/8 -> 8.99125
A22: TOTAL x | B22: =A21 -> m² | I22: =I20/I21 -> 17349.49
A25: MANO DE OBRA - PERSONAS
A26: Código | B26: Descripción | C26: Unidad | D26: Cantidad | E26: Dias | F26: Desperdicio | G26: Cantidad + Desperdicio | H26: Precio Unitario | I26: Subtotal
A27: MO-CA | B27: =IF($A27=0,"",VLOOKUP($A27,'00_MO'!$A$4:$D$7,2,FALSE)) -> Capataz | C27: =IF($A27=0,"",VLOOKUP($A27,'00_MO'!$A$4:$D$7,3,FALSE)) -> u | D27: 1 | E27: =2+3 -> 5 | F27: 0.25 | G27: =ROUNDUP(((D27*E27)*(1+F27)),0) -> 7 | H27: =IF($A27=0,"",VLOOKUP($A27,'00_MO'!$A$4:$D$7,4,FALSE)) -> 50000 | I27: =H27*G27 -> 350000 | K27: 2 camiones x dia
A28: MO-OF | B28: =IF($A28=0,"",VLOOKUP($A28,'00_MO'!$A$4:$D$7,2,FALSE)) -> Oficial | C28: =IF($A28=0,"",VLOOKUP($A28,'00_MO'!$A$4:$D$7,3,FALSE)) -> u | D28: 2 | E28: =2+3 -> 5 | F28: 0.25 | G28: =ROUNDUP(((D28*E28)*(1+F28)),0) -> 13 | H28: =IF($A28=0,"",VLOOKUP($A28,'00_MO'!$A$4:$D$7,4,FALSE)) -> 40000 | I28: =H28*G28 -> 520000 | K28: =8*2 -> 16 | L28: m3 | M28: =K28/0.1 -> 160 | N28: m2
A29: MO-AY | B29: =IF($A29=0,"",VLOOKUP($A29,'00_MO'!$A$4:$D$7,2,FALSE)) -> Ayudante | C29: =IF($A29=0,"",VLOOKUP($A29,'00_MO'!$A$4:$D$7,3,FALSE)) -> u | D29: 2 | E29: =2+3 -> 5 | F29: 0.25 | G29: =ROUNDUP(((D29*E29)*(1+F29)),0) -> 13 | H29: =IF($A29=0,"",VLOOKUP($A29,'00_MO'!$A$4:$D$7,4,FALSE)) -> 30000 | I29: =H29*G29 -> 390000 | K29: =D9/K28 -> 4.495625 | M29: =H3/M28 -> 4.495625
B30: =IF($A30=0,"",VLOOKUP($A30,'00_MO'!$A$4:$D$7,2,FALSE)) | C30: =IF($A30=0,"",VLOOKUP($A30,'00_MO'!$A$4:$D$7,3,FALSE)) | G30: =ROUNDUP(((D30*E30)*(1+F30)),0) -> 0 | H30: =IF($A30=0,"",VLOOKUP($A30,'00_MO'!$A$4:$D$7,4,FALSE)) | K30: preparacion de piso?
B31: =IF($A31=0,"",VLOOKUP($A31,'00_MO'!$A$4:$D$7,2,FALSE)) | C31: =IF($A31=0,"",VLOOKUP($A31,'00_MO'!$A$4:$D$7,3,FALSE)) | G31: =ROUNDUP(((D31*E31)*(1+F31)),0) -> 0 | H31: =IF($A31=0,"",VLOOKUP($A31,'00_MO'!$A$4:$D$7,4,FALSE))
B32: =IF($A32=0,"",VLOOKUP($A32,'00_MO'!$A$4:$D$7,2,FALSE)) | C32: =IF($A32=0,"",VLOOKUP($A32,'00_MO'!$A$4:$D$7,3,FALSE)) | G32: =ROUNDUP(((D32*E32)*(1+F32)),0) -> 0 | H32: =IF($A32=0,"",VLOOKUP($A32,'00_MO'!$A$4:$D$7,4,FALSE))
A34: TOTAL | I34: =SUM(I27:I32) -> 1260000
A35: =$I$3 -> m² | I35: =$H$3 -> 719.3
A36: TOTAL x | B36: =A35 -> m² | I36: =I34/I35 -> 1751.703
A39: MANO DE OBRA - EQUIPOS
A40: Código | B40: Descripción | C40: Unidad | D40: Cantidad | E40: Dias | F40: Desperdicio | G40: Cantidad + Desperdicio | H40: Precio Unitario | I40: Subtotal
B41: =IF($A41=0,"",VLOOKUP($A41,'00_Eq'!$A$4:$D$6,2,FALSE)) | C41: =IF($A41=0,"",VLOOKUP($A41,'00_Eq'!$A$4:$D$51,3,FALSE)) | G41: =ROUNDUP(((D41*E41)*(1+F41)),0) -> 0 | H41: =IF($A41=0,"",VLOOKUP($A41,'00_Eq'!$A$4:$D$6,4,FALSE))
B42: =IF($A42=0,"",VLOOKUP($A42,'00_Eq'!$A$4:$D$6,2,FALSE)) | C42: =IF($A42=0,"",VLOOKUP($A42,'00_Eq'!$A$4:$D$51,3,FALSE)) | G42: =ROUNDUP(((D42*E42)*(1+F42)),0) -> 0 | H42: =IF($A42=0,"",VLOOKUP($A42,'00_Eq'!$A$4:$D$6,4,FALSE))
B43: =IF($A43=0,"",VLOOKUP($A43,'00_Eq'!$A$4:$D$6,2,FALSE)) | C43: =IF($A43=0,"",VLOOKUP($A43,'00_Eq'!$A$4:$D$51,3,FALSE)) | G43: =ROUNDUP(((D43*E43)*(1+F43)),0) -> 0 | H43: =IF($A43=0,"",VLOOKUP($A43,'00_Eq'!$A$4:$D$6,4,FALSE))
B44: =IF($A44=0,"",VLOOKUP($A44,'00_Eq'!$A$4:$D$6,2,FALSE)) | C44: =IF($A44=0,"",VLOOKUP($A44,'00_Eq'!$A$4:$D$51,3,FALSE)) | G44: =ROUNDUP(((D44*E44)*(1+F44)),0) -> 0 | H44: =IF($A44=0,"",VLOOKUP($A44,'00_Eq'!$A$4:$D$6,4,FALSE))
B45: =IF($A45=0,"",VLOOKUP($A45,'00_Eq'!$A$4:$D$6,2,FALSE)) | C45: =IF($A45=0,"",VLOOKUP($A45,'00_Eq'!$A$4:$D$51,3,FALSE)) | G45: =ROUNDUP(((D45*E45)*(1+F45)),0) -> 0 | H45: =IF($A45=0,"",VLOOKUP($A45,'00_Eq'!$A$4:$D$6,4,FALSE))
B46: =IF($A46=0,"",VLOOKUP($A46,'00_Eq'!$A$4:$D$6,2,FALSE)) | C46: =IF($A46=0,"",VLOOKUP($A46,'00_Eq'!$A$4:$D$51,3,FALSE)) | G46: =ROUNDUP(((D46*E46)*(1+F46)),0) -> 0 | H46: =IF($A46=0,"",VLOOKUP($A46,'00_Eq'!$A$4:$D$6,4,FALSE))
A48: TOTAL | I48: =SUM(I41:I46) -> 0
A49: =$I$3 -> m² | I49: =$H$3 -> 719.3
...

Sheet 3.3
