Workbook

Sheet 00_Mat
A1: MATERIALES
A3: CODIGO | B3: MATERIALES CORRALON | C3: UNIDAD | D3: PRECIO CON IVA | E3: PRECIO SIN IVA | F3: DESCUENTO | G3: PRECIO CON DESCUENTO
A4: ARG | B4: Arena a granel (1m3) | C4: m3 | D4: 29403 | E4: =D4/1.21 -> 24300
A5: AR | B5: Bolson de Arena (1m3) | C5: m3 | E5: 33470
A6: PIEG | B6: Piedra a granel (1m3) | C6: m3 | D6: 58995 | E6: =D6/1.21 -> 48756.198
A7: PIEP | B7: Bolson de Piedra partida (1m3) | C7: m3 | E7: 74566
A8: PIE | B8: Bolson de Piedra (1m3) | C8: m3 | D8: 60000 | E8: 61700
A9: CEM | B9: Bolsa Cemento "Loma Negra" 25 k (u) | C9: u | E9: 7000 | I9: ML | J9: 46081
A10: CEM-GROUT | B10: Sika Grout 25k (u) | C10: u | E10: 31900
A11: CAL | B11: Bolsa Cal "Cacique" 25 k (u) | C11: u | D11: 6500 | E11: =D11/1.21 -> 5371.9008
A12: PLASTICOR | B12: Bolsa Plasticor 40k (u) | C12: u | D12: 8500 | E12: =D12/1.21 -> 7024.7934
A13: CER | B13: Ceresita 20 k (u) | C13: u | D13: 45000 | E13: =D13/1.21 -> 37190.083
A14: LP18 | B14: Ladrillo Portante 18 (u) | C14: u | E14: 1377
A15: LP12 | B15: Ladrillo Portante 12 (u) | C15: u | E15: 1110.2
A16: LH18 | B16: Ladrillo Hueco 18 (u) | C16: u | E16: 837
A17: LH12 | B17: Ladrillo Hueco 12 (u) | C17: u | E17: 726
A18: LH8 | B18: Ladrillo Hueco 8 (u) | C18: u | E18: 568.7 | I18: Su Corralon | J18: 45824
A19: LCOM | B19: Ladrillo Comun | C19: u | E19: 190.61 | I19: Su Corralon | J19: 45824
A20: LCOMVIST | B20: Ladrillo Comun Vista | C20: u | D20: 240 | E20: =D20/1.21 -> 198.34711 | I20: Su Corralon | J20: 45771
A21: LPINT | B21: Pavimento Intertrabado | C21: m2 | E21: 37600 | I21: Su Corralon | J21: 45824
A22: LGB | B22: Garden Block 38x38x8cm (1m2) | C22: m2 | E22: 22500 | I22: ml | J22: 45877
A23: LDC | B23: Deck Liston Hormigon Cemento Piso Durmiente 100 X 12 Cms (1m2) | E23: 41000 | I23: ml | J23: 45877
A24: YES | B24: Bolsa Yeso Tuyango 30 k (u) | C24: u | D24: 13879 | E24: 15000 | I24: ML | J24: 46081
A25: YES-P | B25: Bolsa Yeso Proyectado Tuyango 30 k (u) | C25: u | E25: 18000 | I25: ml | J25: 45902
A26: ES | B26: Cascote / Escombro (m3) | C26: m3 | E26: 35000 | I26: ML | J26: 45929
A27: TOS | B27: Tosca Compactada | C27: m3 | E27: 30000 | I27: Pablo | J27: 45778
A28: TN | B28: BOLSON Tierra negra | C28: m3 | E28: 33275 | I28: Su Corralon | J28: 45824
A29: TNF | B29: BOLSON Tierra negra fertil 10% compost | C29: m3 | E29: 86600 | I29: Su Corralon | J29: 45890
A30: TRA | B30: BOLSON Tierra negra abonada 40% compost | C30: m3 | E30: 94400 | I30: Su Corralon | J30: 45890
A31: TNFI | B31: TIERRA NEGRA FINA | C31: m3 | E31: 60000 | I31: Pablo | J31: 45896
A32: TNRL | B32: TIERRA NEGRA DE RELLENO LIMPIO | C32: m3 | E32: 25000 | I32: Pablo | J32: 45896
A33: TNR | B33: TIERRA NEGRA DE RELLENO | C33: m3 | E33: 20000 | I33: Pablo | J33: 45896
A34: CL2 | B34: Clavos 2" punta paris (k) | C34: k | E34: 4500 | I34: urquiza | J34: 46023
A35: CL2.5 | B35: Clavos 2,5" punta paris (k) | C35: k | E35: 4500 | I35: urquiza | J35: 46023
A36: AL-50k | B36: Alambre Fardo (50 k) | C36: k | E36: 220000 | I36: urquiza | J36: 46023
A37: ES24 | B37: Cascote / Escombro cada 24 m3 (m3) | C37: m3 | D37: 16500 | E37: =D37/1.21 -> 13636.364 | I37: Su Corralon | J37: 45412
A38: DISCO PORC | B38: Disco Amoladora para porcelanato. marca aliafor | E38: 22314 | I38: Su Corralon | J38: 45919
A39: DISCO | B39: Disco Ascerradora | C39: u | E39: 120000
A40: DIS | B40: Disco corte | C40: u | E40: 40000
A41: VI7 | B41: Vigueta pretensada de hormigon 7m | C41: u | E41: 34000
...

Sheet 00_MO
A1: MANO DE OBRA
A3: CODIGO | B3: MATERIALES CORRALON | C3: UNIDAD | D3: PRECIO SIN IVA | E3: FECHA
A4: MO-CA | B4: Capataz | C4: u | D4: =80000*1.5 -> 120000 | E4: 46063
A5: MO-PU | B5: Puntero | C5: u | D5: =70000*1.5 -> 105000 | E5: 46063
A6: MO-OF | B6: Oficial | C6: u | D6: =60000*1.5 -> 90000 | E6: 46063
A7: MO-AY | B7: Ayudante | C7: u | D7: =40000*1.5 -> 60000 | E7: 46063

Sheet 00_Eq
A1: EQUIPOS
A3: CODIGO | B3: MATERIALES CORRALON | C3: UNIDAD | D3: PRECIO SIN IVA | E3: REFERENCIA | F3: FECHA
A4: E-MC | B4: Mini Cargadora | C4: u | D4: 420000 | E4: JP VIAL | F4: 45945 | G4: CON MAQUINISTA Y GASOIL
A5: E-MCM | B5: Mini Cargadora con martillo | C5: u | D5: 550000 | E5: Pablo | F5: 45804
A6: E-ME | B6: Mini Excavadora | C6: u | D6: 550000 | E6: Pablo | F6: 45804
A7: E-MP | B7: Motopison | C7: u | D7: 40000
A8: E-RP | B8: Retropala | C8: u | D8: 680000 | E8: JP VIAL | F8: 45945 | G8: CON MAQUINISTA Y GASOIL
A9: E-VC | B9: Vibrocompactador | C9: u | D9: 680000 | E9: JP VIAL | F9: 45945 | G9: CON MAQUINISTA Y GASOIL
A10: E-MN | B10: Motoniveladora | C10: u | D10: 900000 | E10: JP VIAL | F10: 45945 | G10: CON MAQUINISTA Y GASOIL
A11: E-CAMCH | B11: Camion Chasis | C11: u | D11: 350000 | E11: JP VIAL | F11: 45945 | G11: CON MAQUINISTA Y GASOIL
A12: E-REG | B12: Regador | C12: u | D12: 350000 | E12: JP VIAL | F12: 45945 | G12: CON MAQUINISTA Y GASOIL
A13: E-MAR | B13: Martillete | C13: u | D13: 45000 | E13: allquifer | F13: 45916
A14: E-ASC | B14: Ascerradora | C14: u | D14: 60000 | F14: 45890
A15: E-RET | B15: Retiro x camion | C15: u | D15: 160000 | E15: Nico | F15: 45890
A16: E-MR | B16: Mini Retro | C16: u | D16: 480000 | E16: Pablo | F16: 45804
A17: MS-TM3 | B17: TOSCA x M3 | C17: m3 | D17: 30000 | E17: Pablo | F17: 45804
A18: MS-TCA | B18: TOSCA X EQUIPO | C18: m3 | D18: 10500 | E18: JP VIAL | F18: 45945
A19: MS-ER | B19: EXCAVACION Y RETIRO | C19: m3 | D19: 30000 | G19: precio a chekear
A20: MS-TC | B20: TOSCA COMPACTADA | C20: m3 | D20: 25000 | E20: Pablo | F20: 45804
A21: MS-ARBOL | B21: RETIRO DE ARBOL | C21: u | D21: 570000 | E21: Pablo | F21: 45804
A22: E-CAM | B22: Camioneta | C22: u | D22: 200000
A23: E-TRAS | B23: TRASLADO DE MAQUINARIA | C23: u | D23: 300000 | E23: Pablo | F23: 45804
A24: E-VOL | B24: Volquete | C24: u | D24: 200000
A25: E-EXC | B25: Excavadora 22TN | C25: u | D25: 900000 | E25: JP VIAL | F25: 45945 | G25: CON MAQUINISTA Y GASOIL
A26: E-TOP | B26: Topadora | C26: u | D26: 1350000 | E26: JP VIAL | F26: 45945 | G26: CON MAQUINISTA Y GASOIL
A27: E-PALA | B27: Pala frontal | C27: u | D27: 800000 | E27: JP VIAL | F27: 45945 | G27: CON MAQUINISTA Y GASOIL

Sheet 00_Sub
A1: SUBCONTRATOS
A3: CODIGO | B3: PINTURA | C3: UNIDAD | D3: PRECIO SIN IVA | E3: REFERENCIA | F3: FECHA
A4: SUB-PI | B4: Pintura Interior: 1Mano Enduido + Yeso, 1 Mano Enduido, 2 a 3 Manos de Pintura | C4: m2 | D4: 15000 | E4: CHIZO | F4: 45904
A5: SUB-PIC | B5: Pintura Interior Cielorraso con una mano de enduido | C5: m2 | D5: 10000 | E5: CHIZO | F5: 45904
A6: SUB-PET | B6: Pintura Exterior Tarquini | C6: m2 | D6: 12000 | E6: CHIZO | F6: 45904
A7: SUB-PE | B7: Pintura Exterior | C7: m2 | D7: 10000
A8: SUB-PIY | B8: Pintura interior sobre yeso con una mano de enduido, lijado, fijado y pintado | C8: m2 | D8: 10000 | E8: CHIZO | F8: 45904
A9: SUB-PI | B9: Pintura Interior | C9: m2 | D9: 8000
A10: SUB-END | B10: Enduido | C10: m2 | D10: 8000
A11: SUB-PPS | B11: Pintura Puerta Simple Hoja | C11: u | D11: 25000
A12: SUB-PPD | B12: Pintura Puerta Doble Hoja | C12: u | D12: 50000
A13: CODIGO | B13: DURLOCK | C13: UNIDAD | D13: PRECIO SIN IVA | E13: REFERENCIA | F13: FECHA
A14: SUB-CIE | B14: Instalacion de Cielorraso Durlock. Incluye Materiales. | C14: m2 | D14: 37000 | E14: CLAUDIO | F14: 45791
A15: SUB-CIEDES | B15: Instalacion de Cielorraso Desmontable. Incluye Materiales. | C15: m2 | D15: 37000 | E15: CLAUDIO | F15: 45791
A16: SUB-CIECO | B16: Instalacion de Cielorraso Durlock Cortineros. Incluye Materiales. | C16: m | D16: 45000 | E16: CLAUDIO | F16: 45791
A17: SUB-CIECA | B17: Instalacion de Cajon Durlock. Incluye Materiales. | C17: m | D17: 20000 | E17: CLAUDIO | F17: 45791
A18: SUB-CIEGL | B18: Instalacion de Cielorraso Durlock Garganta Led. Incluye Materiales. | C18: m | D18: 45000 | E18: CLAUDIO | F18: 45791
A19: SUB-TAB | B19: Instalacion de Tabique Durlock. Incluye Materiales. | C19: m2 | D19: 48000 | E19: CLAUDIO | F19: 45791
A20: SUB-BZ | B20: Instlacion Buña Z. Incluye Materiales. | C20: m | D20: 16000 | E20: CLAUDIO | F20: 45791
A21: SUB-CAN | B21: Instalacion Cantonera. Incluye Materiales. | C21: m | D21: 16000 | E21: CLAUDIO | F21: 45791
A22: CODIGO | B22: ELECTRICIDAD | C22: UNIDAD | D22: PRECIO SIN IVA | E22: REFERENCIA | F22: FECHA
A23: SUB-E-BOC | B23: Boca. Mano de obra y Materiales. | C23: boca | D23: 100000 | E23: CABEZA | F23: 45800
A24: SUB-E-COL | B24: Colocacion de artefatcos | C24: u | D24: 7000 | E24: CABEZA | F24: 45800
A25: SUB-E-AAC | B25: Alimentacion aire acondicionado con split. (Mo y mat) | C25: u | D25: 100000 | E25: CABEZA | F25: 45800
A26: SUB-E-TAB | B26: Instalacion de Tablero para 100 bocas (casa chica). Incluye alimentacion desde el pilar. | C26: u | D26: 100000 | E26: CABEZA | F26: 45800
A27: SUB-ELE-B | B27: Boca mano de obra | C27: boca | D27: 60000 | E27: CABEZA | F27: 45800
A28: CODIGO | B28: PISERO | C28: UNIDAD | D28: PRECIO SIN IVA | E28: REFERENCIA | F28: FECHA
A29: SUB-PIS | B29: PISO | C29: m² | D29: 10000 | E29: CESAR | F29: 46079
A30: SUB-COR | B30: CORDON | C30: m | D30: 10000 | E30: CEFERINO | F30: 45800
A31: SUB-CONT | B31: BOMBEO HORMIGON CELULAR. Incluye mano de obra y bomba. | C31: m² | D31: 12000 | E31: ISMAEL | F31: 46079
A32: CODIGO | B32: REVESTIMIENTOS | C32: UNIDAD | D32: PRECIO SIN IVA | E32: REFERENCIA | F32: FECHA
A33: SUB-SIDING | B33: Colocion de siding en pared | C33: m2 | D33: 18000
A34: SUB-REV-CH | B34: Revestimiento de chapa | C34: m2 | D34: 18000 | E34: Hugo | F34: 45902
A35: SUB-YP | B35: Ejecucion de yeso proyectado en Pared | C35: m2 | D35: 10000 | E35: ISMAEL | F35: 45902
A36: SUB-YAC | B36: Ejecucion de yeso proyectado aristas y cantonera | C36: unidad | D36: 10000 | E36: ISMAEL | F36: 45902
A37: CODIGO | B37: MOVIMIENTO DE SUELOS | C37: UNIDAD | D37: PRECIO SIN IVA | E37: REFERENCIA | F37: FECHA
A38: MS-MC | B38: MINICARGADORA | C38: u | D38: 420000 | E38: PABLO | F38: 45743
A39: MS-MCM | B39: MINICARGADORA CON MARTILLO | C39: u | D39: 550000 | E39: PABLO | F39: 45743
A40: MS-MR | B40: MINIRETRO EXCAVADORA | C40: u | D40: 550000 | E40: PABLO | F40: 45743
A41: MS-T | B41: TRASLADO DE MAQUINARIA | C41: u | D41: 300000 | E41: PABLO | F41: 45743
...

Sheet 00_JEF + ESTR
A1: JEFATURA DE OBRA (mes)
A3: Jefatura de Obra | B3: =SUM(B4:B5) -> 2500000
A4: Jorge | B4: -
A5: Jefe de Obra | B5: 2500000
A6: Gastos Estructura | B6: =SUM(B7:B10) -> 3400000
A7: Nafta Jefe de Obra | B7: 500000
A8: Nafta Jorge | B8: 500000
A9: Guille | B9: 400000
A10: Herramientas | B10: 2000000
D11: MESES | E11: G.E. + J.d. O TOTAL
B12: =SUM(B6+B3) -> 5900000 | D12: ='01_C&P'!D9 -> 16 | E12: =(D12*B12) -> 94400000

Sheet 01_C&P
A1: EDIFICIO LAS HERAS
A3: PLANILLA COMPUTO Y PRESPUPUESTO
A5: ITEM | B5: DESCRIPCIÓN | C5: UNIDAD | D5: CANTIDAD | E5: SUBTOTAL 01: GASTOS DIRECTOS | O5: SUBTOTAL 02: GASTOS INDIRECTOS | R5: SUBTOTAL 03: BENEFICIOS | U5: TOTAL (NETO)
E6: V.UNITARIO | L6: V.GENERAL | O6: V. GENERAL | R6: V. GENERAL | U6: V. UNITARIO | X6: V.GENERAL
E7: MAT. | F7: M.O.: JORNALES | G7: M.O.: EQUIPOS | H7: M.O.: MATERIALES | I7: M.O.: SUBCONTRATOS | J7: M.O. | K7: GENERAL | L7: MAT. | M7: M.O | N7: GENERAL | O7: MAT. | P7: M.O. | Q7: GENERAL | R7: MAT. | S7: M.O. | T7: GENERAL | U7: MAT. | V7: M.O | W7: GENERAL | X7: MAT. | Y7: M.O | Z7: GENERAL
A8: 1- TAREAS PRELIMINARES
A9: 0.1 | B9: OBRADOR | C9: mes | D9: 16 | I9: 700000 | J9: =SUM(F9:I9) -> 700000 | K9: =SUM(E9,J9) -> 700000 | L9: =$D9*E9 -> 0 | M9: =$D9*(SUM(F9:I9)) -> 11200000 | N9: =L9+M9 -> 11200000 | O9: =L9 -> 0 | P9: =(P$130*M9)/M$130 -> 12790400 | Q9: =O9+P9 -> 12790400 | R9: =L9 -> 0 | S9: =(S$130*P9)/P$130 -> 15988000 | T9: =R9+S9 -> 15988000 | U9: =E9 | V9: =Y9/D9 -> 1081188.5 | W9: =U9+V9 -> 1081188.5 | X9: =L9 -> 0 | Y9: =(Y$130*S9)/S$130 -> 17299016 | Z9: =X9+Y9 -> 17299016
A10: 0.2 | B10: BANOS QUIMICOS (2) | C10: mes | D10: =D9 -> 16 | I10: 240000 | J10: =SUM(F10:I10) -> 240000 | K10: =SUM(E10,J10) -> 240000 | L10: =$D10*E10 -> 0 | M10: =$D10*(SUM(F10:I10)) -> 3840000 | N10: =L10+M10 -> 3840000 | O10: =L10 -> 0 | P10: =(P$130*M10)/M$130 -> 4385280 | Q10: =O10+P10 -> 4385280 | R10: =L10 -> 0 | S10: =(S$130*P10)/P$130 -> 5481600 | T10: =R10+S10 -> 5481600 | U10: =E10 | V10: =Y10/D10 -> 370693.2 | W10: =U10+V10 -> 370693.2 | X10: =L10 -> 0 | Y10: =(Y$130*S10)/S$130 -> 5931091.2 | Z10: =X10+Y10 -> 5931091.2
A11: 0.3 | B11: INSTALACIONES PROVISORIAS | C11: gl | D11: 1 | I11: 5000000 | J11: =SUM(F11:I11) -> 5000000 | K11: =SUM(E11,J11) -> 5000000 | L11: =$D11*E11 -> 0 | M11: =$D11*(SUM(F11:I11)) -> 5000000 | N11: =L11+M11 -> 5000000 | O11: =L11 -> 0 | P11: =(P$130*M11)/M$130 -> 5710000 | Q11: =O11+P11 -> 5710000 | R11: =L11 -> 0 | S11: =(S$130*P11)/P$130 -> 7137500 | T11: =R11+S11 -> 7137500 | U11: =E11 | V11: =Y11/D11 -> 7722775 | W11: =U11+V11 -> 7722775 | X11: =L11 -> 0 | Y11: =(Y$130*S11)/S$130 -> 7722775 | Z11: =X11+Y11 -> 7722775
A12: 0.4 | B12: LIMPIEZA PERIODICA DE OBRA | C12: mes | D12: =D9 -> 16 | I12: 1000000 | J12: =SUM(F12:I12) -> 1000000 | K12: =SUM(E12,J12) -> 1000000 | L12: =$D12*E12 -> 0 | M12: =$D12*(SUM(F12:I12)) -> 16000000 | N12: =L12+M12 -> 16000000 | O12: =L12 -> 0 | P12: =(P$130*M12)/M$130 -> 18272000 | Q12: =O12+P12 -> 18272000 | R12: =L12 -> 0 | S12: =(S$130*P12)/P$130 -> 22840000 | T12: =R12+S12 -> 22840000 | U12: =E12 | V12: =Y12/D12 -> 1544555 | W12: =U12+V12 -> 1544555 | X12: =L12 -> 0 | Y12: =(Y$130*S12)/S$130 -> 24712880 | Z12: =X12+Y12 -> 24712880
A13: 0.5 | B13: ACARREO DE MATERIALES | C13: mes | D13: =D9 -> 16 | I13: 1000000 | J13: =SUM(F13:I13) -> 1000000 | K13: =SUM(E13,J13) -> 1000000 | L13: =$D13*E13 -> 0 | M13: =$D13*(SUM(F13:I13)) -> 16000000 | N13: =L13+M13 -> 16000000 | O13: =L13 -> 0 | P13: =(P$130*M13)/M$130 -> 18272000 | Q13: =O13+P13 -> 18272000 | R13: =L13 -> 0 | S13: =(S$130*P13)/P$130 -> 22840000 | T13: =R13+S13 -> 22840000 | U13: =E13 | V13: =Y13/D13 -> 1544555 | W13: =U13+V13 -> 1544555 | X13: =L13 -> 0 | Y13: =(Y$130*S13)/S$130 -> 24712880 | Z13: =X13+Y13 -> 24712880
A14: 0.6 | B14: AYUDA DE GREMIOS | C14: mes | D14: =D9 -> 16 | I14: 3000000 | J14: =SUM(F14:I14) -> 3000000 | K14: =SUM(E14,J14) -> 3000000 | L14: =$D14*E14 -> 0 | M14: =$D14*(SUM(F14:I14)) -> 48000000 | N14: =L14+M14 -> 48000000 | O14: =L14 -> 0 | P14: =(P$130*M14)/M$130 -> 54816000 | Q14: =O14+P14 -> 54816000 | R14: =L14 -> 0 | S14: =(S$130*P14)/P$130 -> 68520000 | T14: =R14+S14 -> 68520000 | U14: =E14 | V14: =Y14/D14 -> 4633665 | W14: =U14+V14 -> 4633665 | X14: =L14 -> 0 | Y14: =(Y$130*S14)/S$130 -> 74138640 | Z14: =X14+Y14 -> 74138640
A15: 0.7 | B15: LIMPIEZA FINAL | C15: gl | D15: 1 | I15: 2000000 | J15: =SUM(F15:I15) -> 2000000 | K15: =SUM(E15,J15) -> 2000000 | L15: =$D15*E15 -> 0 | M15: =$D15*(SUM(F15:I15)) -> 2000000 | N15: =L15+M15 -> 2000000 | O15: =L15 -> 0 | P15: =(P$130*M15)/M$130 -> 2284000 | Q15: =O15+P15 -> 2284000 | R15: =L15 -> 0 | S15: =(S$130*P15)/P$130 -> 2855000 | T15: =R15+S15 -> 2855000 | U15: =E15 | V15: =Y15/D15 -> 3089110 | W15: =U15+V15 -> 3089110 | X15: =L15 -> 0 | Y15: =(Y$130*S15)/S$130 -> 3089110 | Z15: =X15+Y15 -> 3089110
A16: 0.8 | B16: ESTRUCTURA DE ENCOFRADO Y APUNTALAMIENTO PROVISORIO | C16: gl | D16: 1 | G16: =ESTRUCTURA!I50 -> 129142648 | J16: =SUM(F16:I16) -> 129142648 | K16: =SUM(E16,J16) -> 129142648 | L16: =$D16*E16 -> 0 | M16: =$D16*(SUM(F16:I16)) -> 129142648 | N16: =L16+M16 -> 129142648 | O16: =L16 -> 0 | P16: =(P$130*M16)/M$130 -> 147480904 | Q16: =O16+P16 -> 147480904 | R16: =L16 -> 0 | S16: =(S$130*P16)/P$130 -> 184351130 | T16: =R16+S16 -> 184351130 | U16: =E16 | V16: =Y16/D16 -> 1.9946792e+08 | W16: =U16+V16 -> 1.9946792e+08 | X16: =L16 -> 0 | Y16: =(Y$130*S16)/S$130 -> 1.9946792e+08 | Z16: =X16+Y16 -> 1.9946792e+08
A17: EXCAVACION
A18: 0.9 | B18: EXCAVACION BASES Y TRONCOS | C18: m³ | D18: =172*2.13 -> 366.36 | E18: ='0.9'!$I$22 -> 0 | F18: ='0.9'!$I$36 -> 0 | G18: ='0.9'!$I$50 -> 37504.094 | H18: ='0.9'!$I$64 -> 0 | I18: ='0.9'!$I$78 -> 0 | J18: =SUM(F18:I18) -> 37504.094 | K18: =SUM(E18,J18) -> 37504.094 | L18: =$D18*E18 -> 0 | M18: =$D18*(SUM(F18:I18)) -> 13740000 | N18: =L18+M18 -> 13740000 | O18: =L18 -> 0 | P18: =(P$130*M18)/M$130 -> 15691080 | Q18: =O18+P18 -> 15691080 | R18: =L18 -> 0 | S18: =(S$130*P18)/P$130 -> 19613850 | T18: =R18+S18 -> 19613850 | U18: =E18 -> 0 | V18: =Y18/D18 -> 57927.136 | W18: =U18+V18 -> 57927.136 | X18: =L18 -> 0 | Y18: =(Y$130*S18)/S$130 -> 21222186 | Z18: =X18+Y18 -> 21222186
A19: 0.10 | B19: EXCAVACION TENSORES | C19: m³ | D19: =(45*0.4)*0.3 -> 5.4 | E19: ='0.10'!$I$22 -> 0 | F19: ='0.10'!$I$36 -> 0 | G19: ='0.10'!$I$50 -> 50000 | H19: ='0.10'!$I$64 -> 0 | I19: ='0.10'!$I$78 -> 0 | J19: =SUM(F19:I19) -> 50000 | K19: =SUM(E19,J19) -> 50000 | L19: =$D19*E19 -> 0 | M19: =$D19*(SUM(F19:I19)) -> 270000 | N19: =L19+M19 -> 270000 | O19: =L19 -> 0 | P19: =(P$130*M19)/M$130 -> 308340 | Q19: =O19+P19 -> 308340 | R19: =L19 -> 0 | S19: =(S$130*P19)/P$130 -> 385425 | T19: =R19+S19 -> 385425 | U19: =E19 -> 0 | V19: =Y19/D19 -> 77227.75 | W19: =U19+V19 -> 77227.75 | X19: =L19 -> 0 | Y19: =(Y$130*S19)/S$130 -> 417029.85 | Z19: =X19+Y19 -> 417029.85
A20: 0.11 | B20: EXCAVACION TRONERAS | C20: m³ | D20: =6*46 -> 276 | E20: ='0.11'!$I$22 -> 0 | F20: ='0.11'!$I$36 -> 0 | G20: ='0.11'!$I$50 -> 37500 | H20: ='0.11'!$I$64 -> 0 | I20: ='0.11'!$I$78 -> 0 | J20: =SUM(F20:I20) -> 37500 | K20: =SUM(E20,J20) -> 37500 | L20: =$D20*E20 -> 0 | M20: =$D20*(SUM(F20:I20)) -> 10350000 | N20: =L20+M20 -> 10350000 | O20: =L20 -> 0 | P20: =(P$130*M20)/M$130 -> 11819700 | Q20: =O20+P20 -> 11819700 | R20: =L20 -> 0 | S20: =(S$130*P20)/P$130 -> 14774625 | T20: =R20+S20 -> 14774625 | U20: =E20 -> 0 | V20: =Y20/D20 -> 57920.812 | W20: =U20+V20 -> 57920.812 | X20: =L20 -> 0 | Y20: =(Y$130*S20)/S$130 -> 15986144 | Z20: =X20+Y20 -> 15986144
A21: OBRA GRIS - FUNDACIONES
A22: 0.12 | B22: BASES | C22: m³ | D22: 108 | E22: ='0.12'!$I$22 -> 264204.49 | F22: ='0.12'!$I$36 -> 65000 | G22: ='0.12'!$I$50 -> 0 | H22: ='0.12'!$I$64 -> 6111.1111 | I22: ='0.12'!$I$78 -> 0 | J22: =SUM(F22:I22) -> 71111.111 | K22: =SUM(E22,J22) -> 335315.6 | L22: =$D22*E22 -> 28534084 | M22: =$D22*(SUM(F22:I22)) -> 7680000 | N22: =L22+M22 -> 36214084 | O22: =L22 -> 28534084 | P22: =(P$130*M22)/M$130 -> 8770560 | Q22: =O22+P22 -> 37304644 | R22: =L22 -> 28534084 | S22: =(S$130*P22)/P$130 -> 10963200 | T22: =R22+S22 -> 39497284 | U22: =E22 -> 264204.49 | V22: =Y22/D22 -> 109835.02 | W22: =U22+V22 -> 374039.51 | X22: =L22 -> 28534084 | Y22: =(Y$130*S22)/S$130 -> 11862182 | Z22: =X22+Y22 -> 40396267
A23: 0.13 | B23: TRONCOS | C23: m³ | D23: 20 | E23: ='0.13'!$I$22 -> 290615.56 | F23: ='0.13'!$I$36 -> 351000 | G23: ='0.13'!$I$50 -> 0 | H23: ='0.13'!$I$64 -> 13475 | I23: ='0.13'!$I$78 -> 0 | J23: =SUM(F23:I23) -> 364475 | K23: =SUM(E23,J23) -> 655090.56 | L23: =$D23*E23 -> 5812311.3 | M23: =$D23*(SUM(F23:I23)) -> 7289500 | N23: =L23+M23 -> 13101811 | O23: =L23 -> 5812311.3 | P23: =(P$130*M23)/M$130 -> 8324609 | Q23: =O23+P23 -> 14136920 | R23: =L23 -> 5812311.3 | S23: =(S$130*P23)/P$130 -> 10405761 | T23: =R23+S23 -> 16218073 | U23: =E23 -> 290615.56 | V23: =Y23/D23 -> 562951.68 | W23: =U23+V23 -> 853567.25 | X23: =L23 -> 5812311.3 | Y23: =(Y$130*S23)/S$130 -> 11259034 | Z23: =X23+Y23 -> 17071345
A24: 0.14 | B24: TENSORES | C24: m³ | D24: =D19 -> 5.4 | E24: ='0.14'!$I$22 -> 389379.44 | F24: ='0.14'!$I$36 -> 386111.11 | G24: ='0.14'!$I$50 -> 0 | H24: ='0.14'!$I$64 -> 0 | I24: ='0.14'!$I$78 -> 0 | J24: =SUM(F24:I24) -> 386111.11 | K24: =SUM(E24,J24) -> 775490.56 | L24: =$D24*E24 -> 2102649 | M24: =$D24*(SUM(F24:I24)) -> 2085000 | N24: =L24+M24 -> 4187649 | O24: =L24 -> 2102649 | P24: =(P$130*M24)/M$130 -> 2381070 | Q24: =O24+P24 -> 4483719 | R24: =L24 -> 2102649 | S24: =(S$130*P24)/P$130 -> 2976337.5 | T24: =R24+S24 -> 5078986.5 | U24: =E24 -> 389379.44 | V24: =Y24/D24 -> 596369.85 | W24: =U24+V24 -> 985749.29 | X24: =L24 -> 2102649 | Y24: =(Y$130*S24)/S$130 -> 3220397.2 | Z24: =X24+Y24 -> 5323046.2
A25: 0.15 | B25: TABIQUES DE SUBMURACION | C25: m³ | D25: =95*3*0.15 -> 42.75 | E25: ='0.15'!$I$22 -> 442353.68 | F25: ='0.15'!$I$36 -> 369239.77 | G25: ='0.15'!$I$50 -> 0 | H25: ='0.15'!$I$64 -> 5146.1988 | I25: ='0.15'!$I$78 -> 0 | J25: =SUM(F25:I25) -> 374385.96 | K25: =SUM(E25,J25) -> 816739.65 | L25: =$D25*E25 -> 18910620 | M25: =$D25*(SUM(F25:I25)) -> 16005000 | N25: =L25+M25 -> 34915620 | O25: =L25 -> 18910620 | P25: =(P$130*M25)/M$130 -> 18277710 | Q25: =O25+P25 -> 37188330 | R25: =L25 -> 18910620 | S25: =(S$130*P25)/P$130 -> 22847138 | T25: =R25+S25 -> 41757758 | U25: =E25 -> 442353.68 | V25: =Y25/D25 -> 578259.71 | W25: =U25+V25 -> 1020613.4 | X25: =L25 -> 18910620 | Y25: =(Y$130*S25)/S$130 -> 24720603 | Z25: =X25+Y25 -> 43631223
A26: OBRA GRIS - SOBRE SUBSUELO
A27: 36892 | B27: COLUMNAS Y TABIQUES | C27: m³ | D27: 23 | E27: ='1.1'!$I$22 -> 548114.34 | F27: ='1.1'!$I$36 -> 599347.83 | G27: ='1.1'!$I$50 -> 0 | H27: ='1.1'!$I$64 -> 13869.565 | I27: ='1.1'!$I$78 -> 0 | J27: =SUM(F27:I27) -> 613217.39 | K27: =SUM(E27,J27) -> 1161331.7 | L27: =$D27*E27 -> 12606630 | M27: =$D27*(SUM(F27:I27)) -> 14104000 | N27: =L27+M27 -> 26710630 | O27: =L27 -> 12606630 | P27: =(P$130*M27)/M$130 -> 16106768 | Q27: =O27+P27 -> 28713398 | R27: =L27 -> 12606630 | S27: =(S$130*P27)/P$130 -> 20133460 | T27: =R27+S27 -> 32740090 | U27: =E27 -> 548114.34 | V27: =Y27/D27 -> 947147.99 | W27: =U27+V27 -> 1495262.3 | X27: =L27 -> 12606630 | Y27: =(Y$130*S27)/S$130 -> 21784404 | Z27: =X27+Y27 -> 34391034
A28: 46054 | B28: VIGAS | C28: m³ | D28: 16 | E28: ='1.2'!$I$22 -> 539468.37 | F28: ='1.2'!$I$36 -> 861562.5 | G28: ='1.2'!$I$50 -> 0 | H28: ='1.2'!$I$64 -> 19937.5 | I28: ='1.2'!$I$78 -> 0 | J28: =SUM(F28:I28) -> 881500 | K28: =SUM(E28,J28) -> 1420968.4 | L28: =$D28*E28 -> 8631493.9 | M28: =$D28*(SUM(F28:I28)) -> 14104000 | N28: =L28+M28 -> 22735494 | O28: =L28 -> 8631493.9 | P28: =(P$130*M28)/M$130 -> 16106768 | Q28: =O28+P28 -> 24738262 | R28: =L28 -> 8631493.9 | S28: =(S$130*P28)/P$130 -> 20133460 | T28: =R28+S28 -> 28764954 | U28: =E28 -> 539468.37 | V28: =Y28/D28 -> 1361525.2 | W28: =U28+V28 -> 1900993.6 | X28: =L28 -> 8631493.9 | Y28: =(Y$130*S28)/S$130 -> 21784404 | Z28: =X28+Y28 -> 30415898
A29: 46082 | B29: LOSA | C29: m³ | D29: =54+3 -> 57 | E29: ='1.3'!$I$22 -> 362272.74 | F29: ='1.3'!$I$36 -> 342105.26 | G29: ='1.3'!$I$50 -> 0 | H29: ='1.3'!$I$64 -> 8587.7193 | I29: ='1.3'!$I$78 -> 0 | J29: =SUM(F29:I29) -> 350692.98 | K29: =SUM(E29,J29) -> 712965.72 | L29: =$D29*E29 -> 20649546 | M29: =$D29*(SUM(F29:I29)) -> 19989500 | N29: =L29+M29 -> 40639046 | O29: =L29 -> 20649546 | P29: =(P$130*M29)/M$130 -> 22828009 | Q29: =O29+P29 -> 43477555 | R29: =L29 -> 20649546 | S29: =(S$130*P29)/P$130 -> 28535011 | T29: =R29+S29 -> 49184557 | U29: =E29 -> 362272.74 | V29: =Y29/D29 -> 541664.6 | W29: =U29+V29 -> 903937.34 | X29: =L29 -> 20649546 | Y29: =(Y$130*S29)/S$130 -> 30874882 | Z29: =X29+Y29 -> 51524428
A30: 1.31 | B30: LOSA DE SUPRESION SOBRE SUELO COMPACTADO. e=10cm. | C30: m³ | D30: =390*0.1 -> 39 | E30: ='1.31'!$I$22 -> 218369.72 | F30: ='1.31'!$I$36 -> 129615.38 | G30: ='1.31'!$I$50 -> 0 | H30: ='1.31'!$I$64 -> 0 | I30: ='1.31'!$I$78 -> 0 | J30: =SUM(F30:I30) -> 129615.38 | K30: =SUM(E30,J30) -> 347985.1 | L30: =$D30*E30 -> 8516419 | M30: =$D30*(SUM(F30:I30)) -> 5055000 | N30: =L30+M30 -> 13571419 | O30: =L30 -> 8516419 | P30: =(P$130*M30)/M$130 -> 5772810 | Q30: =O30+P30 -> 14289229 | R30: =L30 -> 8516419 | S30: =(S$130*P30)/P$130 -> 7216012.5 | T30: =R30+S30 -> 15732432 | U30: =E30 -> 218369.72 | V30: =Y30/D30 -> 200198.09 | W30: =U30+V30 -> 418567.81 | X30: =L30 -> 8516419 | Y30: =(Y$130*S30)/S$130 -> 7807725.5 | Z30: =X30+Y30 -> 16324145
A31: 1.32 | B31: PAVIMENTO ALISADO EN ESTACIONAMIENTO. e=10cm | C31: m² | D31: 310 | E31: ='1.32'!$I$22 -> 25336.66 | F31: ='1.32'!$I$36 -> 3725.8065 | G31: ='1.32'!$I$50 -> 0 | H31: ='1.32'!$I$64 -> 0 | I31: ='1.32'!$I$78 -> 12516.129 | J31: =SUM(F31:I31) -> 16241.935 | K31: =SUM(E31,J31) -> 41578.595 | L31: =$D31*E31 -> 7854364.5 | M31: =$D31*(SUM(F31:I31)) -> 5035000 | N31: =L31+M31 -> 12889364 | O31: =L31 -> 7854364.5 | P31: =(P$130*M31)/M$130 -> 5749970 | Q31: =O31+P31 -> 13604334 | R31: =L31 -> 7854364.5 | S31: =(S$130*P31)/P$130 -> 7187462.5 | T31: =R31+S31 -> 15041827 | U31: =E31 -> 25336.66 | V31: =Y31/D31 -> 25086.563 | W31: =U31+V31 -> 50423.222 | X31: =L31 -> 7854364.5 | Y31: =(Y$130*S31)/S$130 -> 7776834.4 | Z31: =X31+Y31 -> 15631199
A32: 46113 | B32: MAMPOSTERIA. | C32: m² | D32: =120*3 -> 360 | E32: ='1.4'!$I$22 -> 28937.371 | F32: ='1.4'!$I$36 -> 16625 | G32: ='1.4'!$I$50 -> 0 | H32: ='1.4'!$I$64 -> 222.22222 | I32: ='1.4'!$I$78 -> 0 | J32: =SUM(F32:I32) -> 16847.222 | K32: =SUM(E32,J32) -> 45784.593 | L32: =$D32*E32 -> 10417454 | M32: =$D32*(SUM(F32:I32)) -> 6065000 | N32: =L32+M32 -> 16482454 | O32: =L32 -> 10417454 | P32: =(P$130*M32)/M$130 -> 6926230 | Q32: =O32+P32 -> 17343684 | R32: =L32 -> 10417454 | S32: =(S$130*P32)/P$130 -> 8657787.5 | T32: =R32+S32 -> 19075241 | U32: =E32 -> 28937.371 | V32: =Y32/D32 -> 26021.461 | W32: =U32+V32 -> 54958.832 | X32: =L32 -> 10417454 | Y32: =(Y$130*S32)/S$130 -> 9367726.1 | Z32: =X32+Y32 -> 19785180
A33: 46143 | B33: CONTRAPISO . e=12cm | C33: m² | D33: 80 | E33: ='1.5'!$I$22 -> 18664.73 | F33: ='1.5'!$I$36 -> 14437.5 | G33: ='1.5'!$I$50 -> 0 | H33: ='1.5'!$I$64 -> 0 | I33: ='1.5'!$I$78 -> 15000 | J33: =SUM(F33:I33) -> 29437.5 | K33: =SUM(E33,J33) -> 48102.23 | L33: =$D33*E33 -> 1493178.4 | M33: =$D33*(SUM(F33:I33)) -> 2355000 | N33: =L33+M33 -> 3848178.4 | O33: =L33 -> 1493178.4 | P33: =(P$130*M33)/M$130 -> 2689410 | Q33: =O33+P33 -> 4182588.4 | R33: =L33 -> 1493178.4 | S33: =(S$130*P33)/P$130 -> 3361762.5 | T33: =R33+S33 -> 4854940.9 | U33: =E33 -> 18664.73 | V33: =Y33/D33 -> 45467.838 | W33: =U33+V33 -> 64132.568 | X33: =L33 -> 1493178.4 | Y33: =(Y$130*S33)/S$130 -> 3637427 | Z33: =X33+Y33 -> 5130605.5
A34: 46174 | B34: CARPETA . e=3cm | C34: m² | D34: =D33 -> 80 | E34: ='1.6'!$I$22 -> 5017.625 | F34: ='1.6'!$I$36 -> 17625 | G34: ='1.6'!$I$50 -> 0 | H34: ='1.6'!$I$64 -> 0 | I34: ='1.6'!$I$78 -> 0 | J34: =SUM(F34:I34) -> 17625 | K34: =SUM(E34,J34) -> 22642.625 | L34: =$D34*E34 -> 401410 | M34: =$D34*(SUM(F34:I34)) -> 1410000 | N34: =L34+M34 -> 1811410 | O34: =L34 -> 401410 | P34: =(P$130*M34)/M$130 -> 1610220 | Q34: =O34+P34 -> 2011630 | R34: =L34 -> 401410 | S34: =(S$130*P34)/P$130 -> 2012775 | T34: =R34+S34 -> 2414185 | U34: =E34 -> 5017.625 | V34: =Y34/D34 -> 27222.782 | W34: =U34+V34 -> 32240.407 | X34: =L34 -> 401410 | Y34: =(Y$130*S34)/S$130 -> 2177822.5 | Z34: =X34+Y34 -> 2579232.5
A35: 46204 | B35: REVOQUE INTERIOR. (GRUESO FRATAZADO) | C35: m² | D35: =30*3*2 -> 180 | E35: ='1.7'!$I$22 -> 2871.4118 | F35: ='1.7'!$I$36 -> 26000 | G35: ='1.7'!$I$50 -> 0 | H35: ='1.7'!$I$64 -> 0 | I35: ='1.7'!$I$78 -> 0 | J35: =SUM(F35:I35) -> 26000 | K35: =SUM(E35,J35) -> 28871.412 | L35: =$D35*E35 -> 516854.13 | M35: =$D35*(SUM(F35:I35)) -> 4680000 | N35: =L35+M35 -> 5196854.1 | O35: =L35 -> 516854.13 | P35: =(P$130*M35)/M$130 -> 5344560 | Q35: =O35+P35 -> 5861414.1 | R35: =L35 -> 516854.13 | S35: =(S$130*P35)/P$130 -> 6680700 | T35: =R35+S35 -> 7197554.1 | U35: =E35 -> 2871.4118 | V35: =Y35/D35 -> 40158.43 | W35: =U35+V35 -> 43029.842 | X35: =L35 -> 516854.13 | Y35: =(Y$130*S35)/S$130 -> 7228517.4 | Z35: =X35+Y35 -> 7745371.5
A36: 46235 | B36: REVOQUE INTERTIOR HIDROFUGO. | C36: m² | D36: =94*3*1 -> 282 | E36: ='1.8'!$I$22 -> 3811.6746 | F36: ='1.8'!$I$36 -> 35053.191 | G36: ='1.8'!$I$50 -> 0 | H36: ='1.8'!$I$64 -> 0 | I36: ='1.8'!$I$78 -> 0 | J36: =SUM(F36:I36) -> 35053.191 | K36: =SUM(E36,J36) -> 38864.866 | L36: =$D36*E36 -> 1074892.2 | M36: =$D36*(SUM(F36:I36)) -> 9885000 | N36: =L36+M36 -> 10959892 | O36: =L36 -> 1074892.2 | P36: =(P$130*M36)/M$130 -> 11288670 | Q36: =O36+P36 -> 12363562 | R36: =L36 -> 1074892.2 | S36: =(S$130*P36)/P$130 -> 14110838 | T36: =R36+S36 -> 15185730 | U36: =E36 -> 3811.6746 | V36: =Y36/D36 -> 54141.582 | W36: =U36+V36 -> 57953.257 | X36: =L36 -> 1074892.2 | Y36: =(Y$130*S36)/S$130 -> 15267926 | Z36: =X36+Y36 -> 16342818
A37: OBRA GRIS - SOBRE PLANTA BAJA
A38: 45293 | B38: COLUMNAS Y TABIQUES | C38: m³ | D38: 31 | E38: ='2.1.'!I22 -> 537748.84 | F38: ='2.1.'!I36 -> 377419.35 | G38: ='2.1.'!I50 -> 0 | H38: ='2.1.'!I64 -> 15790.323 | I38: ='2.1.'!I78 -> 0 | J38: =SUM(F38:I38) -> 393209.68 | K38: =SUM(E38,J38) -> 930958.52 | L38: =$D38*E38 -> 16670214 | M38: =$D38*(SUM(F38:I38)) -> 12189500 | N38: =L38+M38 -> 28859714 | O38: =L38 -> 16670214 | P38: =(P$130*M38)/M$130 -> 13920409 | Q38: =O38+P38 -> 30590623 | R38: =L38 -> 16670214 | S38: =(S$130*P38)/P$130 -> 17400511 | T38: =R38+S38 -> 34070725 | U38: =E38 -> 537748.84 | V38: =Y38/D38 -> 607333.97 | W38: =U38+V38 -> 1145082.8 | X38: =L38 -> 16670214 | Y38: =(Y$130*S38)/S$130 -> 18827353 | Z38: =X38+Y38 -> 35497567
A39: n | B39: VIGAS | C39: m³ | D39: 14 | E39: ='2.2.'!I22 -> 559896.94 | F39: ='2.2.'!I36 -> 835714.29 | G39: ='2.2.'!I50 -> 0 | H39: ='2.2.'!I64 -> 19250 | I39: ='2.2.'!I78 -> 0 | J39: =SUM(F39:I39) -> 854964.29 | K39: =SUM(E39,J39) -> 1414861.2 | L39: =$D39*E39 -> 7838557.2 | M39: =$D39*(SUM(F39:I39)) -> 11969500 | N39: =L39+M39 -> 19808057 | O39: =L39 -> 7838557.2 | P39: =(P$130*M39)/M$130 -> 13669169 | Q39: =O39+P39 -> 21507726 | R39: =L39 -> 7838557.2 | S39: =(S$130*P39)/P$130 -> 17086461 | T39: =R39+S39 -> 24925018 | U39: =E39 -> 559896.94 | V39: =Y39/D39 -> 1320539.4 | W39: =U39+V39 -> 1880436.3 | X39: =L39 -> 7838557.2 | Y39: =(Y$130*S39)/S$130 -> 18487551 | Z39: =X39+Y39 -> 26326108
A40: 45353 | B40: LOSA | C40: m³ | D40: =23+3 -> 26 | E40: ='2.3'!I22 -> 417771.5 | F40: ='2.3'!I36 -> 570000 | G40: ='2.3'!I50 -> 0 | H40: ='2.3'!I64 -> 10365.385 | I40: ='2.3'!I78 -> 0 | J40: =SUM(F40:I40) -> 580365.38 | K40: =SUM(E40,J40) -> 998136.88 | L40: =$D40*E40 -> 10862059 | M40: =$D40*(SUM(F40:I40)) -> 15089500 | N40: =L40+M40 -> 25951559 | O40: =L40 -> 10862059 | P40: =(P$130*M40)/M$130 -> 17232209 | Q40: =O40+P40 -> 28094268 | R40: =L40 -> 10862059 | S40: =(S$130*P40)/P$130 -> 21540261 | T40: =R40+S40 -> 32402320 | U40: =E40 -> 417771.5 | V40: =Y40/D40 -> 896406.26 | W40: =U40+V40 -> 1314177.8 | X40: =L40 -> 10862059 | Y40: =(Y$130*S40)/S$130 -> 23306563 | Z40: =X40+Y40 -> 34168622
A41: 46114 | B41: MAMPOSTERIA. | C41: m² | D41: =85*4 -> 340 | E41: ='2.4'!I22 -> 28748.294 | F41: ='2.4'!I36 -> 17161.765 | G41: ='2.4'!I50 -> 0 | H41: ='2.4'!I64 -> 235.29412 | I41: ='2.4'!I78 -> 0 | J41: =SUM(F41:I41) -> 17397.059 | K41: =SUM(E41,J41) -> 46145.353 | L41: =$D41*E41 -> 9774420.1 | M41: =$D41*(SUM(F41:I41)) -> 5915000 | N41: =L41+M41 -> 15689420 | O41: =L41 -> 9774420.1 | P41: =(P$130*M41)/M$130 -> 6754930 | Q41: =O41+P41 -> 16529350 | R41: =L41 -> 9774420.1 | S41: =(S$130*P41)/P$130 -> 8443662.5 | T41: =R41+S41 -> 18218083 | U41: =E41 -> 28748.294 | V41: =Y41/D41 -> 26870.714 | W41: =U41+V41 -> 55619.009 | X41: =L41 -> 9774420.1 | Y41: =(Y$130*S41)/S$130 -> 9136042.8 | Z41: =X41+Y41 -> 18910463
A42: 46144 | B42: CONTRAPISO INTERIOR . e=12cm | C42: m² | D42: =144 -> 144 | E42: ='2.5'!I22 -> 20997.164 | F42: ='2.5'!I36 -> 8020.8333 | G42: ='2.5'!I50 -> 0 | H42: ='2.5'!I64 -> 0 | I42: ='2.5'!I78 -> 15000 | J42: =SUM(F42:I42) -> 23020.833 | K42: =SUM(E42,J42) -> 44017.997 | L42: =$D42*E42 -> 3023591.6 | M42: =$D42*(SUM(F42:I42)) -> 3315000 | N42: =L42+M42 -> 6338591.6 | O42: =L42 -> 3023591.6 | P42: =(P$130*M42)/M$130 -> 3785730 | Q42: =O42+P42 -> 6809321.6 | R42: =L42 -> 3023591.6 | S42: =(S$130*P42)/P$130 -> 4732162.5 | T42: =R42+S42 -> 7755754.1 | U42: =E42 -> 20997.164 | V42: =Y42/D42 -> 35556.943 | W42: =U42+V42 -> 56554.107 | X42: =L42 -> 3023591.6 | Y42: =(Y$130*S42)/S$130 -> 5120199.8 | Z42: =X42+Y42 -> 8143791.4
...

Sheet 01_VENTA
A1: EDIFICIO LAS HERAS
A3: Pilar, 04 de Marzo de 2026.
A5: PLANILLA COMPUTO Y PRESPUPUESTO
A7: ITEM | B7: DESCRIPCIÓN | C7: UNIDAD | D7: CANTIDAD | E7: TOTAL (NETO)
E8: V. UNITARIO | H8: V.GENERAL
E9: MAT. | F9: M.O | G9: GENERAL | H9: MAT. | I9: M.O | J9: GENERAL
A10: 1- TAREAS PRELIMINARES
A11: ='01_C&P'!A9 -> 0.1 | B11: ='01_C&P'!B9 -> OBRADOR | C11: ='01_C&P'!C9 -> mes | D11: ='01_C&P'!D9 -> 16 | E11: ='01_C&P'!U9 | F11: ='01_C&P'!V9 -> 1081188.5 | G11: ='01_C&P'!W9 -> 1081188.5 | H11: ='01_C&P'!X9 -> 0 | I11: ='01_C&P'!Y9 -> 17299016 | J11: =H11+I11 -> 17299016
A12: ='01_C&P'!A10 -> 0.2 | B12: ='01_C&P'!B10 -> BANOS QUIMICOS (2) | C12: ='01_C&P'!C10 -> mes | D12: ='01_C&P'!D10 -> 16 | E12: ='01_C&P'!U10 | F12: ='01_C&P'!V10 -> 370693.2 | G12: ='01_C&P'!W10 -> 370693.2 | H12: ='01_C&P'!X10 -> 0 | I12: ='01_C&P'!Y10 -> 5931091.2 | J12: =H12+I12 -> 5931091.2
A13: ='01_C&P'!A11 -> 0.3 | B13: ='01_C&P'!B11 -> INSTALACIONES PROVISORIAS | C13: ='01_C&P'!C11 -> gl | D13: ='01_C&P'!D11 -> 1 | E13: ='01_C&P'!U11 | F13: ='01_C&P'!V11 -> 7722775 | G13: ='01_C&P'!W11 -> 7722775 | H13: ='01_C&P'!X11 -> 0 | I13: ='01_C&P'!Y11 -> 7722775 | J13: =H13+I13 -> 7722775
A14: ='01_C&P'!A12 -> 0.4 | B14: ='01_C&P'!B12 -> LIMPIEZA PERIODICA DE OBRA | C14: ='01_C&P'!C12 -> mes | D14: ='01_C&P'!D12 -> 16 | E14: ='01_C&P'!U12 | F14: ='01_C&P'!V12 -> 1544555 | G14: ='01_C&P'!W12 -> 1544555 | H14: ='01_C&P'!X12 -> 0 | I14: ='01_C&P'!Y12 -> 24712880 | J14: =H14+I14 -> 24712880
A15: ='01_C&P'!A13 -> 0.5 | B15: ='01_C&P'!B13 -> ACARREO DE MATERIALES | C15: ='01_C&P'!C13 -> mes | D15: ='01_C&P'!D13 -> 16 | E15: ='01_C&P'!U13 | F15: ='01_C&P'!V13 -> 1544555 | G15: ='01_C&P'!W13 -> 1544555 | H15: ='01_C&P'!X13 -> 0 | I15: ='01_C&P'!Y13 -> 24712880 | J15: =H15+I15 -> 24712880
A16: ='01_C&P'!A14 -> 0.6 | B16: ='01_C&P'!B14 -> AYUDA DE GREMIOS | C16: ='01_C&P'!C14 -> mes | D16: ='01_C&P'!D14 -> 16 | E16: ='01_C&P'!U14 | F16: ='01_C&P'!V14 -> 4633665 | G16: ='01_C&P'!W14 -> 4633665 | H16: ='01_C&P'!X14 -> 0 | I16: ='01_C&P'!Y14 -> 74138640 | J16: =H16+I16 -> 74138640
A17: ='01_C&P'!A15 -> 0.7 | B17: ='01_C&P'!B15 -> LIMPIEZA FINAL | C17: ='01_C&P'!C15 -> gl | D17: ='01_C&P'!D15 -> 1 | E17: ='01_C&P'!U15 | F17: ='01_C&P'!V15 -> 3089110 | G17: ='01_C&P'!W15 -> 3089110 | H17: ='01_C&P'!X15 -> 0 | I17: ='01_C&P'!Y15 -> 3089110 | J17: =H17+I17 -> 3089110
A18: ='01_C&P'!A16 -> 0.8 | B18: ='01_C&P'!B16 -> ESTRUCTURA DE ENCOFRADO Y APUNTALAMIENTO PROVISORIO | C18: ='01_C&P'!C16 -> gl | D18: ='01_C&P'!D16 -> 1 | E18: ='01_C&P'!U16 | F18: ='01_C&P'!V16 -> 1.9946792e+08 | G18: ='01_C&P'!W16 -> 1.9946792e+08 | H18: ='01_C&P'!X16 -> 0 | I18: ='01_C&P'!Y16 -> 1.9946792e+08 | J18: =H18+I18 -> 1.9946792e+08
A19: ='01_C&P'!A17 -> EXCAVACION
A20: ='01_C&P'!A18 -> 0.9 | B20: ='01_C&P'!B18 -> EXCAVACION BASES Y TRONCOS | C20: ='01_C&P'!C18 -> m³ | D20: ='01_C&P'!D18 -> 366.36 | E20: ='01_C&P'!U18 -> 0 | F20: ='01_C&P'!V18 -> 57927.136 | G20: ='01_C&P'!W18 -> 57927.136 | H20: ='01_C&P'!X18 -> 0 | I20: ='01_C&P'!Y18 -> 21222186 | J20: =H20+I20 -> 21222186
A21: ='01_C&P'!A19 -> 0.10 | B21: ='01_C&P'!B19 -> EXCAVACION TENSORES | C21: ='01_C&P'!C19 -> m³ | D21: ='01_C&P'!D19 -> 5.4 | E21: ='01_C&P'!U19 -> 0 | F21: ='01_C&P'!V19 -> 77227.75 | G21: ='01_C&P'!W19 -> 77227.75 | H21: ='01_C&P'!X19 -> 0 | I21: ='01_C&P'!Y19 -> 417029.85 | J21: =H21+I21 -> 417029.85
A22: ='01_C&P'!A20 -> 0.11 | B22: ='01_C&P'!B20 -> EXCAVACION TRONERAS | C22: ='01_C&P'!C20 -> m³ | D22: ='01_C&P'!D20 -> 276 | E22: ='01_C&P'!U20 -> 0 | F22: ='01_C&P'!V20 -> 57920.812 | G22: ='01_C&P'!W20 -> 57920.812 | H22: ='01_C&P'!X20 -> 0 | I22: ='01_C&P'!Y20 -> 15986144 | J22: =H22+I22 -> 15986144
A23: ='01_C&P'!A21 -> OBRA GRIS - FUNDACIONES
A24: ='01_C&P'!A22 -> 0.12 | B24: ='01_C&P'!B22 -> BASES | C24: ='01_C&P'!C22 -> m³ | D24: ='01_C&P'!D22 -> 108 | E24: ='01_C&P'!U22 -> 264204.49 | F24: ='01_C&P'!V22 -> 109835.02 | G24: ='01_C&P'!W22 -> 374039.51 | H24: ='01_C&P'!X22 -> 28534084 | I24: ='01_C&P'!Y22 -> 11862182 | J24: =H24+I24 -> 40396267
A25: ='01_C&P'!A23 -> 0.13 | B25: ='01_C&P'!B23 -> TRONCOS | C25: ='01_C&P'!C23 -> m³ | D25: ='01_C&P'!D23 -> 20 | E25: ='01_C&P'!U23 -> 290615.56 | F25: ='01_C&P'!V23 -> 562951.68 | G25: ='01_C&P'!W23 -> 853567.25 | H25: ='01_C&P'!X23 -> 5812311.3 | I25: ='01_C&P'!Y23 -> 11259034 | J25: =H25+I25 -> 17071345
A26: ='01_C&P'!A24 -> 0.14 | B26: ='01_C&P'!B24 -> TENSORES | C26: ='01_C&P'!C24 -> m³ | D26: ='01_C&P'!D24 -> 5.4 | E26: ='01_C&P'!U24 -> 389379.44 | F26: ='01_C&P'!V24 -> 596369.85 | G26: ='01_C&P'!W24 -> 985749.29 | H26: ='01_C&P'!X24 -> 2102649 | I26: ='01_C&P'!Y24 -> 3220397.2 | J26: =H26+I26 -> 5323046.2
A27: ='01_C&P'!A25 -> 0.15 | B27: ='01_C&P'!B25 -> TABIQUES DE SUBMURACION | C27: ='01_C&P'!C25 -> m³ | D27: ='01_C&P'!D25 -> 42.75 | E27: ='01_C&P'!U25 -> 442353.68 | F27: ='01_C&P'!V25 -> 578259.71 | G27: ='01_C&P'!W25 -> 1020613.4 | H27: ='01_C&P'!X25 -> 18910620 | I27: ='01_C&P'!Y25 -> 24720603 | J27: =H27+I27 -> 43631223
A28: ='01_C&P'!A26 -> OBRA GRIS - SOBRE SUBSUELO
A29: ='01_C&P'!A27 -> 36892 | B29: ='01_C&P'!B27 -> COLUMNAS Y TABIQUES | C29: ='01_C&P'!C27 -> m³ | D29: ='01_C&P'!D27 -> 23 | E29: ='01_C&P'!U27 -> 548114.34 | F29: ='01_C&P'!V27 -> 947147.99 | G29: ='01_C&P'!W27 -> 1495262.3 | H29: ='01_C&P'!X27 -> 12606630 | I29: ='01_C&P'!Y27 -> 21784404 | J29: =H29+I29 -> 34391034
A30: ='01_C&P'!A28 -> 46054 | B30: ='01_C&P'!B28 -> VIGAS | C30: ='01_C&P'!C28 -> m³ | D30: ='01_C&P'!D28 -> 16 | E30: ='01_C&P'!U28 -> 539468.37 | F30: ='01_C&P'!V28 -> 1361525.2 | G30: ='01_C&P'!W28 -> 1900993.6 | H30: ='01_C&P'!X28 -> 8631493.9 | I30: ='01_C&P'!Y28 -> 21784404 | J30: =H30+I30 -> 30415898
A31: ='01_C&P'!A29 -> 46082 | B31: ='01_C&P'!B29 -> LOSA | C31: ='01_C&P'!C29 -> m³ | D31: ='01_C&P'!D29 -> 57 | E31: ='01_C&P'!U29 -> 362272.74 | F31: ='01_C&P'!V29 -> 541664.6 | G31: ='01_C&P'!W29 -> 903937.34 | H31: ='01_C&P'!X29 -> 20649546 | I31: ='01_C&P'!Y29 -> 30874882 | J31: =H31+I31 -> 51524428
A32: ='01_C&P'!A30 -> 1.31 | B32: ='01_C&P'!B30 -> LOSA DE SUPRESION SOBRE SUELO COMPACTADO. e=10cm. | C32: ='01_C&P'!C30 -> m³ | D32: ='01_C&P'!D30 -> 39 | E32: ='01_C&P'!U30 -> 218369.72 | F32: ='01_C&P'!V30 -> 200198.09 | G32: ='01_C&P'!W30 -> 418567.81 | H32: ='01_C&P'!X30 -> 8516419 | I32: ='01_C&P'!Y30 -> 7807725.5 | J32: =H32+I32 -> 16324145
A33: ='01_C&P'!A31 -> 1.32 | B33: ='01_C&P'!B31 -> PAVIMENTO ALISADO EN ESTACIONAMIENTO. e=10cm | C33: ='01_C&P'!C31 -> m² | D33: ='01_C&P'!D31 -> 310 | E33: ='01_C&P'!U31 -> 25336.66 | F33: ='01_C&P'!V31 -> 25086.563 | G33: ='01_C&P'!W31 -> 50423.222 | H33: ='01_C&P'!X31 -> 7854364.5 | I33: ='01_C&P'!Y31 -> 7776834.4 | J33: =H33+I33 -> 15631199
A34: ='01_C&P'!A32 -> 46113 | B34: ='01_C&P'!B32 -> MAMPOSTERIA. | C34: ='01_C&P'!C32 -> m² | D34: ='01_C&P'!D32 -> 360 | E34: ='01_C&P'!U32 -> 28937.371 | F34: ='01_C&P'!V32 -> 26021.461 | G34: ='01_C&P'!W32 -> 54958.832 | H34: ='01_C&P'!X32 -> 10417454 | I34: ='01_C&P'!Y32 -> 9367726.1 | J34: =H34+I34 -> 19785180
A35: ='01_C&P'!A33 -> 46143 | B35: ='01_C&P'!B33 -> CONTRAPISO . e=12cm | C35: ='01_C&P'!C33 -> m² | D35: ='01_C&P'!D33 -> 80 | E35: ='01_C&P'!U33 -> 18664.73 | F35: ='01_C&P'!V33 -> 45467.838 | G35: ='01_C&P'!W33 -> 64132.568 | H35: ='01_C&P'!X33 -> 1493178.4 | I35: ='01_C&P'!Y33 -> 3637427 | J35: =H35+I35 -> 5130605.5
A36: ='01_C&P'!A34 -> 46174 | B36: ='01_C&P'!B34 -> CARPETA . e=3cm | C36: ='01_C&P'!C34 -> m² | D36: ='01_C&P'!D34 -> 80 | E36: ='01_C&P'!U34 -> 5017.625 | F36: ='01_C&P'!V34 -> 27222.782 | G36: ='01_C&P'!W34 -> 32240.407 | H36: ='01_C&P'!X34 -> 401410 | I36: ='01_C&P'!Y34 -> 2177822.5 | J36: =H36+I36 -> 2579232.5
A37: ='01_C&P'!A35 -> 46204 | B37: ='01_C&P'!B35 -> REVOQUE INTERIOR. (GRUESO FRATAZADO) | C37: ='01_C&P'!C35 -> m² | D37: ='01_C&P'!D35 -> 180 | E37: ='01_C&P'!U35 -> 2871.4118 | F37: ='01_C&P'!V35 -> 40158.43 | G37: ='01_C&P'!W35 -> 43029.842 | H37: ='01_C&P'!X35 -> 516854.13 | I37: ='01_C&P'!Y35 -> 7228517.4 | J37: =H37+I37 -> 7745371.5
A38: ='01_C&P'!A36 -> 46235 | B38: ='01_C&P'!B36 -> REVOQUE INTERTIOR HIDROFUGO. | C38: ='01_C&P'!C36 -> m² | D38: ='01_C&P'!D36 -> 282 | E38: ='01_C&P'!U36 -> 3811.6746 | F38: ='01_C&P'!V36 -> 54141.582 | G38: ='01_C&P'!W36 -> 57953.257 | H38: ='01_C&P'!X36 -> 1074892.2 | I38: ='01_C&P'!Y36 -> 15267926 | J38: =H38+I38 -> 16342818
A39: ='01_C&P'!A37 -> OBRA GRIS - SOBRE PLANTA BAJA
A40: ='01_C&P'!A38 -> 45293 | B40: ='01_C&P'!B38 -> COLUMNAS Y TABIQUES | C40: ='01_C&P'!C38 -> m³ | D40: ='01_C&P'!D38 -> 31 | E40: ='01_C&P'!U38 -> 537748.84 | F40: ='01_C&P'!V38 -> 607333.97 | G40: ='01_C&P'!W38 -> 1145082.8 | H40: ='01_C&P'!X38 -> 16670214 | I40: ='01_C&P'!Y38 -> 18827353 | J40: =H40+I40 -> 35497567
A41: ='01_C&P'!A39 -> n | B41: ='01_C&P'!B39 -> VIGAS | C41: ='01_C&P'!C39 -> m³ | D41: ='01_C&P'!D39 -> 14 | E41: ='01_C&P'!U39 -> 559896.94 | F41: ='01_C&P'!V39 -> 1320539.4 | G41: ='01_C&P'!W39 -> 1880436.3 | H41: ='01_C&P'!X39 -> 7838557.2 | I41: ='01_C&P'!Y39 -> 18487551 | J41: =H41+I41 -> 26326108
A42: ='01_C&P'!A40 -> 45353 | B42: ='01_C&P'!B40 -> LOSA | C42: ='01_C&P'!C40 -> m³ | D42: ='01_C&P'!D40 -> 26 | E42: ='01_C&P'!U40 -> 417771.5 | F42: ='01_C&P'!V40 -> 896406.26 | G42: ='01_C&P'!W40 -> 1314177.8 | H42: ='01_C&P'!X40 -> 10862059 | I42: ='01_C&P'!Y40 -> 23306563 | J42: =H42+I42 -> 34168622
A43: ='01_C&P'!A41 -> 46114 | B43: ='01_C&P'!B41 -> MAMPOSTERIA. | C43: ='01_C&P'!C41 -> m² | D43: ='01_C&P'!D41 -> 340 | E43: ='01_C&P'!U41 -> 28748.294 | F43: ='01_C&P'!V41 -> 26870.714 | G43: ='01_C&P'!W41 -> 55619.009 | H43: ='01_C&P'!X41 -> 9774420.1 | I43: ='01_C&P'!Y41 -> 9136042.8 | J43: =H43+I43 -> 18910463
...

Sheet 01_RESUMEN VENTA
B4: M2 | G4: MAT | H4: MO | I4: MAT + MO
B5: CUBIERTO | C5: S/CUBIERTO | D5: DESCUBIERTO | F5: TOTAL PESOS | G5: ='01_VENTA'!H132 -> 5.6636989e+08 | H5: ='01_VENTA'!I132 -> 1537402823 | I5: ='01_VENTA'!J132 -> 2103772717
B6: 1 | C6: 0.5 | D6: 0.25 | F6: TOTAL USD | G6: =G5/1450 -> 390599.93 | H6: =H5/1450 -> 1060277.8 | I6: =I5/1450 -> 1450877.7
A7: SUBSUELO | B7: 410 | C7: - | D7: - | F7: USD X M2 | G7: =G6/B23 -> 146.66288 | H7: =H6/B23 -> 398.11426 | I7: =I6/B23 -> 544.77715
A8: PLANTA BAJA | B8: 144 | C8: - | D8: 247
A9: P1 | B9: 231 | C9: 34 | D9: -
A10: P2 | B10: 231 | C10: 22 | D10: -
A11: P3 | B11: 231 | C11: 22 | D11: -
A12: P4 | B12: 231 | C12: 19 | D12: -
A13: P5 | B13: 231 | C13: 19 | D13: -
A14: P6 | B14: 231 | C14: 22 | D14: -
A15: P7 | B15: 231 | C15: 19 | D15: -
A16: P8 | B16: 231 | C16: 19 | D16: -
A17: AZOTEA ACC. | B17: 43 | C17: 30 | D17: =178-C17 -> 148
A18: AZOTEA INACC. | B18: - | C18: - | D18: 66
A20: SUBTOTAL | B20: =SUM(B7:B18) -> 2445 | C20: =SUM(C7:C18) -> 206 | D20: =SUM(D7:D18) -> 461
B21: =B20*B6 -> 2445 | C21: =C20*C6 -> 103 | D21: =D20*D6 -> 115.25
A23: TOTAL | B23: =B21+C21+D21 -> 2663.25

Sheet 01_RESUMEN MAT.
A1: ='01_C&P'!A1 -> EDIFICIO LAS HERAS
A3: ='2.1.'!A3 -> 45293 | B3: ='2.1.'!B3 -> COLUMNAS Y TABIQUES | H3: ='2.1.'!H3 -> 31 | I3: ='2.1.'!I3 -> m³
A5: MATERIALES
A6: Código | B6: Descripción | C6: Unidad | D6: Cantidad | F6: Desperdicio | G6: Cantidad + Desperdicio | H6: Precio Unitario | I6: Subtotal
A7: ='2.1.'!A7 -> H30 | B7: ='2.1.'!B7 -> Hormigon H30 | C7: ='2.1.'!C7 -> m3 | D7: ='2.1.'!D7 -> 31 | E7: ='2.1.'!E7 | F7: ='2.1.'!F7 -> 0.1 | G7: ='2.1.'!G7 -> 35 | H7: ='2.1.'!H7 -> 158000 | I7: ='2.1.'!I7 -> 5530000
A8: ='2.1.'!A8 -> HADN6 | B8: ='2.1.'!B8 -> Hierros ADN 420 Φ 6 | C8: ='2.1.'!C8 -> u | D8: ='2.1.'!D8 -> 266 | E8: ='2.1.'!E8 | F8: ='2.1.'!F8 -> 0.1 | G8: ='2.1.'!G8 -> 293 | H8: ='2.1.'!H8 -> 5250 | I8: ='2.1.'!I8 -> 1538250 | M8: =SUM(I8:I13) -> 6634136.1
A9: ='2.1.'!A9 -> HADN8 | B9: ='2.1.'!B9 -> Hierros ADN 420 Φ 8 | C9: ='2.1.'!C9 -> u | D9: ='2.1.'!D9 -> 50 | E9: ='2.1.'!E9 | F9: ='2.1.'!F9 -> 0.1 | G9: ='2.1.'!G9 -> 55 | H9: ='2.1.'!H9 -> 9050 | I9: ='2.1.'!I9 -> 497750
A10: ='2.1.'!A10 -> HADN10 | B10: ='2.1.'!B10 -> Hierros ADN 420Φ 10 | C10: ='2.1.'!C10 -> u | D10: ='2.1.'!D10 -> 15 | E10: ='2.1.'!E10 | F10: ='2.1.'!F10 -> 0.1 | G10: ='2.1.'!G10 -> 17 | H10: ='2.1.'!H10 -> 11237 | I10: ='2.1.'!I10 -> 191029
A11: ='2.1.'!A11 -> HADN12 | B11: ='2.1.'!B11 -> Hierros ADN 420 Φ 12 | C11: ='2.1.'!C11 -> u | D11: ='2.1.'!D11 -> 44 | E11: ='2.1.'!E11 | F11: ='2.1.'!F11 -> 0.1 | G11: ='2.1.'!G11 -> 49 | H11: ='2.1.'!H11 -> 20442.5 | I11: ='2.1.'!I11 -> 1001682.5
A12: ='2.1.'!A12 -> HADN16 | B12: ='2.1.'!B12 -> Hierros ADN 420 Φ 16 | C12: ='2.1.'!C12 -> u | D12: ='2.1.'!D12 -> 65 | E12: ='2.1.'!E12 | F12: ='2.1.'!F12 -> 0.1 | G12: ='2.1.'!G12 -> 72 | H12: ='2.1.'!H12 -> 36603.12 | I12: ='2.1.'!I12 -> 2635424.6
A13: ='2.1.'!A13 -> HADN20 | B13: ='2.1.'!B13 -> Hierros ADN 420 Φ 20 | C13: ='2.1.'!C13 -> U | D13: ='2.1.'!D13 -> 12 | E13: ='2.1.'!E13 | F13: ='2.1.'!F13 -> 0.1 | G13: ='2.1.'!G13 -> 14 | H13: ='2.1.'!H13 -> 55000 | I13: ='2.1.'!I13 -> 770000
A14: ='2.1.'!A14 -> F-MIR | B14: ='2.1.'!B14 -> Fenolico 18mm Miraluz 125 GR con film | C14: ='2.1.'!C14 -> u | D14: ='2.1.'!D14 -> 15.5 | E14: ='2.1.'!E14 | F14: ='2.1.'!F14 -> 0.25 | G14: ='2.1.'!G14 -> 20 | H14: ='2.1.'!H14 -> 55260 | I14: ='2.1.'!I14 -> 1105200
A15: ='2.1.'!A15 -> F-GR2 | B15: ='2.1.'!B15 -> Fenolico 18mm Grandis 2 Buenas cal 3/3 | C15: ='2.1.'!C15 -> u | D15: ='2.1.'!D15 -> 45.5 | E15: ='2.1.'!E15 | F15: ='2.1.'!F15 -> 0.25 | G15: ='2.1.'!G15 -> 57 | H15: ='2.1.'!H15 -> 45454 | I15: ='2.1.'!I15 -> 2590878
A16: ='2.1.'!A16 -> H-PL-TI | B16: ='2.1.'!B16 -> Bomba Pluma Traslado e Instalacion | C16: ='2.1.'!C16 -> u | D16: ='2.1.'!D16 -> 1 | E16: ='2.1.'!E16 | F16: ='2.1.'!F16 | G16: ='2.1.'!G16 -> 1 | H16: ='2.1.'!H16 -> 600000 | I16: ='2.1.'!I16 -> 600000
A17: ='2.1.'!A17 -> H-PL-m | B17: ='2.1.'!B17 -> Bomba Pluma m3 bombeable | C17: ='2.1.'!C17 -> m3 | D17: ='2.1.'!D17 -> 31 | E17: ='2.1.'!E17 | F17: ='2.1.'!F17 -> 0.1 | G17: ='2.1.'!G17 -> 35 | H17: ='2.1.'!H17 -> 6000 | I17: ='2.1.'!I17 -> 210000
A18: ='2.1.'!A18 | B18: ='2.1.'!B18 | C18: ='2.1.'!C18 | D18: ='2.1.'!D18 | E18: ='2.1.'!E18 | F18: ='2.1.'!F18 -> 0.1 | G18: ='2.1.'!G18 -> 0 | H18: ='2.1.'!H18 | I18: ='2.1.'!I18 -> 0
A20: TOTAL MATERIALES | I20: =SUM(I7:I18) -> 16670214
A23: ='2.2.'!A3 -> n | B23: ='2.2.'!B3 -> VIGAS | G23: ='2.2.'!G3 | H23: ='2.2.'!H3 -> 14 | I23: ='2.2.'!I3 -> m³
A25: ='2.2.'!A5 -> MATERIALES | B25: ='2.2.'!B5 | C25: ='2.2.'!C5 | D25: ='2.2.'!D5 | E25: ='2.2.'!E5 | F25: ='2.2.'!F5 | G25: ='2.2.'!G5 | H25: ='2.2.'!H5 | I25: ='2.2.'!I5
A26: ='2.2.'!A6 -> Código | B26: ='2.2.'!B6 -> Descripción | C26: ='2.2.'!C6 -> Unidad | D26: ='2.2.'!D6 -> Cantidad | F26: ='2.2.'!F6 -> Desperdicio | G26: ='2.2.'!G6 -> Cantidad + Desperdicio | H26: ='2.2.'!H6 -> Precio Unitario | I26: ='2.2.'!I6 -> Subtotal
A27: ='2.2.'!A7 -> H30 | B27: ='2.2.'!B7 -> Hormigon H30 | C27: ='2.2.'!C7 -> m3 | D27: ='2.2.'!D7 -> 14 | E27: ='2.2.'!E7 | F27: ='2.2.'!F7 -> 0.1 | G27: ='2.2.'!G7 -> 16 | H27: ='2.2.'!H7 -> 158000 | I27: ='2.2.'!I7 -> 2528000
A28: ='2.2.'!A8 -> HADN6 | B28: ='2.2.'!B8 -> Hierros ADN 420 Φ 6 | C28: ='2.2.'!C8 -> u | D28: ='2.2.'!D8 -> 123 | E28: ='2.2.'!E8 | F28: ='2.2.'!F8 -> 0.1 | G28: ='2.2.'!G8 -> 136 | H28: ='2.2.'!H8 -> 5250 | I28: ='2.2.'!I8 -> 714000 | M28: =SUM(I28:I33) -> 3492397.2
A29: ='2.2.'!A9 -> HADN8 | B29: ='2.2.'!B9 -> Hierros ADN 420 Φ 8 | C29: ='2.2.'!C9 -> u | D29: ='2.2.'!D9 -> 4 | E29: ='2.2.'!E9 | F29: ='2.2.'!F9 -> 0.1 | G29: ='2.2.'!G9 -> 5 | H29: ='2.2.'!H9 -> 9050 | I29: ='2.2.'!I9 -> 45250
A30: ='2.2.'!A10 -> HADN10 | B30: ='2.2.'!B10 -> Hierros ADN 420Φ 10 | C30: ='2.2.'!C10 -> u | D30: ='2.2.'!D10 -> 66 | E30: ='2.2.'!E10 | F30: ='2.2.'!F10 -> 0.1 | G30: ='2.2.'!G10 -> 73 | H30: ='2.2.'!H10 -> 11237 | I30: ='2.2.'!I10 -> 820301
A31: ='2.2.'!A11 -> HADN12 | B31: ='2.2.'!B11 -> Hierros ADN 420 Φ 12 | C31: ='2.2.'!C11 -> u | D31: ='2.2.'!D11 -> 34 | E31: ='2.2.'!E11 | F31: ='2.2.'!F11 -> 0.1 | G31: ='2.2.'!G11 -> 38 | H31: ='2.2.'!H11 -> 20442.5 | I31: ='2.2.'!I11 -> 776815
A32: ='2.2.'!A12 -> HADN16 | B32: ='2.2.'!B12 -> Hierros ADN 420 Φ 16 | C32: ='2.2.'!C12 -> u | D32: ='2.2.'!D12 -> 9 | E32: ='2.2.'!E12 | F32: ='2.2.'!F12 -> 0.1 | G32: ='2.2.'!G12 -> 10 | H32: ='2.2.'!H12 -> 36603.12 | I32: ='2.2.'!I12 -> 366031.2
A33: ='2.2.'!A13 -> HADN20 | B33: ='2.2.'!B13 -> Hierros ADN 420 Φ 20 | C33: ='2.2.'!C13 -> U | D33: ='2.2.'!D13 -> 12 | E33: ='2.2.'!E13 | F33: ='2.2.'!F13 -> 0.1 | G33: ='2.2.'!G13 -> 14 | H33: ='2.2.'!H13 -> 55000 | I33: ='2.2.'!I13 -> 770000
A34: ='2.2.'!A14 -> F-MIR | B34: ='2.2.'!B14 -> Fenolico 18mm Miraluz 125 GR con film | C34: ='2.2.'!C14 -> u | D34: ='2.2.'!D14 -> 0 | E34: ='2.2.'!E14 | F34: ='2.2.'!F14 -> 0.25 | G34: ='2.2.'!G14 -> 0 | H34: ='2.2.'!H14 -> 55260 | I34: ='2.2.'!I14 -> 0
A35: ='2.2.'!A15 -> F-GR2 | B35: ='2.2.'!B15 -> Fenolico 18mm Grandis 2 Buenas cal 3/3 | C35: ='2.2.'!C15 -> u | D35: ='2.2.'!D15 -> 31.5 | E35: ='2.2.'!E15 | F35: ='2.2.'!F15 -> 0.25 | G35: ='2.2.'!G15 -> 40 | H35: ='2.2.'!H15 -> 45454 | I35: ='2.2.'!I15 -> 1818160
A36: ='2.2.'!A16 | B36: ='2.2.'!B16 | C36: ='2.2.'!C16 | D36: ='2.2.'!D16 | E36: ='2.2.'!E16 | F36: ='2.2.'!F16 | G36: ='2.2.'!G16 -> 0 | H36: ='2.2.'!H16 | I36: ='2.2.'!I16
A37: ='2.2.'!A17 | B37: ='2.2.'!B17 | C37: ='2.2.'!C17 | D37: ='2.2.'!D17 | E37: ='2.2.'!E17 | F37: ='2.2.'!F17 | G37: ='2.2.'!G17 -> 0 | H37: ='2.2.'!H17 | I37: ='2.2.'!I17
A38: ='2.2.'!A18 | B38: ='2.2.'!B18 | C38: ='2.2.'!C18 | D38: ='2.2.'!D18 | E38: ='2.2.'!E18 | F38: ='2.2.'!F18 | G38: ='2.2.'!G18 -> 0 | H38: ='2.2.'!H18 | I38: ='2.2.'!I18
A39: ='2.2.'!A19 | B39: ='2.2.'!B19 | C39: ='2.2.'!C19 | D39: ='2.2.'!D19 | E39: ='2.2.'!E19 | F39: ='2.2.'!F19 | G39: ='2.2.'!G19 | H39: ='2.2.'!H19 | I39: ='2.2.'!I19
A40: ='2.2.'!A20 -> TOTAL MATERIALES | B40: ='2.2.'!B20 | C40: ='2.2.'!C20 | D40: ='2.2.'!D20 | E40: ='2.2.'!E20 | F40: ='2.2.'!F20 | G40: ='2.2.'!G20 | H40: ='2.2.'!H20 | I40: ='2.2.'!I20 -> 7838557.2
A43: ='2.3.'!A3 -> #REF! | B43: ='2.3.'!B3 -> #REF! | G43: ='2.3.'!G3 -> #REF! | H43: ='2.3.'!H3 -> #REF! | I43: ='2.3.'!I3 -> #REF!
A45: ='2.3.'!A5 -> #REF! | B45: ='2.3.'!B5 -> #REF! | C45: ='2.3.'!C5 -> #REF! | D45: ='2.3.'!D5 -> #REF! | E45: ='2.3.'!E5 -> #REF! | F45: ='2.3.'!F5 -> #REF! | G45: ='2.3.'!G5 -> #REF! | H45: ='2.3.'!H5 -> #REF! | I45: ='2.3.'!I5 -> #REF!
A46: ='2.3.'!A6 -> #REF! | B46: ='2.3.'!B6 -> #REF! | C46: ='2.3.'!C6 -> #REF! | D46: ='2.3.'!D6 -> #REF! | F46: ='2.3.'!F6 -> #REF! | G46: ='2.3.'!G6 -> #REF! | H46: ='2.3.'!H6 -> #REF! | I46: ='2.3.'!I6 -> #REF!
A47: ='2.3.'!A7 -> #REF! | B47: ='2.3.'!B7 -> #REF! | C47: ='2.3.'!C7 -> #REF! | D47: ='2.3.'!D7 -> #REF! | E47: ='2.3.'!E7 -> #REF! | F47: ='2.3.'!F7 -> #REF! | G47: ='2.3.'!G7 -> #REF! | H47: ='2.3.'!H7 -> #REF! | I47: ='2.3.'!I7 -> #REF!
A48: ='2.3.'!A8 -> #REF! | B48: ='2.3.'!B8 -> #REF! | C48: ='2.3.'!C8 -> #REF! | D48: ='2.3.'!D8 -> #REF! | E48: ='2.3.'!E8 -> #REF! | F48: ='2.3.'!F8 -> #REF! | G48: ='2.3.'!G8 -> #REF! | H48: ='2.3.'!H8 -> #REF! | I48: ='2.3.'!I8 -> #REF!
A49: ='2.3.'!A9 -> #REF! | B49: ='2.3.'!B9 -> #REF! | C49: ='2.3.'!C9 -> #REF! | D49: ='2.3.'!D9 -> #REF! | E49: ='2.3.'!E9 -> #REF! | F49: ='2.3.'!F9 -> #REF! | G49: ='2.3.'!G9 -> #REF! | H49: ='2.3.'!H9 -> #REF! | I49: ='2.3.'!I9 -> #REF!
...

Sheet 01_RESUMEN MAT M.O.
A1: ='01_C&P'!A1 -> EDIFICIO LAS HERAS
A3: ='2.1.'!A3 -> 45293 | B3: ='2.1.'!B3 -> COLUMNAS Y TABIQUES | G3: ='2.1.'!G3 | H3: ='2.1.'!H3 -> 31 | I3: ='2.1.'!I3 -> m³
A5: ='2.1.'!A53 -> MANO DE OBRA - MATERIALES | C5: ='2.1.'!C53 | D5: ='2.1.'!D53 | E5: ='2.1.'!E53 | F5: ='2.1.'!F53 | G5: ='2.1.'!G53 | H5: ='2.1.'!H53 | I5: ='2.1.'!I53
A6: ='2.1.'!A54 -> Código | B6: ='2.1.'!B54 -> Descripción | C6: ='2.1.'!C54 -> Unidad | D6: ='2.1.'!D54 -> Cantidad | E6: ='2.1.'!E54 | F6: ='2.1.'!F54 -> Desperdicio | G6: ='2.1.'!G54 -> Cantidad + Desperdicio | H6: ='2.1.'!H54 -> Precio Unitario | I6: ='2.1.'!I54 -> Subtotal
A7: ='2.1.'!A55 | B7: ='2.1.'!B55 | C7: ='2.1.'!C55 | D7: ='2.1.'!D55 | E7: ='2.1.'!E55 | F7: ='2.1.'!F55 -> 0.1 | G7: ='2.1.'!G55 -> 0 | H7: ='2.1.'!H55 | I7: ='2.1.'!I55 -> 0
A8: ='2.1.'!A56 | B8: ='2.1.'!B56 | C8: ='2.1.'!C56 | D8: ='2.1.'!D56 | E8: ='2.1.'!E56 | F8: ='2.1.'!F56 -> 0.1 | G8: ='2.1.'!G56 -> 0 | H8: ='2.1.'!H56 | I8: ='2.1.'!I56 -> 0
A9: ='2.1.'!A57 -> CL2 | B9: ='2.1.'!B57 -> Clavos 2" punta paris (k) | C9: ='2.1.'!C57 -> k | D9: ='2.1.'!D57 -> 10 | E9: ='2.1.'!E57 | F9: ='2.1.'!F57 -> 0.1 | G9: ='2.1.'!G57 -> 11 | H9: ='2.1.'!H57 -> 4500 | I9: ='2.1.'!I57 -> 49500
A10: =#REF! -> #REF! | B10: =#REF! -> #REF! | C10: ='2.1.'!C58 -> k | D10: ='2.1.'!D58 -> 1 | E10: ='2.1.'!E58 | F10: ='2.1.'!F58 -> 0.1 | G10: ='2.1.'!G58 -> 2 | H10: ='2.1.'!H58 -> 220000 | I10: ='2.1.'!I58 -> 440000
A11: ='2.1.'!A58 -> AL-50k | B11: ='2.1.'!B58 -> Alambre Fardo (50 k) | C11: ='2.1.'!C59 -> k | D11: ='2.1.'!D59 | E11: ='2.1.'!E59 | F11: ='2.1.'!F59 -> 0.1 | G11: ='2.1.'!G59 -> 0 | H11: ='2.1.'!H59 | I11: ='2.1.'!I59 -> 0
A12: ='2.1.'!A60 | B12: ='2.1.'!B60 | C12: ='2.1.'!C60 | D12: ='2.1.'!D60 | E12: ='2.1.'!E60 | F12: ='2.1.'!F60 | G12: ='2.1.'!G60 -> 0 | H12: ='2.1.'!H60 | I12: ='2.1.'!I60 -> 0
A13: ='2.1.'!A61 | B13: ='2.1.'!B61 | C13: ='2.1.'!C61 | D13: ='2.1.'!D61 | E13: ='2.1.'!E61 | F13: ='2.1.'!F61 | G13: ='2.1.'!G61 | H13: ='2.1.'!H61 | I13: ='2.1.'!I61
A14: ='2.1.'!A62 -> TOTAL | B14: ='2.1.'!B62 | C14: ='2.1.'!C62 | D14: ='2.1.'!D62 | E14: ='2.1.'!E62 | F14: ='2.1.'!F62 | G14: ='2.1.'!G62 | H14: ='2.1.'!H62 | I14: ='2.1.'!I62 -> 489500
A17: ='2.2.'!A3 -> n | B17: ='2.2.'!B3 -> VIGAS | G17: ='2.2.'!G3 | H17: ='2.2.'!H3 -> 14 | I17: ='2.2.'!I3 -> m³
A19: ='2.2.'!A53 -> MANO DE OBRA - MATERIALES | C19: ='2.2.'!C53 | D19: ='2.2.'!D53 | E19: ='2.2.'!E53 | F19: ='2.2.'!F53 | G19: ='2.2.'!G53 | H19: ='2.2.'!H53 | I19: ='2.2.'!I53
A20: ='2.2.'!A54 -> Código | B20: ='2.2.'!B54 -> Descripción | C20: ='2.2.'!C54 -> Unidad | D20: ='2.2.'!D54 -> Cantidad | E20: ='2.2.'!E54 | F20: ='2.2.'!F54 -> Desperdicio | G20: ='2.2.'!G54 -> Cantidad + Desperdicio | H20: ='2.2.'!H54 -> Precio Unitario | I20: ='2.2.'!I54 -> Subtotal
A21: ='2.2.'!A55 | B21: ='2.2.'!B55 | C21: ='2.2.'!C55 | D21: ='2.2.'!D55 | E21: ='2.2.'!E55 | F21: ='2.2.'!F55 -> 0.1 | G21: ='2.2.'!G55 -> 0 | H21: ='2.2.'!H55 | I21: ='2.2.'!I55 -> 0
A22: ='2.2.'!A56 | B22: ='2.2.'!B56 | C22: ='2.2.'!C56 | D22: ='2.2.'!D56 | E22: ='2.2.'!E56 | F22: ='2.2.'!F56 -> 0.1 | G22: ='2.2.'!G56 -> 0 | H22: ='2.2.'!H56 | I22: ='2.2.'!I56 -> 0
A23: ='2.2.'!A57 -> CL2 | B23: ='2.2.'!B57 -> Clavos 2" punta paris (k) | C23: ='2.2.'!C57 -> k | D23: ='2.2.'!D57 -> 10 | E23: ='2.2.'!E57 | F23: ='2.2.'!F57 -> 0.1 | G23: ='2.2.'!G57 -> 11 | H23: ='2.2.'!H57 -> 4500 | I23: ='2.2.'!I57 -> 49500
A24: ='2.2.'!A58 -> AL-50k | B24: ='2.2.'!B58 -> Alambre Fardo (50 k) | C24: ='2.2.'!C58 -> k | D24: ='2.2.'!D58 -> 1 | E24: ='2.2.'!E58 | F24: ='2.2.'!F58 | G24: ='2.2.'!G58 -> 1 | H24: ='2.2.'!H58 -> 220000 | I24: ='2.2.'!I58 -> 220000
A25: ='2.2.'!A59 | B25: ='2.2.'!B59 | C25: ='2.2.'!C59 | D25: ='2.2.'!D59 | E25: ='2.2.'!E59 | F25: ='2.2.'!F59 -> 0.1 | G25: ='2.2.'!G59 -> 0 | H25: ='2.2.'!H59 | I25: ='2.2.'!I59 -> 0
A26: ='2.2.'!A60 | B26: ='2.2.'!B60 | C26: ='2.2.'!C60 | D26: ='2.2.'!D60 | E26: ='2.2.'!E60 | F26: ='2.2.'!F60 -> 0.1 | G26: ='2.2.'!G60 -> 0 | H26: ='2.2.'!H60 | I26: ='2.2.'!I60 -> 0
A27: ='2.2.'!A61 | B27: ='2.2.'!B61 | C27: ='2.2.'!C61 | D27: ='2.2.'!D61 | E27: ='2.2.'!E61 | F27: ='2.2.'!F61 | G27: ='2.2.'!G61 | H27: ='2.2.'!H61 | I27: ='2.2.'!I61
A28: ='2.2.'!A62 -> TOTAL | B28: ='2.2.'!B62 | C28: ='2.2.'!C62 | D28: ='2.2.'!D62 | E28: ='2.2.'!E62 | F28: ='2.2.'!F62 | G28: ='2.2.'!G62 | H28: ='2.2.'!H62 | I28: ='2.2.'!I62 -> 269500
A31: ='2.3.'!A3 -> #REF! | B31: ='2.3.'!B3 -> #REF! | G31: ='2.3.'!G3 -> #REF! | H31: ='2.3.'!H3 -> #REF! | I31: ='2.3.'!I3 -> #REF!
A33: ='2.3.'!A53 -> #REF! | C33: ='2.3.'!C53 -> #REF! | D33: ='2.3.'!D53 -> #REF! | E33: ='2.3.'!E53 -> #REF! | F33: ='2.3.'!F53 -> #REF! | G33: ='2.3.'!G53 -> #REF! | H33: ='2.3.'!H53 -> #REF! | I33: ='2.3.'!I53 -> #REF!
A34: ='2.3.'!A54 -> #REF! | B34: ='2.3.'!B54 -> #REF! | C34: ='2.3.'!C54 -> #REF! | D34: ='2.3.'!D54 -> #REF! | E34: ='2.3.'!E54 -> #REF! | F34: ='2.3.'!F54 -> #REF! | G34: ='2.3.'!G54 -> #REF! | H34: ='2.3.'!H54 -> #REF! | I34: ='2.3.'!I54 -> #REF!
A35: ='2.3.'!A55 -> #REF! | B35: ='2.3.'!B55 -> #REF! | C35: ='2.3.'!C55 -> #REF! | D35: ='2.3.'!D55 -> #REF! | E35: ='2.3.'!E55 -> #REF! | F35: ='2.3.'!F55 -> #REF! | G35: ='2.3.'!G55 -> #REF! | H35: ='2.3.'!H55 -> #REF! | I35: ='2.3.'!I55 -> #REF!
A36: ='2.3.'!A56 -> #REF! | B36: ='2.3.'!B56 -> #REF! | C36: ='2.3.'!C56 -> #REF! | D36: ='2.3.'!D56 -> #REF! | E36: ='2.3.'!E56 -> #REF! | F36: ='2.3.'!F56 -> #REF! | G36: ='2.3.'!G56 -> #REF! | H36: ='2.3.'!H56 -> #REF! | I36: ='2.3.'!I56 -> #REF!
A37: ='2.3.'!A57 -> #REF! | B37: ='2.3.'!B57 -> #REF! | C37: ='2.3.'!C57 -> #REF! | D37: ='2.3.'!D57 -> #REF! | E37: ='2.3.'!E57 -> #REF! | F37: ='2.3.'!F57 -> #REF! | G37: ='2.3.'!G57 -> #REF! | H37: ='2.3.'!H57 -> #REF! | I37: ='2.3.'!I57 -> #REF!
A38: ='2.3.'!A58 -> #REF! | B38: ='2.3.'!B58 -> #REF! | C38: ='2.3.'!C58 -> #REF! | D38: ='2.3.'!D58 -> #REF! | E38: ='2.3.'!E58 -> #REF! | F38: ='2.3.'!F58 -> #REF! | G38: ='2.3.'!G58 -> #REF! | H38: ='2.3.'!H58 -> #REF! | I38: ='2.3.'!I58 -> #REF!
A39: ='2.3.'!A59 -> #REF! | B39: ='2.3.'!B59 -> #REF! | C39: ='2.3.'!C59 -> #REF! | D39: ='2.3.'!D59 -> #REF! | E39: ='2.3.'!E59 -> #REF! | F39: ='2.3.'!F59 -> #REF! | G39: ='2.3.'!G59 -> #REF! | H39: ='2.3.'!H59 -> #REF! | I39: ='2.3.'!I59 -> #REF!
A40: ='2.3.'!A60 -> #REF! | B40: ='2.3.'!B60 -> #REF! | C40: ='2.3.'!C60 -> #REF! | D40: ='2.3.'!D60 -> #REF! | E40: ='2.3.'!E60 -> #REF! | F40: ='2.3.'!F60 -> #REF! | G40: ='2.3.'!G60 -> #REF! | H40: ='2.3.'!H60 -> #REF! | I40: ='2.3.'!I60 -> #REF!
A41: ='2.3.'!A61 -> #REF! | B41: ='2.3.'!B61 -> #REF! | C41: ='2.3.'!C61 -> #REF! | D41: ='2.3.'!D61 -> #REF! | E41: ='2.3.'!E61 -> #REF! | F41: ='2.3.'!F61 -> #REF! | G41: ='2.3.'!G61 -> #REF! | H41: ='2.3.'!H61 -> #REF! | I41: ='2.3.'!I61 -> #REF!
A42: ='2.3.'!A62 -> #REF! | B42: ='2.3.'!B62 -> #REF! | C42: ='2.3.'!C62 -> #REF! | D42: ='2.3.'!D62 -> #REF! | E42: ='2.3.'!E62 -> #REF! | F42: ='2.3.'!F62 -> #REF! | G42: ='2.3.'!G62 -> #REF! | H42: ='2.3.'!H62 -> #REF! | I42: ='2.3.'!I62 -> #REF!
A45: ='2.4.'!A3 -> #REF! | B45: ='2.4.'!B3 -> #REF! | G45: ='2.4.'!G3 -> #REF! | H45: ='2.4.'!H3 -> #REF! | I45: ='2.4.'!I3 -> #REF!
A47: ='2.4.'!A53 -> #REF! | B47: ='2.4.'!B53 -> #REF! | C47: ='2.4.'!C53 -> #REF! | D47: ='2.4.'!D53 -> #REF! | E47: ='2.4.'!E53 -> #REF! | F47: ='2.4.'!F53 -> #REF! | G47: ='2.4.'!G53 -> #REF! | H47: ='2.4.'!H53 -> #REF! | I47: ='2.4.'!I53 -> #REF!
A48: ='2.4.'!A54 -> #REF! | B48: ='2.4.'!B54 -> #REF! | C48: ='2.4.'!C54 -> #REF! | D48: ='2.4.'!D54 -> #REF! | E48: ='2.4.'!E54 -> #REF! | F48: ='2.4.'!F54 -> #REF! | G48: ='2.4.'!G54 -> #REF! | H48: ='2.4.'!H54 -> #REF! | I48: ='2.4.'!I54 -> #REF!
A49: ='2.4.'!A55 -> #REF! | B49: ='2.4.'!B55 -> #REF! | C49: ='2.4.'!C55 -> #REF! | D49: ='2.4.'!D55 -> #REF! | E49: ='2.4.'!E55 -> #REF! | F49: ='2.4.'!F55 -> #REF! | G49: ='2.4.'!G55 -> #REF! | H49: ='2.4.'!H55 -> #REF! | I49: ='2.4.'!I55 -> #REF!
A50: ='2.4.'!A56 -> #REF! | B50: ='2.4.'!B56 -> #REF! | C50: ='2.4.'!C56 -> #REF! | D50: ='2.4.'!D56 -> #REF! | E50: ='2.4.'!E56 -> #REF! | F50: ='2.4.'!F56 -> #REF! | G50: ='2.4.'!G56 -> #REF! | H50: ='2.4.'!H56 -> #REF! | I50: ='2.4.'!I56 -> #REF!
A51: ='2.4.'!A57 -> #REF! | B51: ='2.4.'!B57 -> #REF! | C51: ='2.4.'!C57 -> #REF! | D51: ='2.4.'!D57 -> #REF! | E51: ='2.4.'!E57 -> #REF! | F51: ='2.4.'!F57 -> #REF! | G51: ='2.4.'!G57 -> #REF! | H51: ='2.4.'!H57 -> #REF! | I51: ='2.4.'!I57 -> #REF!
...

Sheet 01_RESUMEN SERV. M.O.
A1: ='01_C&P'!A1 -> EDIFICIO LAS HERAS
A3: ='2.1.'!A3 -> 45293 | B3: ='2.1.'!B3 -> COLUMNAS Y TABIQUES | G3: ='2.1.'!G3 | H3: ='2.1.'!H3 -> 31 | I3: ='2.1.'!I3 -> m³
A5: ='2.1.'!A39 -> MANO DE OBRA - EQUIPOS | C5: ='2.1.'!C39 | D5: ='2.1.'!D39 | E5: ='2.1.'!E39 | F5: ='2.1.'!F39 | G5: ='2.1.'!G39 | H5: ='2.1.'!H39 | I5: ='2.1.'!I39
A6: ='2.1.'!A40 -> Código | B6: ='2.1.'!B40 -> Descripción | C6: ='2.1.'!C40 -> Unidad | D6: ='2.1.'!D40 -> Cantidad | E6: ='2.1.'!E40 -> Dias | F6: ='2.1.'!F40 -> Desperdicio | G6: ='2.1.'!G40 -> Cantidad + Desperdicio | H6: ='2.1.'!H40 -> Precio Unitario | I6: ='2.1.'!I40 -> Subtotal
A7: ='2.1.'!A41 | B7: ='2.1.'!B41 | C7: ='2.1.'!C41 | D7: ='2.1.'!D41 | E7: ='2.1.'!E41 | F7: ='2.1.'!F41 | G7: ='2.1.'!G41 -> 0 | H7: ='2.1.'!H41 | I7: ='2.1.'!I41 -> 0
A8: ='2.1.'!A42 | B8: ='2.1.'!B42 | C8: ='2.1.'!C42 | D8: ='2.1.'!D42 | E8: ='2.1.'!E42 | F8: ='2.1.'!F42 | G8: ='2.1.'!G42 -> 0 | H8: ='2.1.'!H42 | I8: ='2.1.'!I42 -> 0
